<mujoco model="HU_D03_02">
  <compiler angle="radian" meshdir="../meshes/HU_D03_02/"/>
  <size njmax="5000" nconmax="1000"/>

  <default>
    <light castshadow="false" diffuse="1 1 1" />
    <camera fovy="60" />
    <default class="visual">
      <geom contype="0" conaffinity="0" group="1" type="mesh" rgba="0.8 0.8 0.8 1.0" />
    </default>
    <joint damping="0.01" margin="0.0001" />
    <geom contype="1" conaffinity="1" friction="1.0 0.3 0.3" rgba="0.5 0.6 0.7 0.5" margin="0.001" group="0" />
    <equality solref="0.001  1" />
  </default>

  <option timestep="0.001" />
  <!-- <option>
    <flag sensornoise="enable" />
  </option> -->

  <visual>
    <rgba com="0.502 1.0 0 1.0" contactpoint="0.5 0.1 0.8 0.4" contactforce="0.2 0.98 0.2 0.8" />
    <scale com="0.2" forcewidth="0.05" contactwidth="0.10" contactheight="0.04" />
  </visual>

  <asset>
    <mesh name="base_link" file="base_link.STL"/>
    <mesh name="left_hip_pitch_link" file="left_hip_pitch_link.STL"/>
    <mesh name="left_hip_roll_link" file="left_hip_roll_link.STL"/>
    <mesh name="left_hip_yaw_link" file="left_hip_yaw_link.STL"/>
    <mesh name="left_knee_link" file="left_knee_link.STL"/>
    <mesh name="left_ankle_pitch_link" file="left_ankle_pitch_link.STL"/>
    <mesh name="left_ankle_roll_link" file="left_ankle_roll_link.STL"/>
    <mesh name="left_A_achilles_link" file="left_A_achilles_link.STL"/>
    <mesh name="left_A_achilles_rod_link" file="left_A_achilles_rod_link.STL"/>
    <mesh name="left_A_achilles_cp_link" file="left_A_achilles_cp_link.STL"/>
    <mesh name="left_B_achilles_link" file="left_B_achilles_link.STL"/>
    <mesh name="left_B_achilles_rod_link" file="left_B_achilles_rod_link.STL"/>
    <mesh name="left_B_achilles_cp_link" file="left_B_achilles_cp_link.STL"/>
    <mesh name="right_hip_pitch_link" file="right_hip_pitch_link.STL"/>
    <mesh name="right_hip_roll_link" file="right_hip_roll_link.STL"/>
    <mesh name="right_hip_yaw_link" file="right_hip_yaw_link.STL"/>
    <mesh name="right_knee_link" file="right_knee_link.STL"/>
    <mesh name="right_ankle_pitch_link" file="right_ankle_pitch_link.STL"/>
    <mesh name="right_ankle_roll_link" file="right_ankle_roll_link.STL"/>
    <mesh name="right_A_achilles_link" file="right_A_achilles_link.STL"/>
    <mesh name="right_A_achilles_rod_link" file="right_A_achilles_rod_link.STL"/>
    <mesh name="right_A_achilles_cp_link" file="right_A_achilles_cp_link.STL"/>
    <mesh name="right_B_achilles_link" file="right_B_achilles_link.STL"/>
    <mesh name="right_B_achilles_rod_link" file="right_B_achilles_rod_link.STL"/>
    <mesh name="right_B_achilles_cp_link" file="right_B_achilles_cp_link.STL"/>
    <mesh name="waist_yaw_link" file="waist_yaw_link.STL"/>
    <mesh name="waist_roll_link" file="waist_roll_link.STL"/>
    <mesh name="waist_pitch_link" file="waist_pitch_link.STL"/>
    <mesh name="waist_A_link" file="waist_A_link.STL"/>
    <mesh name="waist_A_rod_link" file="waist_A_rod_link.STL"/>
    <mesh name="waist_A_cp_link" file="waist_A_cp_link.STL"/>
    <mesh name="waist_B_link" file="waist_B_link.STL"/>
    <mesh name="waist_B_rod_link" file="waist_B_rod_link.STL"/>
    <mesh name="waist_B_cp_link" file="waist_B_cp_link.STL"/>
    <mesh name="left_shoulder_pitch_link" file="left_shoulder_pitch_link.STL"/>
    <mesh name="left_shoulder_roll_link" file="left_shoulder_roll_link.STL"/>
    <mesh name="left_shoulder_yaw_link" file="left_shoulder_yaw_link.STL"/>
    <mesh name="left_elbow_link" file="left_elbow_link.STL"/>
    <mesh name="left_wrist_yaw_link" file="left_wrist_yaw_link.STL"/>
    <mesh name="left_wrist_pitch_link" file="left_wrist_pitch_link.STL"/>
    <mesh name="left_hand_yaw_link" file="left_hand_yaw_link.STL"/>
    <mesh name="right_shoulder_pitch_link" file="right_shoulder_pitch_link.STL"/>
    <mesh name="right_shoulder_roll_link" file="right_shoulder_roll_link.STL"/>
    <mesh name="right_shoulder_yaw_link" file="right_shoulder_yaw_link.STL"/>
    <mesh name="right_elbow_link" file="right_elbow_link.STL"/>
    <mesh name="right_wrist_yaw_link" file="right_wrist_yaw_link.STL"/>
    <mesh name="right_wrist_pitch_link" file="right_wrist_pitch_link.STL"/>
    <mesh name="right_hand_yaw_link" file="right_hand_yaw_link.STL"/>
    <mesh name="head_yaw_link" file="neck_yaw_link.STL"/>
    <mesh name="head_pitch_link" file="neck_pitch_link.STL"/>
  </asset>

  <asset>
    <texture type="skybox" builtin="gradient" width="512" height="512" rgb1="1.0 1.0 1.0" rgb2="1.0 1.0 1.0" />
    <texture name="plane" type="2d" builtin="flat" rgb1="1 1 1" rgb2="1 1 1" width="512" height="512" mark="cross" markrgb="0 0 0" />
    <material name="plane" reflectance="0.0" texture="plane" texrepeat="3 3" texuniform="true" />
  </asset>

  <worldbody>
    <geom name="floor" pos="0 0 0" euler="0 0 0" size="0 0 1" type="plane" material="plane" condim="3" conaffinity="1" contype="1" rgba="1 1 1 1" />
    <light directional="true" diffuse=".8 .8 .8" pos="0 0 10" dir="0 0 -10" />
    <camera name="track" mode="trackcom" pos="0 -2.3 1.6" xyaxes="1 0 0 0 0.707 0.707" />

    <body name="base_link" pos="0 0 1.0">
      <inertial pos="-0.0037 6e-05 0.03467" quat="0.604073 0.604736 -0.366987 0.367029" mass="5.76" diaginertia="0.0397072 0.0353397 0.0147803"/>
      <joint name="floating_base_joint" type="free" damping="0.00000001" stiffness="0.000000001"/>
      <geom type="mesh" class="visual" rgba="0.898039 0.917647 0.929412 1" mesh="base_link"/>
      <!-- <geom pos="0 0 0.21" euler="0 0 0" size="0.06 0.04" type="cylinder" />
      <geom pos="0 0.06 0.08" euler="1.22 0 0" size="0.07 0.03" type="cylinder" />
      <geom pos="0 -0.06 0.08" euler="-1.22 0 0" size="0.07 0.03" type="cylinder" /> -->
      <site name="imu" rgba="0 1 0 1" pos="0 0 0" />

      <!-- left leg -->
      <body name="left_hip_pitch_link" pos="0.01 0.12109 0.00692262">
        <inertial pos="-0.0005 0.00873 -0.08961" quat="0.736436 0.0138863 0.0208401 0.676043" mass="2.16" diaginertia="0.00371364 0.00351311 0.002873"/>
        <joint name="left_hip_pitch_joint" pos="0 0 0" axis="0 0.906308 -0.422618" limited="true" range="-3.14159 3.14159" armature="0.15257125"/>
        <geom type="mesh" class="visual" rgba="0.792157 0.819608 0.929412 1" mesh="left_hip_pitch_link"/>

        <body name="left_hip_roll_link" pos="-0.01 0.00891007 -0.0954226">
          <inertial pos="0.0014 0.00013 -0.03498" quat="0.505645 0.494084 0.49127 0.508781" mass="0.49" diaginertia="0.00183288 0.00154622 0.000941909"/>
          <joint name="left_hip_roll_joint" pos="0 0 0" axis="1 0 0" limited="true" range="-0.523599 2.0944" armature="0.15257125"/>
          <geom type="mesh" class="visual" rgba="0.792157 0.819608 0.933333 1" mesh="left_hip_roll_link"/>

          <body name="left_hip_yaw_link" pos="0 0 -0.0705">
            <inertial pos="0.00447 0.00313 -0.17225" quat="0.712654 0.00624575 -0.00849079 0.701436" mass="4.48" diaginertia="0.0736764 0.0728051 0.00681999"/>
            <joint name="left_hip_yaw_joint" pos="0 0 0" axis="0 0 1" limited="true" range="-2.70526 2.70526" armature="0.15257125"/>
            <geom type="mesh" class="visual" rgba="1 1 1 1" mesh="left_hip_yaw_link"/>
            <!-- <geom type="capsule" pos="0.015 -0.0 -0.14" size="0.05 0.1" euler="0 -0.1 0" /> -->

            <body name="left_knee_link" pos="0 0 -0.3045">
              <inertial pos="0.00745 0.00751 -0.13644" quat="0.989694 -0.0482796 0.00102543 0.134809" mass="2.95" diaginertia="0.02787 0.0276329 0.00321862"/>
              <joint name="left_knee_joint" pos="0 0 0" axis="0 1 0" limited="true" range="-0.0872665 2.58309" armature="0.15257125"/>
              <geom type="mesh" class="visual" rgba="0.666667 0.698039 0.768627 1" mesh="left_knee_link"/>
              <!-- <geom type="capsule" pos="0.015 -0.03 -0.2" size="0.035 0.14" euler="0 0.1 0" /> -->

              <body name="left_ankle_pitch_link" pos="0 0.00139822 -0.385">
                <inertial pos="0.00015 0 0.00047" quat="0.500895 0.500895 -0.499103 0.499103" mass="0.1" diaginertia="2.208e-05 1.929e-05 6.94e-06"/>
                <joint name="left_ankle_pitch_joint" pos="0 0 0" axis="0 1 0" limited="true" range="-0.610865 0.942478"/>
                <geom type="mesh" class="visual" rgba="0.776471 0.756863 0.737255 1" mesh="left_ankle_pitch_link"/>

                <body name="left_ankle_roll_link" pos="0 0 0">
                  <inertial pos="0.0014 0.00013 -0.03498" quat="0.505645 0.494084 0.49127 0.508781" mass="0.49" diaginertia="0.00183288 0.00154622 0.000941909"/>
                  <joint name="left_ankle_roll_joint" pos="0 0 0" axis="1 0 0" limited="true" range="-0.436332 0.436332"/>
                  <geom type="mesh" class="visual" rgba="1 1 1 1" mesh="left_ankle_roll_link"/>
                  <geom name="left_foot"  pos="0.001 0 -0.0535" size="0.125 0.047 0.01" type="box" rgba="0 0.4 0 0.1" />

                  <body name="contact_left_heel" pos="-0.124 0 -0.0635">
                    <inertial pos="0.0 0.0 0.0" quat="1 0 0 0" mass="0.00001" diaginertia="0.00000000001 0.00000000001 0.00000000001"/>
                    <geom name="contact_left_heel" class="visual" size="0.003" type="sphere" rgba="1 0 0 1"/>
                  </body>
                  <body name="contact_left_center" pos="0.001 0 -0.0635">
                    <inertial pos="0.0 0.0 0.0" quat="1 0 0 0" mass="0.00001" diaginertia="0.00000000001 0.00000000001 0.00000000001"/>
                    <geom name="contact_left_center" class="visual" size="0.003" type="sphere" rgba="1 0 0 1"/>
                  </body>
                  <body name="contact_left_tip" pos="0.126 0 -0.0635">
                    <inertial pos="0.0 0.0 0.0" quat="1 0 0 0" mass="0.00001" diaginertia="0.00000000001 0.00000000001 0.00000000001"/>
                    <geom name="contact_left_tip" class="visual" size="0.003" type="sphere" rgba="1 0 0 1"/>
                  </body>

                </body>
              </body>
              <body name="left_A_achilles_link" pos="-0.0238 0.00139822 -0.115">
                <inertial pos="0.00174132 0.00862085 0.00140366" quat="0.646989 0.760854 0.0324327 0.0381406" mass="0.111868" diaginertia="3.63924e-05 2.58699e-05 1.31136e-05"/>
                <joint name="left_A_achilles_joint" pos="0 0 0" axis="1 0 0" limited="true" range="-1.208640507 0.885754595" armature="0.094889232"/>
                <geom type="mesh" class="visual" rgba="0.776471 0.756863 0.737255 1" mesh="left_A_achilles_link"/>

                <body name="left_A_achilles_rod_link" pos="-0.0112 0.0276361 0.00449975">
                  <inertial pos="-9.56643e-10 0.000182023 -0.135042" quat="0.658322 0.000443677 -0.000507307 0.752736" mass="0.109977" diaginertia="0.000696637 0.000696383 2.50649e-06"/>
                  <joint name="left_A_achilles_rod_joint" type="ball" limited="false" />
                  <geom type="mesh" class="visual" rgba="1 1 1 1" mesh="left_A_achilles_rod_link"/>
                </body>
              </body>
              <body name="left_B_achilles_link" pos="-0.0238 0.00139822 -0.205">
                <inertial pos="0.00174132 -0.00862085 0.00140362" quat="0.760852 0.646991 -0.0381406 -0.0324328" mass="0.111868" diaginertia="3.63924e-05 2.58699e-05 1.31136e-05"/>
                <joint name="left_B_achilles_joint" pos="0 0 0" axis="1 0 0" limited="true" range="-0.885754595 1.208640507" armature="0.094889232"/>
                <geom type="mesh" class="visual" rgba="0.776471 0.756863 0.737255 1" mesh="left_B_achilles_link"/>

                <body name="left_B_achilles_rod_link" pos="-0.0112 -0.0276361 0.00449963">
                  <inertial pos="-7.82931e-10 -0.000182011 -0.0900265" quat="0.707106 -0.000714791 0.000714791 0.707106" mass="0.0772071" diaginertia="0.000221257 0.000221098 2.03557e-06"/>
                  <joint name="left_B_achilles_rod_joint" type="ball" limited="false" />
                  <geom type="mesh" class="visual" rgba="1 1 1 1" mesh="left_B_achilles_rod_link"/>
                </body>
              </body>
            </body>
          </body>
        </body>
      </body>

      <!-- right leg -->
      <body name="right_hip_pitch_link" pos="0.01 -0.12109 0.00692262">
        <inertial pos="-0.0005 -0.00873 -0.08961" quat="0.676043 0.0208401 0.0138863 0.736436" mass="2.16" diaginertia="0.00371364 0.00351311 0.002873"/>
        <joint name="right_hip_pitch_joint" pos="0 0 0" axis="0 0.906308 0.422618" limited="true" range="-3.14159 3.14159" armature="0.15257125"/>
        <geom type="mesh" class="visual" rgba="0.898039 0.917647 0.929412 1" mesh="right_hip_pitch_link"/>
        <!-- <geom type="capsule" pos="0 -0.04 -0.08" size="0.055 0.02" euler="0 1.57 0" /> -->

        <body name="right_hip_roll_link" pos="-0.01 -0.00891007 -0.0954226">
          <inertial pos="0.0014 -0.00013 -0.03498" quat="0.508781 0.49127 0.494084 0.505645" mass="0.49" diaginertia="0.00183288 0.00154622 0.000941909"/>
          <joint name="right_hip_roll_joint" pos="0 0 0" axis="1 0 0" limited="true" range="-2.0944 0.523599" armature="0.15257125"/>
          <geom type="mesh" class="visual" rgba="0.792157 0.819608 0.933333 1" mesh="right_hip_roll_link"/>
          <geom type="mesh" class="visual" mesh="right_hip_roll_link"/>

          <body name="right_hip_yaw_link" pos="0 0 -0.0705">
            <inertial pos="0.00447 -0.00313 -0.17225" quat="0.701436 -0.00849079 0.00624575 0.712654" mass="4.48" diaginertia="0.0736764 0.0728051 0.00681999"/>
            <joint name="right_hip_yaw_joint" pos="0 0 0" axis="0 0 1" limited="true" range="-2.70526 2.70526" armature="0.15257125"/>
            <geom type="mesh" class="visual" rgba="0.498039 0.498039 0.498039 1" mesh="right_hip_yaw_link"/>
            <!-- <geom type="capsule" pos="0.015 -0.0 -0.14" size="0.05 0.1" euler="0 -0.1 0" /> -->
            
            <body name="right_knee_link" pos="0 0 -0.3045">
              <inertial pos="0.00745 -0.00751 -0.13644" quat="0.989694 0.0482796 0.00102543 -0.134809" mass="2.95" diaginertia="0.02787 0.0276329 0.00321862"/>
              <joint name="right_knee_joint" pos="0 0 0" axis="0 1 0" limited="true" range="-0.0872665 2.58309" armature="0.15257125"/>
              <geom type="mesh" class="visual" rgba="0.792157 0.819608 0.933333 1" mesh="right_knee_link"/>
              <!-- <geom type="capsule" pos="0.015 0.03 -0.2" size="0.035 0.14" euler="0 0.1 0" /> -->

              <body name="right_ankle_pitch_link" pos="0 -0.00139822 -0.385">
                <inertial pos="0.00015 0 0.00047" quat="0.500895 0.500895 -0.499103 0.499103" mass="0.1" diaginertia="2.208e-05 1.929e-05 6.94e-06"/>
                <joint name="right_ankle_pitch_joint" pos="0 0 0" axis="0 1 0" limited="true" range="-0.610865 0.942478"/>
                <geom type="mesh" class="visual" rgba="0.776471 0.756863 0.737255 1" mesh="right_ankle_pitch_link"/>
                <body name="right_ankle_roll_link" pos="0 0 0">
                  <inertial pos="-0.00717 0 -0.03509" quat="-7.05711e-06 0.729198 -1.68052e-06 0.684303" mass="0.88" diaginertia="0.00326308 0.00315827 0.000660841"/>
                  <joint name="right_ankle_roll_joint" pos="0 0 0" axis="1 0 0" limited="true" range="-0.436332 0.436332"/>
                  <geom type="mesh" class="visual" rgba="0.776471 0.756863 0.737255 1" mesh="right_ankle_roll_link"/>
                  <geom name="right_foot"  pos="0.001 0 -0.0535" size="0.125 0.047 0.01" type="box" rgba="0 0.4 0 0.1" />
                  
                  <body name="contact_right_heel" pos="-0.124 0 -0.0635">
                    <inertial pos="0.0 0.0 0.0" quat="1 0 0 0" mass="0.00001" diaginertia="0.00000000001 0.00000000001 0.00000000001"/>
                    <geom name="contact_right_heel" class="visual" size="0.003" type="sphere" rgba="1 0 0 1"/>
                  </body>
                  <body name="contact_right_center" pos="0.001 0 -0.0635">
                    <inertial pos="0.0 0.0 0.0" quat="1 0 0 0" mass="0.00001" diaginertia="0.00000000001 0.00000000001 0.00000000001"/>
                    <geom name="contact_right_center" class="visual" size="0.003" type="sphere" rgba="1 0 0 1"/>
                  </body>
                  <body name="contact_right_tip" pos="0.126 0 -0.0635">
                    <inertial pos="0.0 0.0 0.0" quat="1 0 0 0" mass="0.00001" diaginertia="0.00000000001 0.00000000001 0.00000000001"/>
                    <geom name="contact_right_tip" class="visual" size="0.003" type="sphere" rgba="1 0 0 1"/>
                  </body>
                </body>
              </body>
              <body name="right_A_achilles_link" pos="-0.0238 -0.00139822 -0.115">
                <inertial pos="0.00174153 -0.00862085 0.00140366" quat="0.760854 0.646989 -0.0381406 -0.0324327" mass="0.111868" diaginertia="3.63924e-05 2.58699e-05 1.31136e-05"/>
                <joint name="right_A_achilles_joint" pos="0 0 0" axis="1 0 0" limited="true" range="-0.885754595 1.208640507" armature="0.094889232"/>
                <geom type="mesh" class="visual" rgba="0.776471 0.756863 0.737255 1" mesh="right_A_achilles_link"/>
                
                <body name="right_A_achilles_rod_link" pos="-0.0112 -0.0276361 0.00449975">
                  <inertial pos="-5.39108e-12 -0.000181911 -0.134958" quat="0.99984 -0.000673849 1.20512e-05 0.0178812" mass="0.109977" diaginertia="0.000696637 0.000696383 2.50649e-06"/>
                  <joint name="right_A_achilles_rod_joint" type="ball" limited="false"/>
                  <geom type="mesh" class="visual" rgba="1 1 1 1" mesh="right_A_achilles_rod_link"/>
                </body>
              </body>
              <body name="right_B_achilles_link" pos="-0.0238 -0.00139822 -0.205">
                <inertial pos="0.00174132 0.00862085 0.00140362" quat="0.646991 0.760852 0.0324328 0.0381406" mass="0.111868" diaginertia="3.63924e-05 2.58699e-05 1.31136e-05"/>
                <joint name="right_B_achilles_joint" pos="0 0 0" axis="1 0 0" limited="true" range="-1.208640507 0.885754595" armature="0.094889232"/>
                <geom type="mesh" class="visual" rgba="0.776471 0.756863 0.737255 1" mesh="right_B_achilles_link"/>

                <body name="right_B_achilles_rod_link" pos="-0.0112 0.0276361 0.00449963">
                  <inertial pos="-8.02709e-10 0.00018201 -0.0900265" quat="0.74618 0.000754293 -0.000672981 0.665743" mass="0.0772071" diaginertia="0.000221257 0.000221098 2.03557e-06"/>
                  <joint name="right_B_achilles_rod_joint" type="ball" limited="false"/>
                  <geom type="mesh" class="visual" rgba="1 1 1 1" mesh="right_B_achilles_rod_link"/>
                </body>
              </body>
            </body>
          </body>
        </body>
      </body>

      <!-- waist -->
      <body name="waist_yaw_link" pos="0 0 0.0925">
        <inertial pos="0.0151 7e-05 0.02661" quat="0.576844 0.424561 0.44742 0.53555" mass="0.86" diaginertia="0.00149726 0.00140092 0.000900536"/>
        <joint name="waist_yaw_joint" pos="0 0 0" axis="0 0 1" limited="true" range="-2.61799 2.61799" armature="0.094889232"/>
        <geom type="mesh" class="visual" rgba="0.898039 0.917647 0.929412 1" mesh="waist_yaw_link"/>

        <body name="waist_roll_link" pos="0 0 0.062">
          <inertial pos="-0.00016 8e-05 -9e-05" quat="0.500061 0.500014 -0.499986 0.499939" mass="0.46" diaginertia="0.00028921 0.00022264 0.00011704"/>
          <joint name="waist_roll_joint" pos="0 0 0" axis="1 0 0" limited="true" range="-0.523599 0.523599"/>
          <geom type="mesh" class="visual" rgba="0.776471 0.756863 0.737255 1" mesh="waist_roll_link"/>

          <!-- upper body -->
          <body name="waist_pitch_link" pos="0 0 0">
            <inertial pos="-0.01035 0.00053 0.2017" quat="0.998415 -0.00424414 -0.0561196 -1.43367e-05" mass="10.96" diaginertia="0.169612 0.132956 0.0890119"/>
            <joint name="waist_pitch_joint" pos="0 0 0" axis="0 1 0" limited="true" range="-0.523599 0.785398"/>
            <geom type="mesh" class="visual" rgba="0.898039 0.921569 0.929412 1" mesh="waist_pitch_link"/>
            <!-- <geom type="capsule" pos="-0.01 0 0.23" size="0.1 0.08" euler="1.57 0 0" />
            <geom type="capsule" pos="-0.03 0 0.07" size="0.06 0.06" euler="1.57 0 0" />
            <geom type="capsule" pos="0.065 0 0.1" size="0.04 0.06" euler="1.57 0 0" /> -->

            <body name="waist_A_link" pos="0 0.0925 0.064">
              <inertial pos="0.0276856 -0.0113695 -0.0100785" quat="0.463231 0.617963 0.534278 0.343636" mass="0.162449" diaginertia="0.000117685 0.00010787 1.93343e-05"/>
              <joint name="waist_A_joint" pos="0 0 0" axis="0 1 0" limited="true" range="-0.785398 0.523599" armature="0.094889232"/>
              <geom type="mesh" class="visual" rgba="0.776471 0.756863 0.737255 1" mesh="waist_A_link"/>

              <body name="waist_A_rod_link" pos="0.0638991 -0.0325 -0.0232574">
                <inertial pos="3.61345e-11 4.43585e-10 -0.032" quat="0.735247 0 0 0.677799" mass="0.0614769" diaginertia="3.44143e-05 3.1751e-05 3.15441e-06"/>
                <joint name="waist_A_rod_joint" type="ball" limited="false"/>
                <geom type="mesh" class="visual" rgba="0.776471 0.756863 0.737255 1" mesh="waist_A_rod_link"/>
              </body>
            </body>
            <body name="waist_B_link" pos="0 -0.0925 0.064">
              <inertial pos="0.0276868 0.0113695 -0.0100754" quat="0.343622 0.534268 0.618029 0.463165" mass="0.162449" diaginertia="0.000117685 0.00010787 1.93343e-05"/>
              <joint name="waist_B_joint" pos="0 0 0" axis="0 1 0" limited="true" range="-0.785398 0.523599" armature="0.094889232"/>
              <geom type="mesh" class="visual" rgba="0.776471 0.756863 0.737255 1" mesh="waist_B_link"/>

              <body name="waist_B_rod_link" pos="0.0638991 0.0325 -0.0232574">
                <inertial pos="1.41023e-10 4.22113e-10 -0.032" quat="0.811452 0 0 0.58442" mass="0.0614769" diaginertia="3.44143e-05 3.1751e-05 3.15441e-06"/>
                <joint name="waist_B_rod_joint" type="ball" limited="false"/>
                <geom type="mesh" class="visual" rgba="0.776471 0.756863 0.737255 1" mesh="waist_B_rod_link"/>
              </body>
            </body>

            <!-- left arm -->
            <body name="left_shoulder_pitch_link" pos="0 0.1575 0.2822">
              <inertial pos="0.00475 0.02422 -0.00034" quat="-0.207346 0.676001 0.207484 0.676004" mass="0.18" diaginertia="0.00028266 0.000238547 0.000176373"/>
              <joint name="left_shoulder_pitch_joint" pos="0 0 0" axis="0 1 0" limited="true" range="-2.79253 2.79253" armature="0.045760625"/>
              <geom type="mesh" class="visual" rgba="0.898039 0.917647 0.929412 1" mesh="left_shoulder_pitch_link"/>

              <body name="left_shoulder_roll_link" pos="0 0.055 0">
                <inertial pos="0.00351 -0.00209 -0.04367" quat="0.986876 0.0163368 0.0422814 -0.154988" mass="1.84" diaginertia="0.00541704 0.00531188 0.00161861"/>
                <joint name="left_shoulder_roll_joint" pos="0 0 0" axis="1 0 0" limited="true" range="-0.0872665 3.22886" armature="0.045760625"/>
                <geom type="mesh" class="visual" rgba="0.792157 0.819608 0.933333 1" mesh="left_shoulder_roll_link"/>
                <!-- <geom type="capsule" pos="0 0 0" size="0.04 0.03" euler="0 1.57 0" /> -->

                <body name="left_shoulder_yaw_link" pos="0 0 -0.1306">
                  <inertial pos="-0.00939 0.00412 -0.06099" quat="0.994517 0.0765298 0.0235208 -0.0672689" mass="0.27" diaginertia="0.000742676 0.000660189 0.000323165"/>
                  <joint name="left_shoulder_yaw_joint" pos="0 0 0" axis="0 0 1" limited="true" range="-1.5708 1.5708" armature="0.045760625"/>
                  <geom type="mesh" class="visual" rgba="0.898039 0.917647 0.929412 1" mesh="left_shoulder_yaw_link"/>

                  <body name="left_elbow_link" pos="0 0 -0.1157">
                    <inertial pos="9e-05 0.0051 -0.02553" quat="0.72332 -0.0286946 0.0280374 0.689347" mass="1.2" diaginertia="0.00246184 0.00240521 0.000806209"/>
                    <joint name="left_elbow_joint" pos="0 0 0" axis="0 1 0" limited="true" range="-2.0944 1.0472" armature="0.045760625"/>
                    <geom type="mesh" class="visual" rgba="0.792157 0.819608 0.933333 1" mesh="left_elbow_link"/>
                    <!-- <geom type="capsule" pos="0 0 0" size="0.04 0.03" euler="1.57 0 0" /> -->

                    <body name="left_wrist_yaw_link" pos="0 0 -0.1048">
                      <inertial pos="0 0.00032 -0.0103" quat="0.504976 0.516322 -0.494484 0.483628" mass="0.07" diaginertia="5.40613e-05 5.38296e-05 3.19891e-05"/>
                      <joint name="left_wrist_yaw_joint" pos="0 0 0" axis="0 0 1" limited="true" range="-1.5708 1.5708" armature="0.010625"/>
                      <geom type="mesh" class="visual" rgba="0.898039 0.917647 0.929412 1" mesh="left_wrist_yaw_link"/>

                      <body name="left_wrist_pitch_link" pos="0 0 -0.0315">
                        <inertial pos="0.00125 0.00272 -0.0656" quat="0.704072 -0.0486096 0.018666 0.708217" mass="0.62" diaginertia="0.00089002 0.000861566 0.000294934"/>
                        <joint name="left_wrist_pitch_joint" pos="0 0 0" axis="0 1 0" limited="true" range="-1.5708 1.5708" armature="0.010625"/>
                        <geom type="mesh" class="visual" rgba="0.898039 0.917647 0.929412 1" mesh="left_wrist_pitch_link"/>

                        <body name="left_hand_yaw_link" pos="0 0 -0.0845">
                          <inertial pos="0 -1e-05 -0.05474" quat="1 0.000173162 -2.74799e-05 4.80685e-05" mass="0.24" diaginertia="0.00049534 0.00039126 0.00013139"/>
                          <joint name="left_hand_yaw_joint" pos="0 0 0" axis="0 0 1" limited="true" range="-3.14159 3.14159" armature="0.010625"/>
                          <geom type="mesh" class="visual" rgba="0.792157 0.819608 0.933333 1" mesh="left_hand_yaw_link"/>
                          <body name="contact_left_hand" pos="0.0 0 0.0">
                            <inertial pos="0.0 0.0 0.0" quat="1 0 0 0" mass="0.00001" diaginertia="0.00000000001 0.00000000001 0.00000000001"/>
                            <geom name="contact_left_hand" class="visual" size="0.003" type="sphere" rgba="1 0 0 1"/>
                          </body>
                          <!-- <geom type="capsule" pos="0 0 -0.09" size="0.035 0.06" euler="0 0 0" /> -->
                        </body>
                      </body>
                    </body>
                  </body>
                </body>
              </body>
            </body>

            <!-- right arm -->
            <body name="right_shoulder_pitch_link" pos="0 -0.1575 0.2822">
              <inertial pos="0.00475 -0.02422 -0.00034" quat="0.207346 0.676001 -0.207484 0.676004" mass="0.18" diaginertia="0.00028266 0.000238547 0.000176373"/>
              <joint name="right_shoulder_pitch_joint" pos="0 0 0" axis="0 1 0" limited="true" range="-2.79253 2.79253" armature="0.045760625"/>
              <geom type="mesh" class="visual" rgba="0.898039 0.917647 0.929412 1" mesh="right_shoulder_pitch_link"/>

              <body name="right_shoulder_roll_link" pos="0 -0.055 0">
                <inertial pos="0.00351 0.00209 -0.04367" quat="0.986876 -0.0163368 0.0422814 0.154988" mass="1.84" diaginertia="0.00541704 0.00531188 0.00161861"/>
                <joint name="right_shoulder_roll_joint" pos="0 0 0" axis="1 0 0" limited="true" range="-3.22886 0.0872665" armature="0.045760625"/>
                <geom type="mesh" class="visual" rgba="0.698039 0.698039 0.698039 1" mesh="right_shoulder_roll_link"/>
                <!-- <geom type="capsule" pos="0 0 0" size="0.04 0.03" euler="0 1.57 0" /> -->

                <body name="right_shoulder_yaw_link" pos="0 0 -0.1306">
                  <inertial pos="-0.00939 -0.00412 -0.06099" quat="0.994517 -0.0765298 0.0235208 0.0672689" mass="0.27" diaginertia="0.000742676 0.000660189 0.000323165"/>
                  <joint name="right_shoulder_yaw_joint" pos="0 0 0" axis="0 0 1" limited="true" range="-1.5708 1.5708" armature="0.045760625"/>
                  <geom type="mesh" class="visual" rgba="0.898039 0.917647 0.929412 1" mesh="right_shoulder_yaw_link"/>
                  <geom type="mesh" class="visual" mesh="right_shoulder_yaw_link"/>

                  <body name="right_elbow_link" pos="0 0 -0.1157">
                    <inertial pos="9e-05 -0.0051 -0.02553" quat="0.689347 0.0280374 -0.0286946 0.72332" mass="1.2" diaginertia="0.00246184 0.00240521 0.000806209"/>
                    <joint name="right_elbow_joint" pos="0 0 0" axis="0 1 0" limited="true" range="-2.0944 1.0472" armature="0.045760625"/>
                    <geom type="mesh" class="visual" rgba="0.792157 0.819608 0.933333 1" mesh="right_elbow_link"/>
                    <!-- <geom type="capsule" pos="0 0 0" size="0.04 0.03" euler="1.57 0 0" /> -->

                    <body name="right_wrist_yaw_link" pos="0 0 -0.1048">
                      <inertial pos="0 -0.00032 -0.0103" quat="0.516322 0.504976 -0.483628 0.494484" mass="0.07" diaginertia="5.40613e-05 5.38296e-05 3.19891e-05"/>
                      <joint name="right_wrist_yaw_joint" pos="0 0 0" axis="0 0 1" limited="true" range="-1.5708 1.5708" armature="0.010625"/>
                      <geom type="mesh" class="visual" rgba="0.898039 0.917647 0.929412 1" mesh="right_wrist_yaw_link"/>

                      <body name="right_wrist_pitch_link" pos="0 0 -0.0315">
                        <inertial pos="0.00125 -0.00272 -0.0656" quat="0.708217 0.018666 -0.0486096 0.704072" mass="0.62" diaginertia="0.00089002 0.000861566 0.000294934"/>
                        <joint name="right_wrist_pitch_joint" pos="0 0 0" axis="0 1 0" limited="true" range="-1.5708 1.5708" armature="0.010625"/>
                        <geom type="mesh" class="visual" rgba="1 1 1 1" mesh="right_wrist_pitch_link"/>

                        <body name="right_hand_yaw_link" pos="0 0 -0.0845">
                          <inertial pos="0 1e-05 -0.05474" quat="1 -0.000173162 -2.74799e-05 -4.80685e-05" mass="0.24" diaginertia="0.00049534 0.00039126 0.00013139"/>
                          <joint name="right_hand_yaw_joint" pos="0 0 0" axis="0 0 1" limited="true" range="-3.14159 3.14159" armature="0.010625"/>
                          <geom type="mesh" class="visual" rgba="0.792157 0.819608 0.933333 1" mesh="right_hand_yaw_link"/>
                          <!-- <geom type="capsule" pos="0 0 -0.09" size="0.035 0.06" euler="0 0 0" /> -->
                          <body name="contact_right_hand" pos="0.0 0 0.0">
                            <inertial pos="0.0 0.0 0.0" quat="1 0 0 0" mass="0.00001" diaginertia="0.00000000001 0.00000000001 0.00000000001"/>
                            <geom name="contact_right_hand" class="visual" size="0.003" type="sphere" rgba="1 0 0 1"/>
                          </body>
                        </body>
                      </body>
                    </body>
                  </body>
                </body>
              </body>
            </body>
            <body name="head_yaw_link" pos="-0.013 0 0.3837">
              <inertial pos="0.00016 0.00514 0.03984" quat="0.992431 -0.100578 -0.032204 0.0626632" mass="0.3" diaginertia="0.000140225 0.000138383 0.000124932"/>
              <joint name="head_yaw_joint" pos="0 0 0" axis="0 0 1" limited="true" range="-0.785398 0.785398" armature="0.010625"/>
              <geom type="mesh" class="visual" rgba="0.898039 0.917647 0.929412 1" mesh="head_yaw_link"/>
              <body name="head_pitch_link" pos="0 0.02325 0.0415">
                <inertial pos="-0.00082 -0.02259 0.07756" quat="0.0129205 0.747799 0.0164911 0.663595" mass="0.61" diaginertia="0.00283931 0.00205117 0.00159809"/>
                <joint name="head_pitch_joint" pos="0 0 0" axis="0 1 0" limited="true" range="-0.523599 0.959931" armature="0.010625"/>
                <geom type="mesh" class="visual" rgba="0.792157 0.819608 0.933333 1" mesh="head_pitch_link"/>
                <!-- <geom type="ellipsoid" pos="0.0 0 0.02" size="0.1 0.11 0.06" euler="0 0 0" /> -->
              </body>
            </body>
          </body>
        </body>
      </body>
    </body>
  </worldbody>

  <equality>
    <connect name='A_achilles_connect_L' body1='left_ankle_roll_link' body2='left_A_achilles_rod_link' anchor='-0.035 0.028 0.0045'/>
    <connect name='B_achilles_connect_L' body1='left_ankle_roll_link' body2='left_B_achilles_rod_link' anchor='-0.035 -0.028 0.0045'/>

    <connect name='A_achilles_connect_R' body1='right_ankle_roll_link' body2='right_A_achilles_rod_link' anchor='-0.035 -0.028 0.0045'/>
    <connect name='B_achilles_connect_R' body1='right_ankle_roll_link' body2='right_B_achilles_rod_link' anchor='-0.035 0.028 0.0045'/>

    <connect name='waist_connect_A' body1='waist_yaw_link' body2='waist_A_rod_link' anchor='0.0639 0.06 0.0387'/>
    <connect name='waist_connect_B' body1='waist_yaw_link' body2='waist_B_rod_link' anchor='0.0639 -0.06 0.0387'/>
  </equality>

  <actuator>
    <motor name="hip_pitch_left" gear="1" joint="left_hip_pitch_joint" ctrllimited="true" ctrlrange="-120 120" />
    <motor name="hip_roll_left" gear="1" joint="left_hip_roll_joint" ctrllimited="true" ctrlrange="-120 120" />
    <motor name="hip_yaw_left" gear="1" joint="left_hip_yaw_joint" ctrllimited="true" ctrlrange="-120 120" />
    <motor name="knee_left" gear="1" joint="left_knee_joint" ctrllimited="true" ctrlrange="-120 120" />
    <motor name="ankle_A_left" gear="1" joint="left_A_achilles_joint" ctrllimited="true" ctrlrange="-45 45" />
    <motor name="ankle_B_left" gear="1" joint="left_B_achilles_joint" ctrllimited="true" ctrlrange="-45 45" />

    <motor name="hip_pitch_right" gear="1" joint="right_hip_pitch_joint" ctrllimited="true" ctrlrange="-120 120" />
    <motor name="hip_roll_right" gear="1" joint="right_hip_roll_joint" ctrllimited="true" ctrlrange="-120 120" />
    <motor name="hip_yaw_right" gear="1" joint="right_hip_yaw_joint" ctrllimited="true" ctrlrange="-120 120" />
    <motor name="knee_right" gear="1" joint="right_knee_joint" ctrllimited="true" ctrlrange="-120 120" />
    <motor name="ankle_A_right" gear="1" joint="right_A_achilles_joint" ctrllimited="true" ctrlrange="-45 45" />
    <motor name="ankle_B_right" gear="1" joint="right_B_achilles_joint" ctrllimited="true" ctrlrange="-45 45" />

    <motor name="body_waist_yaw" gear="1" joint="waist_yaw_joint" ctrllimited="true" ctrlrange="-45 45" />
    <motor name="body_waist_B" gear="1" joint="waist_B_joint" ctrllimited="true" ctrlrange="-45 45" />
    <motor name="body_waist_A" gear="1" joint="waist_A_joint" ctrllimited="true" ctrlrange="-45 45" />

    <motor name="head_yaw" gear="1" joint="head_yaw_joint" ctrllimited="true" ctrlrange="-45 45" />
    <motor name="head_pitch" gear="1" joint="head_pitch_joint" ctrllimited="true" ctrlrange="-45 45" />

    <motor name="shoulder_pitch_left" gear="1" joint="left_shoulder_pitch_joint" ctrllimited="true" ctrlrange="-30 30" />
    <motor name="shoulder_roll_left" gear="1" joint="left_shoulder_roll_joint" ctrllimited="true" ctrlrange="-30 30" />
    <motor name="shoulder_yaw_left" gear="1" joint="left_shoulder_yaw_joint" ctrllimited="true" ctrlrange="-30 30" />
    <motor name="elbow_left" gear="1" joint="left_elbow_joint" ctrllimited="true" ctrlrange="-30 30" />
    <motor name="wrist_yaw_left" gear="1" joint="left_wrist_yaw_joint" ctrllimited="true" ctrlrange="-18 18" />
    <motor name="wrist_pitch_left" gear="1" joint="left_wrist_pitch_joint" ctrllimited="true" ctrlrange="-18 18" />
    <motor name="hand_yaw_left" gear="1" joint="left_hand_yaw_joint" ctrllimited="true" ctrlrange="-18 18" />

    <motor name="shoulder_pitch_right" gear="1" joint="right_shoulder_pitch_joint" ctrllimited="true" ctrlrange="-30 30" />
    <motor name="shoulder_roll_right" gear="1" joint="right_shoulder_roll_joint" ctrllimited="true" ctrlrange="-30 30" />
    <motor name="shoulder_yaw_right" gear="1" joint="right_shoulder_yaw_joint" ctrllimited="true" ctrlrange="-30 30" />
    <motor name="elbow_right" gear="1" joint="right_elbow_joint" ctrllimited="true" ctrlrange="-30 30" />
    <motor name="wrist_yaw_right" gear="1" joint="right_wrist_yaw_joint" ctrllimited="true" ctrlrange="-18 18" />
    <motor name="wrist_pitch_right" gear="1" joint="right_wrist_pitch_joint" ctrllimited="true" ctrlrange="-18 18" />
    <motor name="hand_yaw_right" gear="1" joint="right_hand_yaw_joint" ctrllimited="true" ctrlrange="-18 18" />
  </actuator>

  <sensor>
    <framequat name="Body_Quat" objtype="site" objname="imu" noise="0.0" />
    <gyro name="Body_Gyro" site="imu" noise="0.0" />
    <accelerometer name="Body_Acc" site="imu" noise="0.0" />

    <!-- Left leg sensors -->
    <jointpos name="left_hip_pitch_pos" joint="left_hip_pitch_joint" noise="0.0"/>
    <jointpos name="left_hip_roll_pos" joint="left_hip_roll_joint" noise="0.0"/>
    <jointpos name="left_hip_yaw_pos" joint="left_hip_yaw_joint" noise="0.0"/>
    <jointpos name="left_knee_pos" joint="left_knee_joint" noise="0.0"/>
    <jointpos name="left_A_achilles_pos" joint="left_A_achilles_joint" noise="0.0"/>
    <jointpos name="left_B_achilles_pos" joint="left_B_achilles_joint" noise="0.0"/>
    <!-- Right leg sensors -->
    <jointpos name="right_hip_pitch_pos" joint="right_hip_pitch_joint" noise="0.0"/>
    <jointpos name="right_hip_roll_pos" joint="right_hip_roll_joint" noise="0.0"/>
    <jointpos name="right_hip_yaw_pos" joint="right_hip_yaw_joint" noise="0.0"/>
    <jointpos name="right_knee_pos" joint="right_knee_joint" noise="0.0"/>
    <jointpos name="right_A_achilles_pos" joint="right_A_achilles_joint" noise="0.0"/>
    <jointpos name="right_B_achilles_pos" joint="right_B_achilles_joint" noise="0.0"/>
    <!-- Waist sensors -->
    <jointpos name="waist_yaw_pos" joint="waist_yaw_joint" noise="0.0"/>
    <jointpos name="waist_B_pos" joint="waist_B_joint" noise="0.0"/>
    <jointpos name="waist_A_pos" joint="waist_A_joint" noise="0.0"/>
    <!-- Neck sensors -->
    <jointpos name="head_yaw_pos" joint="head_yaw_joint" noise="0.0"/>
    <jointpos name="head_pitch_pos" joint="head_pitch_joint" noise="0.0"/>
    <!-- Left arm sensors -->
    <jointpos name="left_shoulder_pitch_pos" joint="left_shoulder_pitch_joint" noise="0.0"/>
    <jointpos name="left_shoulder_roll_pos" joint="left_shoulder_roll_joint" noise="0.0"/>
    <jointpos name="left_shoulder_yaw_pos" joint="left_shoulder_yaw_joint" noise="0.0"/>
    <jointpos name="left_elbow_pos" joint="left_elbow_joint" noise="0.0"/>
    <jointpos name="left_wrist_yaw_pos" joint="left_wrist_yaw_joint" noise="0.0"/>
    <jointpos name="left_wrist_pitch_pos" joint="left_wrist_pitch_joint" noise="0.0"/>
    <jointpos name="left_hand_yaw_pos" joint="left_hand_yaw_joint" noise="0.0"/>
    <!-- Right arm sensors -->
    <jointpos name="right_shoulder_pitch_pos" joint="right_shoulder_pitch_joint" noise="0.0"/>
    <jointpos name="right_shoulder_roll_pos" joint="right_shoulder_roll_joint" noise="0.0"/>
    <jointpos name="right_shoulder_yaw_pos" joint="right_shoulder_yaw_joint" noise="0.0"/>
    <jointpos name="right_elbow_pos" joint="right_elbow_joint" noise="0.0"/>
    <jointpos name="right_wrist_yaw_pos" joint="right_wrist_yaw_joint" noise="0.0"/>
    <jointpos name="right_wrist_pitch_pos" joint="right_wrist_pitch_joint" noise="0.0"/>
    <jointpos name="right_hand_yaw_pos" joint="right_hand_yaw_joint" noise="0.0"/>

    <!-- Left leg sensors -->
    <jointvel name="left_hip_pitch_vel" joint="left_hip_pitch_joint" noise="0.0"/>
    <jointvel name="left_hip_roll_vel" joint="left_hip_roll_joint" noise="0.0"/>
    <jointvel name="left_hip_yaw_vel" joint="left_hip_yaw_joint" noise="0.0"/>
    <jointvel name="left_knee_vel" joint="left_knee_joint" noise="0.0"/>
    <jointvel name="left_A_achilles_vel" joint="left_A_achilles_joint" noise="0.0"/>
    <jointvel name="left_B_achilles_vel" joint="left_B_achilles_joint" noise="0.0"/>
    <!-- Right leg sensors -->
    <jointvel name="right_hip_pitch_vel" joint="right_hip_pitch_joint" noise="0.0"/>
    <jointvel name="right_hip_roll_vel" joint="right_hip_roll_joint" noise="0.0"/>
    <jointvel name="right_hip_yaw_vel" joint="right_hip_yaw_joint" noise="0.0"/>
    <jointvel name="right_knee_vel" joint="right_knee_joint" noise="0.0"/>
    <jointvel name="right_A_achilles_vel" joint="right_A_achilles_joint" noise="0.0"/>
    <jointvel name="right_B_achilles_vel" joint="right_B_achilles_joint" noise="0.0"/>
    <!-- Waist sensors -->
    <jointvel name="waist_yaw_vel" joint="waist_yaw_joint" noise="0.0"/>
    <jointvel name="waist_B_vel" joint="waist_B_joint" noise="0.0"/>
    <jointvel name="waist_A_vel" joint="waist_A_joint" noise="0.0"/>
    <!-- Neck sensors -->
    <jointvel name="head_yaw_vel" joint="head_yaw_joint" noise="0.0"/>
    <jointvel name="head_pitch_vel" joint="head_pitch_joint" noise="0.0"/>
    <!-- Left arm sensors -->
    <jointvel name="left_shoulder_pitch_vel" joint="left_shoulder_pitch_joint" noise="0.0"/>
    <jointvel name="left_shoulder_roll_vel" joint="left_shoulder_roll_joint" noise="0.0"/>
    <jointvel name="left_shoulder_yaw_vel" joint="left_shoulder_yaw_joint" noise="0.0"/>
    <jointvel name="left_elbow_vel" joint="left_elbow_joint" noise="0.0"/>
    <jointvel name="left_wrist_yaw_vel" joint="left_wrist_yaw_joint" noise="0.0"/>
    <jointvel name="left_wrist_pitch_vel" joint="left_wrist_pitch_joint" noise="0.0"/>
    <jointvel name="left_hand_yaw_vel" joint="left_hand_yaw_joint" noise="0.0"/>
    <!-- Right arm sensors -->
    <jointvel name="right_shoulder_pitch_vel" joint="right_shoulder_pitch_joint" noise="0.0"/>
    <jointvel name="right_shoulder_roll_vel" joint="right_shoulder_roll_joint" noise="0.0"/>
    <jointvel name="right_shoulder_yaw_vel" joint="right_shoulder_yaw_joint" noise="0.0"/>
    <jointvel name="right_elbow_vel" joint="right_elbow_joint" noise="0.0"/>
    <jointvel name="right_wrist_yaw_vel" joint="right_wrist_yaw_joint" noise="0.0"/>
    <jointvel name="right_wrist_pitch_vel" joint="right_wrist_pitch_joint" noise="0.0"/>
    <jointvel name="right_hand_yaw_vel" joint="right_hand_yaw_joint" noise="0.0"/>
  </sensor>
</mujoco>
