<mujoco model="HU_D03_03">
  <compiler angle="radian" meshdir="../meshes/HU_D03_03/"/>
  <size njmax="5000" nconmax="1000"/>

  <default>
    <light castshadow="false" diffuse="1 1 1" />
    <camera fovy="60" />
    <default class="visual">
      <geom contype="0" conaffinity="0" group="1" type="mesh" rgba="0.8 0.8 0.8 1.0" />
    </default>
    <joint damping="0.01" margin="0.0001" />
    <geom contype="1" conaffinity="1" friction="1.0 0.3 0.3" rgba="0.5 0.6 0.7 0.5" margin="0.001" group="0" />
    <equality solref="0.001  1" />
  </default>

  <option timestep="0.001" />
  <!-- <option>
    <flag sensornoise="enable" />
  </option> -->

  <visual>
    <rgba com="0.502 1.0 0 1.0" contactpoint="0.5 0.1 0.8 0.4" contactforce="0.2 0.98 0.2 0.8" />
    <scale com="0.2" forcewidth="0.05" contactwidth="0.10" contactheight="0.04" />
  </visual>

  <asset>
    <mesh name="base_link" file="base_link.STL"/>
    <mesh name="left_hip_pitch_link" file="left_hip_pitch_link.STL"/>
    <mesh name="left_hip_roll_link" file="left_hip_roll_link.STL"/>
    <mesh name="left_hip_yaw_link" file="left_hip_yaw_link.STL"/>
    <mesh name="left_knee_link" file="left_knee_link.STL"/>
    <mesh name="left_ankle_pitch_link" file="left_ankle_pitch_link.STL"/>
    <mesh name="left_ankle_roll_link" file="left_ankle_roll_link.STL"/>
    <mesh name="left_A_achilles_link" file="left_A_achilles_link.STL"/>
    <mesh name="left_A_achilles_rod_link" file="left_A_achilles_rod_link.STL"/>
    <mesh name="left_A_achilles_cp_link" file="left_A_achilles_cp_link.STL"/>
    <mesh name="left_B_achilles_link" file="left_B_achilles_link.STL"/>
    <mesh name="left_B_achilles_rod_link" file="left_B_achilles_rod_link.STL"/>
    <mesh name="left_B_achilles_cp_link" file="left_B_achilles_cp_link.STL"/>
    <mesh name="right_hip_pitch_link" file="right_hip_pitch_link.STL"/>
    <mesh name="right_hip_roll_link" file="right_hip_roll_link.STL"/>
    <mesh name="right_hip_yaw_link" file="right_hip_yaw_link.STL"/>
    <mesh name="right_knee_link" file="right_knee_link.STL"/>
    <mesh name="right_ankle_pitch_link" file="right_ankle_pitch_link.STL"/>
    <mesh name="right_ankle_roll_link" file="right_ankle_roll_link.STL"/>
    <mesh name="right_A_achilles_link" file="right_A_achilles_link.STL"/>
    <mesh name="right_A_achilles_rod_link" file="right_A_achilles_rod_link.STL"/>
    <mesh name="right_A_achilles_cp_link" file="right_A_achilles_cp_link.STL"/>
    <mesh name="right_B_achilles_link" file="right_B_achilles_link.STL"/>
    <mesh name="right_B_achilles_rod_link" file="right_B_achilles_rod_link.STL"/>
    <mesh name="right_B_achilles_cp_link" file="right_B_achilles_cp_link.STL"/>
    <mesh name="waist_yaw_link" file="waist_yaw_link.STL"/>
    <mesh name="waist_roll_link" file="waist_roll_link.STL"/>
    <mesh name="waist_pitch_link" file="waist_pitch_link.STL"/>
    <mesh name="waist_A_link" file="waist_A_link.STL"/>
    <mesh name="waist_A_rod_link" file="waist_A_rod_link.STL"/>
    <mesh name="waist_A_cp_link" file="waist_A_cp_link.STL"/>
    <mesh name="waist_B_link" file="waist_B_link.STL"/>
    <mesh name="waist_B_rod_link" file="waist_B_rod_link.STL"/>
    <mesh name="waist_B_cp_link" file="waist_B_cp_link.STL"/>
    <mesh name="left_shoulder_pitch_link" file="left_shoulder_pitch_link.STL"/>
    <mesh name="left_shoulder_roll_link" file="left_shoulder_roll_link.STL"/>
    <mesh name="left_shoulder_yaw_link" file="left_shoulder_yaw_link.STL"/>
    <mesh name="left_elbow_link" file="left_elbow_link.STL"/>
    <mesh name="left_wrist_yaw_link" file="left_wrist_yaw_link.STL"/>
    <mesh name="left_wrist_pitch_link" file="left_wrist_pitch_link.STL"/>
    <mesh name="left_hand_yaw_link" file="left_hand_yaw_link.STL"/>
    <mesh name="right_shoulder_pitch_link" file="right_shoulder_pitch_link.STL"/>
    <mesh name="right_shoulder_roll_link" file="right_shoulder_roll_link.STL"/>
    <mesh name="right_shoulder_yaw_link" file="right_shoulder_yaw_link.STL"/>
    <mesh name="right_elbow_link" file="right_elbow_link.STL"/>
    <mesh name="right_wrist_yaw_link" file="right_wrist_yaw_link.STL"/>
    <mesh name="right_wrist_pitch_link" file="right_wrist_pitch_link.STL"/>
    <mesh name="right_hand_yaw_link" file="right_hand_yaw_link.STL"/>
    <mesh name="head_yaw_link" file="neck_yaw_link.STL"/>
    <mesh name="head_pitch_link" file="neck_pitch_link.STL"/>
  </asset>

  <asset>
    <texture type="skybox" builtin="gradient" width="512" height="512" rgb1="1.0 1.0 1.0" rgb2="1.0 1.0 1.0" />
    <texture name="plane" type="2d" builtin="flat" rgb1="1 1 1" rgb2="1 1 1" width="512" height="512" mark="cross" markrgb="0 0 0" />
    <material name="plane" reflectance="0.0" texture="plane" texrepeat="3 3" texuniform="true" />
  </asset>

  <worldbody>
    <geom name="floor" pos="0 0 0" euler="0 0 0" size="0 0 1" type="plane" material="plane" condim="3" conaffinity="1" contype="1" rgba="1 1 1 1" />
    <light directional="true" diffuse=".8 .8 .8" pos="0 0 10" dir="0 0 -10" />
    <camera name="track" mode="trackcom" pos="0 -2.3 1.6" xyaxes="1 0 0 0 0.707 0.707" />

    <body name="base_link" pos="0 0 1.0">
      <inertial pos="-0.0041214 5.036e-05 0.034849" quat="0.607398 0.607794 -0.361622 0.361779" mass="5.765" diaginertia="0.039475 0.035039 0.014476"/>
      <joint name="floating_base_joint" type="free" damping="0.00000001" stiffness="0.000000001"/>
      <geom type="mesh" class="visual" rgba="1 1 1 1" mesh="base_link"/>
      <geom pos="-0.06 0 0.05" euler="0 0 0" size="0.047 0.04" type="cylinder" />
      <geom pos="0.01 0.08 0.025" euler="1.15 0 0" size="0.055 0.03" type="cylinder" />
      <geom pos="0.01 -0.08 0.025" euler="-1.15 0 0" size="0.055 0.03" type="cylinder" />
      <site name="imu" rgba="0 1 0 1" pos="0 0 0" />

      <!-- left leg -->
      <body name="left_hip_pitch_link" pos="0.01 0.12109 0.0069226">
        <inertial pos="-0.00067024 0.0087587 -0.088316" quat="0.711002 0.0261725 -0.000169804 0.702703" mass="2.186" diaginertia="0.00390314 0.00364446 0.0028991"/>
        <joint name="left_hip_pitch_joint" pos="0 0 0" axis="0 0.906308 -0.422619" limited="true" range="-3.1415 3.1415" armature="0.15257125"/>
        <geom type="mesh" class="visual" rgba="1 1 1 1" mesh="left_hip_pitch_link"/>
        <geom type="cylinder" pos="-0.0107 0.0089 -0.0954" size="0.05 0.06" euler="0 1.57 0" />
        <body name="left_hip_roll_link" pos="-0.01 0.0089101 -0.095423">
          <inertial pos="0.002905 0.00013123 -0.0338674" quat="0.512047 0.487457 0.48466 0.515071" mass="0.5" diaginertia="0.00189968 0.001593 0.000969846"/>
          <joint name="left_hip_roll_joint" pos="0 0 0" axis="1 0 0" limited="true" range="-0.524 2.094" armature="0.15257125"/>
          <geom type="mesh" class="visual" rgba="1 1 1 1" mesh="left_hip_roll_link"/>
          <body name="left_hip_yaw_link" pos="0 0 -0.0705">
            <inertial pos="0.00460206 0.00320001 -0.171877" quat="0.71696 0.00631696 -0.0086909 0.697031" mass="4.43" diaginertia="0.0726279 0.0717733 0.00671698"/>
            <joint name="left_hip_yaw_joint" pos="0 0 0" axis="0 0 1" limited="true" range="-2.705 2.705" armature="0.15257125"/>
            <geom type="mesh" class="visual" rgba="1 1 1 1" mesh="left_hip_yaw_link"/>
            <geom type="capsule" pos="0.015 -0.0 -0.14" size="0.05 0.1" euler="0 -0.1 0" />
            <body name="left_knee_link" pos="0 0 -0.3045">
              <inertial pos="0.0095585 0.0080121 -0.13546" quat="0.995593 -0.0468788 -0.00458286 0.0810935" mass="2.844" diaginertia="0.0275684 0.0271599 0.00318662"/>
              <joint name="left_knee_joint" pos="0 0 0" axis="0 1 0" limited="true" range="-0.087 2.583" armature="0.15257125"/>
              <geom type="mesh" class="visual" rgba="1 1 1 1" mesh="left_knee_link"/>
              <geom type="capsule" pos="0.015 0.0 -0.2" size="0.035 0.14" euler="0 0.1 0" />
              <body name="left_ankle_pitch_link" pos="0 0.0013982 -0.3855">
                <inertial pos="0.00014602 0.00019049 0.00096596" quat="0.5 0.5 -0.5 0.5" mass="0.099" diaginertia="2.26e-05 1.98e-05 6.94e-06"/>
                <joint name="left_ankle_pitch_joint" pos="0 0 0" axis="0 1 0" limited="true" range="-0.95 0.611"/>
                <geom type="mesh" class="visual" rgba="1 1 1 1" mesh="left_ankle_pitch_link"/>
                <body name="left_ankle_roll_link" pos="0 0 0">
                  <inertial pos="0.0132965 0 -0.037101" quat="-5.76828e-05 0.739862 -4.13547e-05 0.672759" mass="1.253" diaginertia="0.00549574 0.00520479 0.000871351"/>
                  <joint name="left_ankle_roll_joint" pos="0 0 0" axis="1 0 0" limited="true" range="-0.436 0.436"/>
                  <geom type="mesh" class="visual" rgba="1 1 1 1" mesh="left_ankle_roll_link"/>
                  <geom name="left_foot"  pos="0.018 0 -0.0535" size="0.13 0.047 0.01" type="box" rgba="0 0.4 0 0.1" />

                  <body name="contact_left_heel" pos="-0.106 0 -0.0625">
                    <inertial pos="0.0 0.0 0.0" quat="1 0 0 0" mass="0.00001" diaginertia="0.00000000001 0.00000000001 0.00000000001"/>
                    <geom name="contact_left_heel" class="visual" size="0.003" type="sphere" rgba="1 0 0 1"/>
                  </body>
                  <body name="contact_left_center" pos="0.0 0 -0.0625">
                    <inertial pos="0.0 0.0 0.0" quat="1 0 0 0" mass="0.00001" diaginertia="0.00000000001 0.00000000001 0.00000000001"/>
                    <geom name="contact_left_center" class="visual" size="0.003" type="sphere" rgba="1 0 0 1"/>
                  </body>
                  <body name="contact_left_tip" pos="0.154 0 -0.0625">
                    <inertial pos="0.0 0.0 0.0" quat="1 0 0 0" mass="0.00001" diaginertia="0.00000000001 0.00000000001 0.00000000001"/>
                    <geom name="contact_left_tip" class="visual" size="0.003" type="sphere" rgba="1 0 0 1"/>
                  </body>

                </body>
              </body>
              <body name="left_A_achilles_link" pos="-0.0238 0.0013982 -0.115">
                <inertial pos="0.0017382 0.010471 0.0014412" quat="0.653355 0.749368 0.070713 0.0810802" mass="0.128" diaginertia="5.57384e-05 4.50869e-05 1.70947e-05"/>
                <joint name="left_A_achilles_joint" pos="0 0 0" axis="1 0 0" limited="true" range="-1.184 0.91" armature="0.094889232"/>
                <geom type="mesh" class="visual" rgba="1 1 1 1" mesh="left_A_achilles_link"/>
                <body name="left_A_achilles_rod_link" pos="-0.0112 0.032692 0.0044998">
                  <inertial pos="0 0.00015416 -0.13504" quat="0.707107 0.000403891 -0.000403891 0.707107" mass="0.109" diaginertia="0.000860371 0.00086012 2.50888e-06"/>
                  <joint name="left_A_achilles_rod_joint" type="ball" limited="false"/>
                  <geom type="mesh" class="visual" rgba="1 1 1 1" mesh="left_A_achilles_rod_link"/>
                </body>
              </body>
              <body name="left_B_achilles_link" pos="-0.0238 0.0013982 -0.205">
                <inertial pos="0.0022759 -0.0094672 0.0013031" quat="0.749368 0.653355 -0.0810802 -0.070713" mass="0.128" diaginertia="5.57384e-05 4.50869e-05 1.70947e-05"/>
                <joint name="left_B_achilles_joint" pos="0 0 0" axis="1 0 0" limited="true" range="-0.91 1.184" armature="0.094889232"/>
                <geom type="mesh" class="visual" rgba="1 1 1 1" mesh="left_B_achilles_link"/>
                <body name="left_B_achilles_rod_link" pos="-0.0112 -0.032692 0.0044997">
                  <inertial pos="0 -0.00015416 -0.090027" quat="0.707107 -0.000605418 0.000605418 0.707107" mass="0.077" diaginertia="0.000294031 0.00029387 2.03914e-06"/>
                  <joint name="left_B_achilles_rod_joint" type="ball" limited="false"/>
                  <geom type="mesh" class="visual" rgba="1 1 1 1" mesh="left_B_achilles_rod_link"/>
                </body>
              </body>
            </body>
          </body>
        </body>
      </body>

      <!-- right leg -->
      <body name="right_hip_pitch_link" pos="0.01 -0.12109 0.0069226">
        <inertial pos="-0.00064502 -0.0086743 -0.088248" quat="0.681136 0.0177742 0.0114077 0.731852" mass="2.187" diaginertia="0.0039162 0.00365577 0.00290083"/>
        <joint name="right_hip_pitch_joint" pos="0 0 0" axis="0 0.906308 0.422619" limited="true" range="-3.1415 3.1415" armature="0.15257125"/>
        <geom type="mesh" class="visual" rgba="1 1 1 1" mesh="right_hip_pitch_link"/>
        <geom type="cylinder" pos="-0.0107 -0.0089 -0.0954" size="0.05 0.06" euler="0 1.57 0" />
        <body name="right_hip_roll_link" pos="-0.01 -0.0089101 -0.095423">
          <inertial pos="0.002905 0.00013123 -0.0338674" quat="0.512047 0.487457 0.48466 0.515071" mass="0.5" diaginertia="0.00189968 0.001593 0.000969846"/>
          <joint name="right_hip_roll_joint" pos="0 0 0" axis="1 0 0" limited="true" range="-2.094 0.524" armature="0.15257125"/>
          <geom type="mesh" class="visual" rgba="1 1 1 1" mesh="right_hip_roll_link"/>
          <body name="right_hip_yaw_link" pos="0 0 -0.0705">
            <inertial pos="0.00457981 -0.00320377 -0.171853" quat="0.699686 -0.0086636 0.00637627 0.714369" mass="4.43" diaginertia="0.0726021 0.0717473 0.00671738"/>
            <joint name="right_hip_yaw_joint" pos="0 0 0" axis="0 0 1" limited="true" range="-2.705 2.705" armature="0.15257125"/>
            <geom type="mesh" class="visual" rgba="1 1 1 1" mesh="right_hip_yaw_link"/>
            <geom type="capsule" pos="0.015 -0.0 -0.14" size="0.05 0.1" euler="0 -0.1 0" />
            <body name="right_knee_link" pos="0 0 -0.3045">
              <inertial pos="0.0095547 -0.0079958 -0.13546" quat="0.995831 0.0467361 -0.00493262 -0.0781833" mass="2.845" diaginertia="0.0275931 0.0271804 0.00319144"/>
              <joint name="right_knee_joint" pos="0 0 0" axis="0 1 0" limited="true" range="-0.087 2.583" armature="0.15257125"/>
              <geom type="mesh" class="visual" rgba="1 1 1 1" mesh="right_knee_link"/>
              <geom type="capsule" pos="0.015 0.0 -0.2" size="0.035 0.14" euler="0 0.1 0" />
              <body name="right_ankle_pitch_link" pos="0 -0.0013982 -0.3855">
                <inertial pos="0.00014602 -0.00019049 0.00096596" quat="0.5 0.5 -0.5 0.5" mass="0.099" diaginertia="2.26e-05 1.98e-05 6.94e-06"/>
                <joint name="right_ankle_pitch_joint" pos="0 0 0" axis="0 1 0" limited="true" range="-0.95 0.611"/>
                <geom type="mesh" class="visual" rgba="1 1 1 1" mesh="right_ankle_pitch_link"/>
                <body name="right_ankle_roll_link" pos="0 0 0">
                  <inertial pos="0.0132965 0 -0.037101" quat="-5.76828e-05 0.739862 -4.13547e-05 0.672759" mass="1.253" diaginertia="0.00549574 0.00520479 0.000871351"/>
                  <joint name="right_ankle_roll_joint" pos="0 0 0" axis="1 0 0" limited="true" range="-0.436 0.436"/>
                  <geom type="mesh" class="visual" rgba="1 1 1 1" mesh="right_ankle_roll_link"/>
                  <geom name="right_foot"  pos="0.018 0 -0.0535" size="0.13 0.047 0.01" type="box" rgba="0 0.4 0 0.1" />

                  <body name="contact_right_heel" pos="-0.106 0 -0.0625">
                    <inertial pos="0.0 0.0 0.0" quat="1 0 0 0" mass="0.00001" diaginertia="0.00000000001 0.00000000001 0.00000000001"/>
                    <geom name="contact_right_heel" class="visual" size="0.003" type="sphere" rgba="1 0 0 1"/>
                  </body>
                  <body name="contact_right_center" pos="0.0 0 -0.0625">
                    <inertial pos="0.0 0.0 0.0" quat="1 0 0 0" mass="0.00001" diaginertia="0.00000000001 0.00000000001 0.00000000001"/>
                    <geom name="contact_right_center" class="visual" size="0.003" type="sphere" rgba="1 0 0 1"/>
                  </body>
                  <body name="contact_right_tip" pos="0.154 0 -0.0625">
                    <inertial pos="0.0 0.0 0.0" quat="1 0 0 0" mass="0.00001" diaginertia="0.00000000001 0.00000000001 0.00000000001"/>
                    <geom name="contact_right_tip" class="visual" size="0.003" type="sphere" rgba="1 0 0 1"/>
                  </body>

                </body>
              </body>
              <body name="right_A_achilles_link" pos="-0.0238 -0.0013982 -0.115">
                <inertial pos="0.0022761 -0.0094672 0.0013031" quat="0.749368 0.653355 -0.0810802 -0.070713" mass="0.128" diaginertia="5.57384e-05 4.50869e-05 1.70947e-05"/>
                <joint name="right_A_achilles_joint" pos="0 0 0" axis="1 0 0" limited="true" range="-0.91 1.184" armature="0.094889232"/>
                <geom type="mesh" class="visual" rgba="1 1 1 1" mesh="right_A_achilles_link"/>
                <body name="right_A_achilles_rod_link" pos="-0.0112 -0.032692 0.0044998">
                  <inertial pos="0 -0.00015407 -0.13496" quat="1 -0.000571361 0 0" mass="0.109" diaginertia="0.00086037 0.000860111 2.50888e-06"/>
                  <joint name="right_A_achilles_rod_joint" type="ball" limited="false"/>
                  <geom type="mesh" class="visual" rgba="1 1 1 1" mesh="right_A_achilles_rod_link"/>
                </body>
              </body>
              <body name="right_B_achilles_link" pos="-0.0238 -0.0013982 -0.205">
                <inertial pos="0.0022759 0.0094672 0.0013031" quat="0.653355 0.749368 0.070713 0.0810802" mass="0.128" diaginertia="5.57384e-05 4.50869e-05 1.70947e-05"/>
                <joint name="right_B_achilles_joint" pos="0 0 0" axis="1 0 0" limited="true" range="-1.184 0.91" armature="0.094889232"/>
                <geom type="mesh" class="visual" rgba="1 1 1 1" mesh="right_B_achilles_link"/>
                <body name="right_B_achilles_rod_link" pos="-0.0112 0.032692 0.0044997">
                  <inertial pos="0 0.00015416 -0.0900266" quat="0.707107 0.000605418 -0.000605418 0.707107" mass="0.077" diaginertia="0.000294031 0.00029387 2.03914e-06"/>
                  <joint name="right_B_achilles_rod_joint" type="ball" limited="false"/>
                  <geom type="mesh" class="visual" rgba="1 1 1 1" mesh="right_B_achilles_rod_link"/>
                </body>
              </body>
            </body>
          </body>
        </body>
      </body>
      
      <!-- waist -->
      <body name="waist_yaw_link" pos="0 0 0.0925">
        <inertial pos="0.019524 -0.0001341 0.023212" quat="0.00429054 0.595481 -0.00290759 0.803353" mass="0.778" diaginertia="0.0015465 0.00135185 0.000841697"/>
        <joint name="waist_yaw_joint" pos="0 0 0" axis="0 0 1" limited="true" range="-2.618 2.618" armature="0.094889232"/>
        <geom type="mesh" class="visual" rgba="1 1 1 1" mesh="waist_yaw_link"/>
        <body name="waist_roll_link" pos="0 0 0.062">
          <inertial pos="-0.00014211 8.87e-05 -0.00011009" quat="0.5 0.5 -0.5 0.5" mass="0.392" diaginertia="0.00021059 0.00016746 8.157e-05"/>
          <joint name="waist_roll_joint" pos="0 0 0" axis="1 0 0" limited="true" range="-0.524 0.524"/>
          <geom type="mesh" class="visual" rgba="1 1 1 1" mesh="waist_roll_link"/>
          
          <!-- upper body -->
          <body name="waist_pitch_link" pos="0 0 0">
            <inertial pos="-0.0119405 -0.00204706 0.217301" quat="0.998919 0.00439441 -0.0462429 -0.0015887" mass="11.989" diaginertia="0.203074 0.170481 0.113818"/>
            <joint name="waist_pitch_joint" pos="0 0 0" axis="0 1 0" limited="true" range="-0.524 0.524"/>
            <geom type="mesh" class="visual" rgba="1 1 1 1" mesh="waist_pitch_link"/>
            <geom type="capsule" pos="-0.006 0 0.25681" size="0.11 0.055" euler="1.57 0 0" />
            <geom type="capsule" pos="-0.03 0 0.07" size="0.06 0.06" euler="1.57 0 0" />
            <geom type="capsule" pos="0.065 0 0.1" size="0.03 0.05" euler="1.57 0 0" />
            <body name="waist_A_link" pos="0 0.0925 0.064">
              <inertial pos="0.0259002 -0.011341 -0.0094285" quat="0.481765 0.629747 0.517566 0.321629" mass="0.177" diaginertia="0.000169576 0.000161205 2.46888e-05"/>
              <joint name="waist_A_joint" pos="0 0 0" axis="0 1 0" limited="true" range="-0.785 0.524" armature="0.094889232"/>
              <geom type="mesh" class="visual" rgba="1 1 1 1" mesh="waist_A_link"/>
              <body name="waist_A_rod_link" pos="0.063899 -0.0325 -0.023257">
                <inertial pos="0 0 -0.032" quat="0.707107 0 0 0.707107" mass="0.064" diaginertia="4.921e-05 4.644e-05 3.28e-06"/>
                <joint name="waist_A_rod_joint" type="ball" limited="false"/>
                <geom type="mesh" class="visual" rgba="1 1 1 1" mesh="waist_A_rod_link"/>
              </body>
            </body>
            <body name="waist_B_link" pos="0 -0.0925 0.064">
              <inertial pos="0.0259012 0.011341 -0.00942567" quat="0.321714 0.517437 0.62989 0.481661" mass="0.177" diaginertia="0.000169576 0.000161204 2.46899e-05"/>
              <joint name="waist_B_joint" pos="0 0 0" axis="0 1 0" limited="true" range="-0.785 0.524" armature="0.094889232"/>
              <geom type="mesh" class="visual" rgba="1 1 1 1" mesh="waist_B_link"/>
              <body name="waist_B_rod_link" pos="0.063899 0.0325 -0.023257">
                <inertial pos="0 0 -0.032" quat="0.707107 0 0 0.707107" mass="0.064" diaginertia="4.921e-05 4.644e-05 3.28e-06"/>
                <joint name="waist_B_rod_joint" type="ball" limited="false"/>
                <geom type="mesh" class="visual" rgba="1 1 1 1" mesh="waist_B_rod_link"/>
              </body>
            </body>
            
            <!-- head -->
            <body name="head_yaw_link" pos="-0.013 0 0.3837">
              <inertial pos="1.263e-05 0.00749931 0.0395799" quat="0.996093 0.0422873 -0.0237008 0.0738173" mass="0.314" diaginertia="0.000152448 0.000145555 0.000137808"/>
              <joint name="head_yaw_joint" pos="0 0 0" axis="0 0 1" limited="true" range="-0.785 0.785" armature="0.010625"/>
              <geom type="mesh" class="visual" rgba="1 1 1 1" mesh="head_yaw_link"/>
              <body name="head_pitch_link" pos="0 0 0.0415">
                <inertial pos="0.00894282 -0.00017284 0.069511" quat="0.543859 0.556672 -0.440435 0.447604" mass="0.969" diaginertia="0.00353609 0.00247072 0.0024232"/>
                <joint name="head_pitch_joint" pos="0 0 0" axis="0 1 0" limited="true" range="-0.524 0.96" armature="0.010625"/>
                <geom type="mesh" class="visual" rgba="1 1 1 1" mesh="head_pitch_link"/>
                <geom type="box" pos="0.0077 0 0.072" size="0.05 0.075 0.04" euler="0 0.17 0" />
              </body>
            </body>

            <!-- left arm -->
            <body name="left_shoulder_pitch_link" pos="0 0.1575 0.2822">
              <inertial pos="0.0060726 0.0289775 0" quat="-0.154794 0.689956 0.154794 0.689956" mass="0.158" diaginertia="0.00025338 0.000224884 0.000156096"/>
              <joint name="left_shoulder_pitch_joint" pos="0 0 0" axis="0 1 0" limited="true" range="-2.793 2.793" armature="0.045760625"/>
              <geom type="mesh" class="visual" rgba="1 1 1 1" mesh="left_shoulder_pitch_link"/>
              <body name="left_shoulder_roll_link" pos="0 0.055 0">
                <inertial pos="0.00335434 4.779e-05 -0.0464369" quat="0.99923 0.000359422 0.0353633 0.0170014" mass="1.746" diaginertia="0.00493275 0.00488552 0.00135194"/>
                <joint name="left_shoulder_roll_joint" pos="0 0 0" axis="1 0 0" limited="true" range="-0.087 3.229" armature="0.045760625"/>
                <geom type="mesh" class="visual" rgba="1 1 1 1" mesh="left_shoulder_roll_link"/>
                <geom type="cylinder" pos="0 0 0" size="0.04 0.038" euler="0 1.57 0" />
                <geom type="cylinder" pos="0 0 -0.082" size="0.04 0.035" euler="0 0 0" />
                <body name="left_shoulder_yaw_link" pos="0 0 -0.1306">
                  <inertial pos="-0.00949724 0.00403644 -0.060625" quat="0.994786 0.0766668 0.0244394 -0.0626625" mass="0.265" diaginertia="0.000739031 0.000654669 0.00032536"/>
                  <joint name="left_shoulder_yaw_joint" pos="0 0 0" axis="0 0 1" limited="true" range="-1.571 1.571" armature="0.045760625"/>
                  <geom type="mesh" class="visual" rgba="1 1 1 1" mesh="left_shoulder_yaw_link"/>
                  <body name="left_elbow_link" pos="0 0 -0.1157">
                    <inertial pos="-5.874e-05 0.00486789 -0.0240026" quat="0.693551 -0.0250113 0.0255123 0.719522" mass="1.216" diaginertia="0.00246331 0.0024161 0.000829409"/>
                    <joint name="left_elbow_joint" pos="0 0 0" axis="0 1 0" limited="true" range="-2.5307 1.2915" armature="0.045760625"/>
                    <geom type="mesh" class="visual" rgba="1 1 1 1" mesh="left_elbow_link"/>
                    <geom type="cylinder" pos="0 0 0" size="0.0425 0.04" euler="1.57 0  0" />
                    <geom type="cylinder" pos="0 0 -0.072" size="0.0375 0.025" euler="0 0 0" />
                    <body name="left_wrist_yaw_link" pos="0 0 -0.1048">
                      <inertial pos="0 0.00240189 -0.0176639" quat="0.736317 0.676629 0.00218251 -0.00226384" mass="0.116" diaginertia="0.000131201 0.000116937 8.07627e-05"/>
                      <joint name="left_wrist_yaw_joint" pos="0 0 0" axis="0 0 1" limited="true" range="-1.571 1.571" armature="0.010625"/>
                      <geom type="mesh" class="visual" rgba="1 1 1 1" mesh="left_wrist_yaw_link"/>
                      <!-- <geom type="capsule" pos="0 0 0" size="0.04 0.03" euler="0 1.57 0" /> -->
                      <body name="left_wrist_pitch_link" pos="0 0 -0.0345">
                        <inertial pos="-3.73e-06 0.00334909 -0.0313572" quat="0.751924 -0.0368095 0.0331339 0.657387" mass="0.651" diaginertia="0.000930971 0.000928884 0.000330635"/>
                        <joint name="left_wrist_pitch_joint" pos="0 0 0" axis="0 1 0" limited="true" range="-1.571 1.571" armature="0.010625"/>
                        <geom type="mesh" class="visual" rgba="1 1 1 1" mesh="left_wrist_pitch_link"/>
                        <geom type="cylinder" pos="0 0 0" size="0.0275 0.035" euler="1.57 0  0" />
                        <geom type="cylinder" pos="0 0 -0.0617" size="0.0315 0.03" euler="0 0 0" />
                        <body name="left_hand_yaw_link" pos="0 0 -0.0815">
                          <inertial pos="2.8e-06 -4.277e-05 -0.0588716" quat="1 0.000769182 2.28644e-05 1.75869e-08" mass="0.261" diaginertia="0.00057637 0.000470531 0.000139009"/>
                          <joint name="left_hand_yaw_joint" pos="0 0 0" axis="0 0 1" limited="true" range="-2.356 2.356" armature="0.010625"/>
                          <geom type="mesh" class="visual" rgba="1 1 1 1" mesh="left_hand_yaw_link"/>
                          <geom type="box" pos="0 0 -0.04226" size="0.01 0.02 0.0275" euler="0 0 0" />
                          <geom type="box" pos="0 0 -0.116" size="0.01 0.05 0.03" euler="0 0 0" />
                          <body name="contact_left_hand" pos="0.0 0 0.0">
                            <inertial pos="0.0 0.0 0.0" quat="1 0 0 0" mass="0.00001" diaginertia="0.00000000001 0.00000000001 0.00000000001"/>
                            <geom name="contact_left_hand" class="visual" size="0.003" type="sphere" rgba="1 0 0 1"/>
                          </body>
                        </body>
                      </body>
                    </body>
                  </body>
                </body>
              </body>
            </body>
            
            <!-- right arm -->
            <body name="right_shoulder_pitch_link" pos="0 -0.1575 0.2822">
              <inertial pos="0.00608318 -0.0288955 -7.462e-05" quat="0.158288 0.690227 -0.15216 0.689477" mass="0.159" diaginertia="0.000253682 0.000225158 0.00015659"/>
              <joint name="right_shoulder_pitch_joint" pos="0 0 0" axis="0 1 0" limited="true" range="-2.793 2.793" armature="0.045760625"/>
              <geom type="mesh" class="visual" rgba="1 1 1 1" mesh="right_shoulder_pitch_link"/>
              <body name="right_shoulder_roll_link" pos="0 -0.055 0">
                <inertial pos="0.00333695 4.67e-05 -0.0464166" quat="0.999226 0.000395704 0.0352409 0.0174939" mass="1.744" diaginertia="0.0049209 0.00487389 0.00135057"/>
                <joint name="right_shoulder_roll_joint" pos="0 0 0" axis="1 0 0" limited="true" range="-3.229 0.087" armature="0.045760625"/>
                <geom type="mesh" class="visual" rgba="1 1 1 1" mesh="right_shoulder_roll_link"/>
                <geom type="cylinder" pos="0 0 0" size="0.04 0.038" euler="0 1.57 0" />
                <geom type="cylinder" pos="0 0 -0.082" size="0.04 0.035" euler="0 0 0" />
                <body name="right_shoulder_yaw_link" pos="0 0 -0.1306">
                  <inertial pos="-0.00951399 -0.00405211 -0.0605306" quat="0.994779 -0.0764191 0.0244622 0.0630583" mass="0.265" diaginertia="0.000739118 0.000654764 0.000325488"/>
                  <joint name="right_shoulder_yaw_joint" pos="0 0 0" axis="0 0 1" limited="true" range="-1.571 1.571" armature="0.045760625"/>
                  <geom type="mesh" class="visual" rgba="1 1 1 1" mesh="right_shoulder_yaw_link"/>
                  <body name="right_elbow_link" pos="0 0 -0.1157">
                    <inertial pos="5.719e-05 -0.00484446 -0.0239242" quat="0.69325 0.0248562 -0.0254238 0.719819" mass="1.214" diaginertia="0.00246117 0.00241417 0.000828042"/>
                    <joint name="right_elbow_joint" pos="0 0 0" axis="0 1 0" limited="true" range="-2.5307 1.2915" armature="0.045760625"/>
                    <geom type="mesh" class="visual" rgba="1 1 1 1" mesh="right_elbow_link"/>
                    <geom type="cylinder" pos="0 0 0" size="0.0425 0.04" euler="1.57 0  0" />
                    <geom type="cylinder" pos="0 0 -0.072" size="0.0375 0.025" euler="0 0 0" />
                    <body name="right_wrist_yaw_link" pos="0 0 -0.1048">
                      <inertial pos="0 -0.00240189 -0.0175639" quat="0.676629 0.736317 -0.00226384 0.00218251" mass="0.116" diaginertia="0.000131201 0.000116937 8.07627e-05"/>
                      <joint name="right_wrist_yaw_joint" pos="0 0 0" axis="0 0 1" limited="true" range="-1.571 1.571" armature="0.010625"/>
                      <geom type="mesh" class="visual" rgba="1 1 1 1" mesh="right_wrist_yaw_link"/>
                      <!-- <geom type="capsule" pos="0 0 0" size="0.04 0.03" euler="0 1.57 0" /> -->
                      <body name="right_wrist_pitch_link" pos="0 0 -0.0345">
                        <inertial pos="3.73e-06 -0.00334909 -0.0313572" quat="0.751924 0.0368095 -0.0331339 0.657387" mass="0.651" diaginertia="0.000930971 0.000928884 0.000330635"/>
                        <joint name="right_wrist_pitch_joint" pos="0 0 0" axis="0 1 0" limited="true" range="-1.571 1.571" armature="0.010625"/>
                        <geom type="mesh" class="visual" rgba="1 1 1 1" mesh="right_wrist_pitch_link"/>
                        <geom type="cylinder" pos="0 0 0" size="0.0275 0.035" euler="1.57 0  0" />
                        <geom type="cylinder" pos="0 0 -0.0617" size="0.0315 0.03" euler="0 0 0" />
                        <body name="right_hand_yaw_link" pos="0 0 -0.0815">
                          <inertial pos="-2.8e-06 4.277e-05 -0.0587716" quat="1 -0.000769182 -2.28644e-05 1.75869e-08" mass="0.261" diaginertia="0.00057637 0.000470531 0.000139009"/>
                          <joint name="right_hand_yaw_joint" pos="0 0 0" axis="0 0 1" limited="true" range="-2.356 2.356" armature="0.010625"/>
                          <geom type="mesh" class="visual" rgba="1 1 1 1" mesh="right_hand_yaw_link"/>
                          <geom type="box" pos="0 0 -0.04226" size="0.01 0.02 0.0275" euler="0 0 0" />
                          <geom type="box" pos="0 0 -0.116" size="0.01 0.05 0.03" euler="0 0 0" />
                          <body name="contact_right_hand" pos="0.0 0 0.0">
                            <inertial pos="0.0 0.0 0.0" quat="1 0 0 0" mass="0.00001" diaginertia="0.00000000001 0.00000000001 0.00000000001"/>
                            <geom name="contact_right_hand" class="visual" size="0.003" type="sphere" rgba="1 0 0 1"/>
                          </body>
                        </body>
                      </body>
                    </body>
                  </body>
                </body>
              </body>
            </body>
          </body>
        </body>
      </body>
    </body>
  </worldbody>
  <equality>
    <connect name='A_achilles_connect_L' body1='left_ankle_roll_link' body2='left_A_achilles_rod_link' anchor='-0.035 0.033 0.0045'/>
    <connect name='B_achilles_connect_L' body1='left_ankle_roll_link' body2='left_B_achilles_rod_link' anchor='-0.035 -0.033 0.0045'/>

    <connect name='A_achilles_connect_R' body1='right_ankle_roll_link' body2='right_A_achilles_rod_link' anchor='-0.035 -0.033 0.0045'/>
    <connect name='B_achilles_connect_R' body1='right_ankle_roll_link' body2='right_B_achilles_rod_link' anchor='-0.035 0.033 0.0045'/>

    <connect name='waist_connect_A' body1='waist_yaw_link' body2='waist_A_rod_link' anchor='0.0639 0.06 0.0387'/>
    <connect name='waist_connect_B' body1='waist_yaw_link' body2='waist_B_rod_link' anchor='0.0639 -0.06 0.0387'/>
  </equality>

  <actuator>
    <motor name="hip_pitch_left" gear="1" joint="left_hip_pitch_joint" ctrllimited="true" ctrlrange="-120 120" />
    <motor name="hip_roll_left" gear="1" joint="left_hip_roll_joint" ctrllimited="true" ctrlrange="-120 120" />
    <motor name="hip_yaw_left" gear="1" joint="left_hip_yaw_joint" ctrllimited="true" ctrlrange="-120 120" />
    <motor name="knee_left" gear="1" joint="left_knee_joint" ctrllimited="true" ctrlrange="-120 120" />
    <motor name="ankle_A_left" gear="1" joint="left_A_achilles_joint" ctrllimited="true" ctrlrange="-45 45" />
    <motor name="ankle_B_left" gear="1" joint="left_B_achilles_joint" ctrllimited="true" ctrlrange="-45 45" />

    <motor name="hip_pitch_right" gear="1" joint="right_hip_pitch_joint" ctrllimited="true" ctrlrange="-120 120" />
    <motor name="hip_roll_right" gear="1" joint="right_hip_roll_joint" ctrllimited="true" ctrlrange="-120 120" />
    <motor name="hip_yaw_right" gear="1" joint="right_hip_yaw_joint" ctrllimited="true" ctrlrange="-120 120" />
    <motor name="knee_right" gear="1" joint="right_knee_joint" ctrllimited="true" ctrlrange="-120 120" />
    <motor name="ankle_A_right" gear="1" joint="right_A_achilles_joint" ctrllimited="true" ctrlrange="-45 45" />
    <motor name="ankle_B_right" gear="1" joint="right_B_achilles_joint" ctrllimited="true" ctrlrange="-45 45" />

    <motor name="body_waist_yaw" gear="1" joint="waist_yaw_joint" ctrllimited="true" ctrlrange="-45 45" />
    <motor name="body_waist_B" gear="1" joint="waist_B_joint" ctrllimited="true" ctrlrange="-45 45" />
    <motor name="body_waist_A" gear="1" joint="waist_A_joint" ctrllimited="true" ctrlrange="-45 45" />

    <motor name="head_yaw" gear="1" joint="head_yaw_joint" ctrllimited="true" ctrlrange="-18 18" />
    <motor name="head_pitch" gear="1" joint="head_pitch_joint" ctrllimited="true" ctrlrange="-18 18" />

    <motor name="shoulder_pitch_left" gear="1" joint="left_shoulder_pitch_joint" ctrllimited="true" ctrlrange="-30 30" />
    <motor name="shoulder_roll_left" gear="1" joint="left_shoulder_roll_joint" ctrllimited="true" ctrlrange="-30 30" />
    <motor name="shoulder_yaw_left" gear="1" joint="left_shoulder_yaw_joint" ctrllimited="true" ctrlrange="-30 30" />
    <motor name="elbow_left" gear="1" joint="left_elbow_joint" ctrllimited="true" ctrlrange="-30 30" />
    <motor name="wrist_yaw_left" gear="1" joint="left_wrist_yaw_joint" ctrllimited="true" ctrlrange="-18 18" />
    <motor name="wrist_pitch_left" gear="1" joint="left_wrist_pitch_joint" ctrllimited="true" ctrlrange="-18 18" />
    <motor name="hand_yaw_left" gear="1" joint="left_hand_yaw_joint" ctrllimited="true" ctrlrange="-18 18" />

    <motor name="shoulder_pitch_right" gear="1" joint="right_shoulder_pitch_joint" ctrllimited="true" ctrlrange="-30 30" />
    <motor name="shoulder_roll_right" gear="1" joint="right_shoulder_roll_joint" ctrllimited="true" ctrlrange="-30 30" />
    <motor name="shoulder_yaw_right" gear="1" joint="right_shoulder_yaw_joint" ctrllimited="true" ctrlrange="-30 30" />
    <motor name="elbow_right" gear="1" joint="right_elbow_joint" ctrllimited="true" ctrlrange="-30 30" />
    <motor name="wrist_yaw_right" gear="1" joint="right_wrist_yaw_joint" ctrllimited="true" ctrlrange="-18 18" />
    <motor name="wrist_pitch_right" gear="1" joint="right_wrist_pitch_joint" ctrllimited="true" ctrlrange="-18 18" />
    <motor name="hand_yaw_right" gear="1" joint="right_hand_yaw_joint" ctrllimited="true" ctrlrange="-18 18" />
  </actuator>

  <sensor>
    <framequat name="Body_Quat" objtype="site" objname="imu" noise="0.0" />
    <gyro name="Body_Gyro" site="imu" noise="0.0" />
    <accelerometer name="Body_Acc" site="imu" noise="0.0" />

    <!-- Left leg sensors -->
    <jointpos name="left_hip_pitch_pos" joint="left_hip_pitch_joint" noise="0.0"/>
    <jointpos name="left_hip_roll_pos" joint="left_hip_roll_joint" noise="0.0"/>
    <jointpos name="left_hip_yaw_pos" joint="left_hip_yaw_joint" noise="0.0"/>
    <jointpos name="left_knee_pos" joint="left_knee_joint" noise="0.0"/>
    <jointpos name="left_A_achilles_pos" joint="left_A_achilles_joint" noise="0.0"/>
    <jointpos name="left_B_achilles_pos" joint="left_B_achilles_joint" noise="0.0"/>
    <!-- Right leg sensors -->
    <jointpos name="right_hip_pitch_pos" joint="right_hip_pitch_joint" noise="0.0"/>
    <jointpos name="right_hip_roll_pos" joint="right_hip_roll_joint" noise="0.0"/>
    <jointpos name="right_hip_yaw_pos" joint="right_hip_yaw_joint" noise="0.0"/>
    <jointpos name="right_knee_pos" joint="right_knee_joint" noise="0.0"/>
    <jointpos name="right_A_achilles_pos" joint="right_A_achilles_joint" noise="0.0"/>
    <jointpos name="right_B_achilles_pos" joint="right_B_achilles_joint" noise="0.0"/>
    <!-- Waist sensors -->
    <jointpos name="waist_yaw_pos" joint="waist_yaw_joint" noise="0.0"/>
    <jointpos name="waist_B_pos" joint="waist_B_joint" noise="0.0"/>
    <jointpos name="waist_A_pos" joint="waist_A_joint" noise="0.0"/>
    <!-- Neck sensors -->
    <jointpos name="head_yaw_pos" joint="head_yaw_joint" noise="0.0"/>
    <jointpos name="head_pitch_pos" joint="head_pitch_joint" noise="0.0"/>
    <!-- Left arm sensors -->
    <jointpos name="left_shoulder_pitch_pos" joint="left_shoulder_pitch_joint" noise="0.0"/>
    <jointpos name="left_shoulder_roll_pos" joint="left_shoulder_roll_joint" noise="0.0"/>
    <jointpos name="left_shoulder_yaw_pos" joint="left_shoulder_yaw_joint" noise="0.0"/>
    <jointpos name="left_elbow_pos" joint="left_elbow_joint" noise="0.0"/>
    <jointpos name="left_wrist_yaw_pos" joint="left_wrist_yaw_joint" noise="0.0"/>
    <jointpos name="left_wrist_pitch_pos" joint="left_wrist_pitch_joint" noise="0.0"/>
    <jointpos name="left_hand_yaw_pos" joint="left_hand_yaw_joint" noise="0.0"/>
    <!-- Right arm sensors -->
    <jointpos name="right_shoulder_pitch_pos" joint="right_shoulder_pitch_joint" noise="0.0"/>
    <jointpos name="right_shoulder_roll_pos" joint="right_shoulder_roll_joint" noise="0.0"/>
    <jointpos name="right_shoulder_yaw_pos" joint="right_shoulder_yaw_joint" noise="0.0"/>
    <jointpos name="right_elbow_pos" joint="right_elbow_joint" noise="0.0"/>
    <jointpos name="right_wrist_yaw_pos" joint="right_wrist_yaw_joint" noise="0.0"/>
    <jointpos name="right_wrist_pitch_pos" joint="right_wrist_pitch_joint" noise="0.0"/>
    <jointpos name="right_hand_yaw_pos" joint="right_hand_yaw_joint" noise="0.0"/>

    <!-- Left leg sensors -->
    <jointvel name="left_hip_pitch_vel" joint="left_hip_pitch_joint" noise="0.0"/>
    <jointvel name="left_hip_roll_vel" joint="left_hip_roll_joint" noise="0.0"/>
    <jointvel name="left_hip_yaw_vel" joint="left_hip_yaw_joint" noise="0.0"/>
    <jointvel name="left_knee_vel" joint="left_knee_joint" noise="0.0"/>
    <jointvel name="left_A_achilles_vel" joint="left_A_achilles_joint" noise="0.0"/>
    <jointvel name="left_B_achilles_vel" joint="left_B_achilles_joint" noise="0.0"/>
    <!-- Right leg sensors -->
    <jointvel name="right_hip_pitch_vel" joint="right_hip_pitch_joint" noise="0.0"/>
    <jointvel name="right_hip_roll_vel" joint="right_hip_roll_joint" noise="0.0"/>
    <jointvel name="right_hip_yaw_vel" joint="right_hip_yaw_joint" noise="0.0"/>
    <jointvel name="right_knee_vel" joint="right_knee_joint" noise="0.0"/>
    <jointvel name="right_A_achilles_vel" joint="right_A_achilles_joint" noise="0.0"/>
    <jointvel name="right_B_achilles_vel" joint="right_B_achilles_joint" noise="0.0"/>
    <!-- Waist sensors -->
    <jointvel name="waist_yaw_vel" joint="waist_yaw_joint" noise="0.0"/>
    <jointvel name="waist_B_vel" joint="waist_B_joint" noise="0.0"/>
    <jointvel name="waist_A_vel" joint="waist_A_joint" noise="0.0"/>
    <!-- Neck sensors -->
    <jointvel name="head_yaw_vel" joint="head_yaw_joint" noise="0.0"/>
    <jointvel name="head_pitch_vel" joint="head_pitch_joint" noise="0.0"/>
    <!-- Left arm sensors -->
    <jointvel name="left_shoulder_pitch_vel" joint="left_shoulder_pitch_joint" noise="0.0"/>
    <jointvel name="left_shoulder_roll_vel" joint="left_shoulder_roll_joint" noise="0.0"/>
    <jointvel name="left_shoulder_yaw_vel" joint="left_shoulder_yaw_joint" noise="0.0"/>
    <jointvel name="left_elbow_vel" joint="left_elbow_joint" noise="0.0"/>
    <jointvel name="left_wrist_yaw_vel" joint="left_wrist_yaw_joint" noise="0.0"/>
    <jointvel name="left_wrist_pitch_vel" joint="left_wrist_pitch_joint" noise="0.0"/>
    <jointvel name="left_hand_yaw_vel" joint="left_hand_yaw_joint" noise="0.0"/>
    <!-- Right arm sensors -->
    <jointvel name="right_shoulder_pitch_vel" joint="right_shoulder_pitch_joint" noise="0.0"/>
    <jointvel name="right_shoulder_roll_vel" joint="right_shoulder_roll_joint" noise="0.0"/>
    <jointvel name="right_shoulder_yaw_vel" joint="right_shoulder_yaw_joint" noise="0.0"/>
    <jointvel name="right_elbow_vel" joint="right_elbow_joint" noise="0.0"/>
    <jointvel name="right_wrist_yaw_vel" joint="right_wrist_yaw_joint" noise="0.0"/>
    <jointvel name="right_wrist_pitch_vel" joint="right_wrist_pitch_joint" noise="0.0"/>
    <jointvel name="right_hand_yaw_vel" joint="right_hand_yaw_joint" noise="0.0"/>
  </sensor>
</mujoco>
