<mujoco model="DA_D03_03">
  <compiler angle="radian" meshdir="../meshes/DA_D03_03/"/>
  <size njmax="5000" nconmax="1000"/>

  <default>
    <light castshadow="false" diffuse="1 1 1" />
    <camera fovy="60" />
    <default class="visual">
      <geom contype="0" conaffinity="0" group="1" type="mesh" rgba="0.8 0.8 0.8 1.0" />
    </default>
    <joint damping="0.01" margin="0.0001" />
    <geom contype="1" conaffinity="1" friction="1.0 0.3 0.3" rgba="0.5 0.6 0.7 0.5" margin="0.001" group="0" />
    <equality solref="0.001  1" />
  </default>

  <option timestep="0.001" />
  <!-- <option>
    <flag sensornoise="enable" />
  </option> -->

  <visual>
    <rgba com="0.502 1.0 0 1.0" contactpoint="0.5 0.1 0.8 0.4" contactforce="0.2 0.98 0.2 0.8" />
    <scale com="0.2" forcewidth="0.05" contactwidth="0.10" contactheight="0.04" />
  </visual>

  <asset>
    <mesh name="base_link" file="waist_pitch_link.STL"/>

    <mesh name="left_shoulder_pitch_link" file="left_shoulder_pitch_link.STL"/>
    <mesh name="left_shoulder_roll_link" file="left_shoulder_roll_link.STL"/>
    <mesh name="left_shoulder_yaw_link" file="left_shoulder_yaw_link.STL"/>
    <mesh name="left_elbow_link" file="left_elbow_link.STL"/>
    <mesh name="left_wrist_yaw_link" file="left_wrist_yaw_link.STL"/>
    <mesh name="left_wrist_pitch_link" file="left_wrist_pitch_link.STL"/>
    <mesh name="left_hand_yaw_link" file="left_hand_yaw_link.STL"/>

    <mesh name="right_shoulder_pitch_link" file="right_shoulder_pitch_link.STL"/>
    <mesh name="right_shoulder_roll_link" file="right_shoulder_roll_link.STL"/>
    <mesh name="right_shoulder_yaw_link" file="right_shoulder_yaw_link.STL"/>
    <mesh name="right_elbow_link" file="right_elbow_link.STL"/>
    <mesh name="right_wrist_yaw_link" file="right_wrist_yaw_link.STL"/>
    <mesh name="right_wrist_pitch_link" file="right_wrist_pitch_link.STL"/>
    <mesh name="right_hand_yaw_link" file="right_hand_yaw_link.STL"/>

    <mesh name="head_yaw_link" file="neck_yaw_link.STL"/>
    <mesh name="head_pitch_link" file="neck_pitch_link.STL"/>
  </asset>

  <asset>
    <texture type="skybox" builtin="gradient" width="512" height="512" rgb1="1.0 1.0 1.0" rgb2="1.0 1.0 1.0" />
    <texture name="plane" type="2d" builtin="flat" rgb1="1 1 1" rgb2="1 1 1" width="512" height="512" mark="cross" markrgb="0 0 0" />
    <material name="plane" reflectance="0.0" texture="plane" texrepeat="3 3" texuniform="true" />
  </asset>

  <worldbody>
    <geom name="floor" pos="0 0 0" euler="0 0 0" size="0 0 1" type="plane" material="plane" condim="3" conaffinity="1" contype="1" rgba="1 1 1 1" />
    <light directional="true" diffuse=".8 .8 .8" pos="0 0 10" dir="0 0 -10" />
    <camera name="track" mode="trackcom" pos="0 -2.3 1.6" xyaxes="1 0 0 0 0.707 0.707" />

    <body name="base_link" pos="0 0 1.0">
      <inertial pos="-0.0119405 -0.00204706 0.217301" quat="0.998919 0.00439441 -0.0462429 -0.0015887" mass="11.989" diaginertia="0.203074 0.170481 0.113818"/>
      <geom type="mesh" class="visual" rgba="1 1 1 1" mesh="base_link"/>
          
      <!-- head -->
      <body name="head_yaw_link" pos="-0.013 0 0.3837">
        <inertial pos="1.263e-05 0.00749931 0.0395799" quat="0.996093 0.0422873 -0.0237008 0.0738173" mass="0.314" diaginertia="0.000152448 0.000145555 0.000137808"/>
        <joint name="head_yaw_joint" pos="0 0 0" axis="0 0 1" limited="true" range="-0.785 0.785" armature="0.010625"/>
        <geom type="mesh" class="visual" rgba="1 1 1 1" mesh="head_yaw_link"/>
        <body name="head_pitch_link" pos="0 0 0.0415">
          <inertial pos="0.00894282 -0.00017284 0.069511" quat="0.543859 0.556672 -0.440435 0.447604" mass="0.969" diaginertia="0.00353609 0.00247072 0.0024232"/>
          <joint name="head_pitch_joint" pos="0 0 0" axis="0 1 0" limited="true" range="-0.524 0.96" armature="0.010625"/>
          <geom type="mesh" class="visual" rgba="1 1 1 1" mesh="head_pitch_link"/>
        </body>
      </body>

      <!-- left arm -->
      <body name="left_shoulder_pitch_link" pos="0 0.1575 0.2822">
        <inertial pos="0.0060726 0.0289775 0" quat="-0.154794 0.689956 0.154794 0.689956" mass="0.158" diaginertia="0.00025338 0.000224884 0.000156096"/>
        <joint name="left_shoulder_pitch_joint" pos="0 0 0" axis="0 1 0" limited="true" range="-2.793 2.793" armature="0.045760625"/>
        <geom type="mesh" class="visual" rgba="1 1 1 1" mesh="left_shoulder_pitch_link"/>
        <body name="left_shoulder_roll_link" pos="0 0.055 0">
          <inertial pos="0.00335434 4.779e-05 -0.0464369" quat="0.99923 0.000359422 0.0353633 0.0170014" mass="1.746" diaginertia="0.00493275 0.00488552 0.00135194"/>
          <joint name="left_shoulder_roll_joint" pos="0 0 0" axis="1 0 0" limited="true" range="-0.087 3.229" armature="0.045760625"/>
          <geom type="mesh" class="visual" rgba="1 1 1 1" mesh="left_shoulder_roll_link"/>
          <body name="left_shoulder_yaw_link" pos="0 0 -0.1306">
            <inertial pos="-0.00949724 0.00403644 -0.060625" quat="0.994786 0.0766668 0.0244394 -0.0626625" mass="0.265" diaginertia="0.000739031 0.000654669 0.00032536"/>
            <joint name="left_shoulder_yaw_joint" pos="0 0 0" axis="0 0 1" limited="true" range="-1.571 1.571" armature="0.045760625"/>
            <geom type="mesh" class="visual" rgba="1 1 1 1" mesh="left_shoulder_yaw_link"/>
            <body name="left_elbow_link" pos="0 0 -0.1157">
              <inertial pos="-5.874e-05 0.00486789 -0.0240026" quat="0.693551 -0.0250113 0.0255123 0.719522" mass="1.216" diaginertia="0.00246331 0.0024161 0.000829409"/>
              <joint name="left_elbow_joint" pos="0 0 0" axis="0 1 0" limited="true" range="-2.5307 1.2915" armature="0.045760625"/>
              <geom type="mesh" class="visual" rgba="1 1 1 1" mesh="left_elbow_link"/>
              <body name="left_wrist_yaw_link" pos="0 0 -0.1048">
                <inertial pos="0 0.00240189 -0.0176639" quat="0.736317 0.676629 0.00218251 -0.00226384" mass="0.116" diaginertia="0.000131201 0.000116937 8.07627e-05"/>
                <joint name="left_wrist_yaw_joint" pos="0 0 0" axis="0 0 1" limited="true" range="-1.571 1.571" armature="0.010625"/>
                <geom type="mesh" class="visual" rgba="1 1 1 1" mesh="left_wrist_yaw_link"/>
                <body name="left_wrist_pitch_link" pos="0 0 -0.0345">
                  <inertial pos="-3.73e-06 0.00334909 -0.0313572" quat="0.751924 -0.0368095 0.0331339 0.657387" mass="0.651" diaginertia="0.000930971 0.000928884 0.000330635"/>
                  <joint name="left_wrist_pitch_joint" pos="0 0 0" axis="0 1 0" limited="true" range="-1.571 1.571" armature="0.010625"/>
                  <geom type="mesh" class="visual" rgba="1 1 1 1" mesh="left_wrist_pitch_link"/>
                  <body name="left_hand_yaw_link" pos="0 0 -0.0815">
                    <inertial pos="2.8e-06 -4.277e-05 -0.0588716" quat="1 0.000769182 2.28644e-05 1.75869e-08" mass="0.261" diaginertia="0.00057637 0.000470531 0.000139009"/>
                    <joint name="left_hand_yaw_joint" pos="0 0 0" axis="0 0 1" limited="true" range="-2.356 2.356" armature="0.010625"/>
                    <geom type="mesh" class="visual" rgba="1 1 1 1" mesh="left_hand_yaw_link"/>
                    <body name="contact_left_hand" pos="0.0 0 0.0">
                      <inertial pos="0.0 0.0 0.0" quat="1 0 0 0" mass="0.00001" diaginertia="0.00000000001 0.00000000001 0.00000000001"/>
                      <geom name="contact_left_hand" class="visual" size="0.003" type="sphere" rgba="1 0 0 1"/>
                    </body>
                  </body>
                </body>
              </body>
            </body>
          </body>
        </body>
      </body>
            
      <!-- right arm -->
      <body name="right_shoulder_pitch_link" pos="0 -0.1575 0.2822">
        <inertial pos="0.00608318 -0.0288955 -7.462e-05" quat="0.158288 0.690227 -0.15216 0.689477" mass="0.159" diaginertia="0.000253682 0.000225158 0.00015659"/>
        <joint name="right_shoulder_pitch_joint" pos="0 0 0" axis="0 1 0" limited="true" range="-2.793 2.793" armature="0.045760625"/>
        <geom type="mesh" class="visual" rgba="1 1 1 1" mesh="right_shoulder_pitch_link"/>
        <body name="right_shoulder_roll_link" pos="0 -0.055 0">
          <inertial pos="0.00333695 4.67e-05 -0.0464166" quat="0.999226 0.000395704 0.0352409 0.0174939" mass="1.744" diaginertia="0.0049209 0.00487389 0.00135057"/>
          <joint name="right_shoulder_roll_joint" pos="0 0 0" axis="1 0 0" limited="true" range="-3.229 0.087" armature="0.045760625"/>
          <geom type="mesh" class="visual" rgba="1 1 1 1" mesh="right_shoulder_roll_link"/>
          <body name="right_shoulder_yaw_link" pos="0 0 -0.1306">
            <inertial pos="-0.00951399 -0.00405211 -0.0605306" quat="0.994779 -0.0764191 0.0244622 0.0630583" mass="0.265" diaginertia="0.000739118 0.000654764 0.000325488"/>
            <joint name="right_shoulder_yaw_joint" pos="0 0 0" axis="0 0 1" limited="true" range="-1.571 1.571" armature="0.045760625"/>
            <geom type="mesh" class="visual" rgba="1 1 1 1" mesh="right_shoulder_yaw_link"/>
            <body name="right_elbow_link" pos="0 0 -0.1157">
              <inertial pos="5.719e-05 -0.00484446 -0.0239242" quat="0.69325 0.0248562 -0.0254238 0.719819" mass="1.214" diaginertia="0.00246117 0.00241417 0.000828042"/>
              <joint name="right_elbow_joint" pos="0 0 0" axis="0 1 0" limited="true" range="-2.5307 1.2915" armature="0.045760625"/>
              <geom type="mesh" class="visual" rgba="1 1 1 1" mesh="right_elbow_link"/>
              <body name="right_wrist_yaw_link" pos="0 0 -0.1048">
                <inertial pos="0 -0.00240189 -0.0175639" quat="0.676629 0.736317 -0.00226384 0.00218251" mass="0.116" diaginertia="0.000131201 0.000116937 8.07627e-05"/>
                <joint name="right_wrist_yaw_joint" pos="0 0 0" axis="0 0 1" limited="true" range="-1.571 1.571" armature="0.010625"/>
                <geom type="mesh" class="visual" rgba="1 1 1 1" mesh="right_wrist_yaw_link"/>
                <body name="right_wrist_pitch_link" pos="0 0 -0.0345">
                  <inertial pos="3.73e-06 -0.00334909 -0.0313572" quat="0.751924 0.0368095 -0.0331339 0.657387" mass="0.651" diaginertia="0.000930971 0.000928884 0.000330635"/>
                  <joint name="right_wrist_pitch_joint" pos="0 0 0" axis="0 1 0" limited="true" range="-1.571 1.571" armature="0.010625"/>
                  <geom type="mesh" class="visual" rgba="1 1 1 1" mesh="right_wrist_pitch_link"/>
                  <body name="right_hand_yaw_link" pos="0 0 -0.0815">
                    <inertial pos="-2.8e-06 4.277e-05 -0.0587716" quat="1 -0.000769182 -2.28644e-05 1.75869e-08" mass="0.261" diaginertia="0.00057637 0.000470531 0.000139009"/>
                    <joint name="right_hand_yaw_joint" pos="0 0 0" axis="0 0 1" limited="true" range="-2.356 2.356" armature="0.010625"/>
                    <geom type="mesh" class="visual" rgba="1 1 1 1" mesh="right_hand_yaw_link"/>
                    <body name="contact_right_hand" pos="0.0 0 0.0">
                      <inertial pos="0.0 0.0 0.0" quat="1 0 0 0" mass="0.00001" diaginertia="0.00000000001 0.00000000001 0.00000000001"/>
                      <geom name="contact_right_hand" class="visual" size="0.003" type="sphere" rgba="1 0 0 1"/>
                    </body>
                  </body>
                </body>
              </body>
            </body>
          </body>
        </body>
      </body>
    </body>
  </worldbody>

</mujoco>
