<mujoco model="DA_D03_01">
    <compiler angle="radian" meshdir='../meshes/DA_D03_01'/>
    <size njmax="5000" nconmax="1000"/>
  
    <default>
      <light castshadow="false" diffuse="1 1 1" />
      <camera fovy="60" />
      <default class="visual">
        <geom contype="0" conaffinity="0" group="1" type="mesh" rgba="0.8 0.8 0.8 1.0" />
      </default>
      <joint damping="0.01" armature="0.089947268" margin="0.0001" />
      <geom contype="1" conaffinity="1" friction="1.0 0.3 0.3" rgba="0.5 0.6 0.7 0.5" margin="0.001" group="0" />
      <equality solref="0.001  1" />
    </default>
  
    <option timestep="0.001" />
    <!-- <option>
      <flag sensornoise="enable" />
    </option> -->
  
    <visual>
      <rgba com="0.502 1.0 0 1.0" contactpoint="0.5 0.1 0.8 0.4" contactforce="0.2 0.98 0.2 0.8" />
      <scale com="0.2" forcewidth="0.05" contactwidth="0.10" contactheight="0.04" />
    </visual>
  
    <asset>
      <mesh name="base_link" file="base_link.STL"/>
      <mesh name="left_shoulder_pitch_link" file="left_shoulder_pitch_link.STL"/>
      <mesh name="left_shoulder_roll_link" file="left_shoulder_roll_link.STL"/>
      <mesh name="left_shoulder_yaw_link" file="left_shoulder_yaw_link.STL"/>
      <mesh name="left_elbow_link" file="left_elbow_link.STL"/>
      <mesh name="left_wrist_yaw_link" file="left_hand_yaw_link.STL"/>
      <mesh name="left_wrist_pitch_link" file="left_hand_pitch_link.STL"/>
      <mesh name="left_wrist_roll_link" file="left_hand_roll_link.STL"/>

      <mesh name="right_shoulder_pitch_link" file="right_shoulder_pitch_link.STL"/>
      <mesh name="right_shoulder_roll_link" file="right_shoulder_roll_link.STL"/>
      <mesh name="right_shoulder_yaw_link" file="right_shoulder_yaw_link.STL"/>
      <mesh name="right_elbow_link" file="right_elbow_link.STL"/>
      <mesh name="right_wrist_yaw_link" file="right_hand_yaw_link.STL"/>
      <mesh name="right_wrist_pitch_link" file="right_hand_pitch_link.STL"/>
      <mesh name="right_wrist_roll_link" file="right_hand_roll_link.STL"/>
      
      <mesh name="neck_yaw_link" file="neck_yaw_link.STL"/>
      <mesh name="neck_pitch_link" file="neck_pitch_link.STL"/>
    </asset>
    
    <asset>
      <texture type="skybox" builtin="gradient" width="512" height="512" rgb1="1.0 1.0 1.0" rgb2="1.0 1.0 1.0" />
      <texture name="plane" type="2d" builtin="flat" rgb1="1 1 1" rgb2="1 1 1" width="512" height="512" mark="cross" markrgb="0 0 0" />
      <material name="plane" reflectance="0.0" texture="plane" texrepeat="3 3" texuniform="true" />
    </asset>
    
    <worldbody>
      <geom name="floor" pos="0 0 0" euler="0 0 0" size="0 0 1" type="plane" material="plane" condim="3" conaffinity="1" contype="1" rgba="1 1 1 1" />
      <light directional="true" diffuse=".8 .8 .8" pos="0 0 10" dir="0 0 -10" />
      <camera name="track" mode="trackcom" pos="0 -2.3 1.6" xyaxes="1 0 0 0 0.707 0.707" />
      <geom pos="0 0 1.0" type="mesh" class="visual" rgba="1 1 1 1" mesh="base_link"/>
  
      <!-- left arm -->
      <body name="left_shoulder_pitch_link" pos="0 0.1525 1.3957">
        <inertial pos="0.00727 0.0353 0" quat="-0.129632 0.694914 0.130919 0.69509" mass="0.268" diaginertia="0.000487056 0.000471848 0.000283124"/>
        <joint name="left_shoulder_pitch_joint" pos="0 0 0" axis="0 1 0" limited="true" range="-3.14 3.14" armature="0.089947268" />
        <geom type="mesh" class="visual" mesh="left_shoulder_pitch_link"/>
        
        <body name="left_shoulder_roll_link" pos="0 0.0685 0">
          <inertial pos="0.00374 0 -0.05126" quat="0.717878 0.0264961 0.0301058 0.695013" mass="1.817" diaginertia="0.00663993 0.00645852 0.00167661"/>
          <joint name="left_shoulder_roll_joint" pos="0 0 0" axis="1 0 0" limited="true" range="-0.0262 3.1678" armature="0.089947268" />
          <geom type="mesh" class="visual" mesh="left_shoulder_roll_link"/>
          <geom type="capsule" pos="0 0 0" size="0.04 0.03" euler="0 1.57 0" />
    
          <body name="left_shoulder_yaw_link" pos="0 0 -0.1378">
            <inertial pos="-0.00735 0.00248 -0.07621" quat="0.99856 0.0446179 0.0253021 -0.0157119" mass="0.3466" diaginertia="0.00123474 0.00101205 0.000521748"/>
            <joint name="left_shoulder_yaw_joint" pos="0 0 0" axis="0 0 1" limited="true" range="-1.5708 1.5708" armature="0.089947268" />
            <geom type="mesh" class="visual" mesh="left_shoulder_yaw_link"/>
    
            <body name="left_elbow_link" pos="0 0 -0.1322">
              <inertial pos="-0.00121 0.00736 0.00424" quat="0.982902 -0.160618 0.0879565 -0.0192169" mass="0.992" diaginertia="0.00111792 0.000992882 0.000945581"/>
              <joint name="left_elbow_joint" pos="0 0 0" axis="0 1 0" limited="true" range="-2.4958 0" armature="0.089947268" />
              <geom type="mesh" class="visual" mesh="left_elbow_link"/>
              <geom type="capsule" pos="0 0 0" size="0.04 0.03" euler="1.57 0 0" />
    
              <body name="left_wrist_yaw_link" pos="0 0 -0.0591">
                <inertial pos="-0.00117 0.00328 -0.08889" quat="0.999878 0.0101609 -0.00309121 0.0114933" mass="1.2269" diaginertia="0.00522292 0.00512282 0.000674555"/>
                <joint name="left_wrist_yaw_joint" pos="0 0 0" axis="0 0 1" limited="true" range="-1.5708 1.5708" armature="0.015556062" />
                <geom type="mesh" class="visual" mesh="left_wrist_yaw_link"/>
                <geom type="capsule" pos="0 0 -0.09" size="0.035 0.06" euler="0 0 0" />
    
                <body name="left_wrist_roll_link" pos="0 0 -0.2254">
                  <inertial pos="0.00228 -0.0321 0.00331" quat="0.690069 -0.188101 0.178488 0.675696" mass="0.497" diaginertia="0.00036207 0.000329978 0.000245468"/>
                  <joint name="left_wrist_roll_joint" pos="0 0 0" axis="0 1 0" limited="true" range="-0.6981 0.5236" armature="0.015556062" />
                  <geom type="mesh" class="visual" mesh="left_wrist_roll_link"/>
                  <geom type="capsule" pos="0 0 0" size="0.03 0.015" euler="0 1.57 0" />
    
                  <body name="left_wrist_pitch_link" pos="0 0 0">
                    <inertial pos="-0.000664094 0 -0.0684883" quat="0.707057 -0.00837537 -0.00837537 0.707057" mass="0.2269" diaginertia="0.000424793 0.000356834 0.000157137"/>
                    <joint name="left_wrist_pitch_joint" pos="0 0 0" axis="1 0 0" limited="true" range="-1.5708 0.7854" armature="0.015556062" />
                    <geom type="mesh" class="visual" mesh="left_wrist_pitch_link"/>

                    <geom size="0.034" pos="0 0 -0.097" type="sphere"/>

                  </body>
                </body>
              </body>
            </body>
          </body>
        </body>
      </body>
      
      <!-- right arm -->
      <body name="right_shoulder_pitch_link" pos="0 -0.1525 1.3957">
        <inertial pos="0.00727 -0.0353 0" quat="0.129632 0.694914 -0.130919 0.69509" mass="0.268" diaginertia="0.000487056 0.000471848 0.000283124"/>
        <joint name="right_shoulder_pitch_joint" pos="0 0 0" axis="0 1 0" limited="true" range="-3.14 3.14" armature="0.089947268" />
        <geom type="mesh" class="visual" mesh="right_shoulder_pitch_link"/>
        
        <body name="right_shoulder_roll_link" pos="0 -0.0685 0">
          <inertial pos="0.00374 0 -0.05126" quat="0.695013 0.0301058 0.0264961 0.717878" mass="1.817" diaginertia="0.00663993 0.00645852 0.00167661"/>
          <joint name="right_shoulder_roll_joint" pos="0 0 0" axis="1 0 0" limited="true" range="-3.1678 0.0262" armature="0.089947268" />
          <geom type="mesh" class="visual" mesh="right_shoulder_roll_link"/>
          <geom type="capsule" pos="0 0 0" size="0.04 0.03" euler="0 1.57 0" />
       
          <body name="right_shoulder_yaw_link" pos="0 0 -0.1378">
            <inertial pos="-0.00735 -0.00248 -0.07621" quat="0.99856 -0.0446179 0.0253021 0.0157119" mass="0.3466" diaginertia="0.00123474 0.00101205 0.000521748"/>
            <joint name="right_shoulder_yaw_joint" pos="0 0 0" axis="0 0 1" limited="true" range="-1.5708 1.5708" armature="0.089947268" />
            <geom type="mesh" class="visual" mesh="right_shoulder_yaw_link"/>
       
            <body name="right_elbow_link" pos="0 0 -0.1322">
              <inertial pos="-0.00121 -0.00736 0.00424" quat="0.982902 0.160618 0.0879565 0.0192169" mass="0.992" diaginertia="0.00111792 0.000992882 0.000945581"/>
              <joint name="right_elbow_joint" pos="0 0 0" axis="0 1 0" limited="true" range="-2.4958 0" armature="0.089947268" />
              <geom type="mesh" class="visual" mesh="right_elbow_link"/>
              <geom type="capsule" pos="0 0 0" size="0.04 0.03" euler="1.57 0 0" />
       
              <body name="right_wrist_yaw_link" pos="0 0 -0.0591">
                <inertial pos="-0.00117 -0.00328 -0.08889" quat="0.999878 -0.0101609 -0.00309121 -0.0114933" mass="1.2269" diaginertia="0.00522292 0.00512282 0.000674555"/>
                <joint name="right_wrist_yaw_joint" pos="0 0 0" axis="0 0 1" limited="true" range="-1.5708 1.5708" armature="0.015556062" />
                <geom type="mesh" class="visual" mesh="right_wrist_yaw_link"/>
                <geom type="capsule" pos="0 0 -0.09" size="0.035 0.06" euler="0 0 0" />
       
                <body name="right_wrist_roll_link" pos="0 0 -0.2254">
                  <inertial pos="0.00228 0.0321 0.00331" quat="0.675696 0.178488 -0.188101 0.690069" mass="0.497" diaginertia="0.00036207 0.000329978 0.000245468"/>
                  <joint name="right_wrist_roll_joint" pos="0 0 0" axis="0 1 0" limited="true" range="-0.6981 0.5236" armature="0.015556062" />
                  <geom type="mesh" class="visual" mesh="right_wrist_roll_link"/>
                  <geom type="capsule" pos="0 0 0" size="0.03 0.015" euler="0 1.57 0" />
       
                  <body name="right_wrist_pitch_link" pos="0 0 0">
                    <inertial pos="-0.000664094 0 -0.0684883" quat="0.707057 -0.00837537 -0.00837537 0.707057" mass="0.2269" diaginertia="0.000424793 0.000356834 0.000157137"/>
                    <joint name="right_wrist_pitch_joint" pos="0 0 0" axis="1 0 0" limited="true" range="-0.7854 1.5708" armature="0.015556062" />
                    <geom type="mesh" class="visual" mesh="right_wrist_pitch_link"/>

                    <geom size="0.034" pos="0 0 -0.097" type="sphere"/>

                  </body>
                </body>
              </body>
            </body>
          </body>
        </body>
      </body>
     
      <body name="neck_yaw_link" pos="-0.013 0 1.5027">
        <inertial pos="0.00011 0.00253 0.04305" quat="0.721861 0.691331 -0.0201222 0.0239363" mass="0.46" diaginertia="0.000233962 0.000213101 0.000190887"/>
        <joint name="neck_yaw_joint" pos="0 0 0" axis="0 0 1" limited="true" range="-0.7854 0.7854"/>
        <geom type="mesh" rgba="0.898039 0.917647 0.929412 1" mesh="neck_yaw_link"/>
       
        <body name="neck_pitch_link" pos="0 0.0282 0.045">
          <inertial pos="0.00081 0.00138 0.07215" quat="0.00265078 0.773858 0.0220122 0.632971" mass="0.45" diaginertia="0.00341778 0.0024621 0.00216008"/>
          <joint name="neck_pitch_joint" pos="0 0 0" axis="0 1 0" limited="true" range="-0.9599 0.9599"/>
          <geom type="mesh" rgba="0.513726 0.917647 1 1" mesh="neck_pitch_link"/>
        </body>
      </body>
    </worldbody>

    <actuator>
      <motor name="neck_yaw"     gear="1" joint="neck_yaw_joint"     ctrllimited='true' ctrlrange='-10 10' />
      <motor name="neck_pitch"   gear="1" joint="neck_pitch_joint"   ctrllimited='true' ctrlrange='-10 10' />

      <motor name="shoulder_pitch_left"   gear="1" joint="left_shoulder_pitch_joint"   ctrllimited='true' ctrlrange='-15.5 15.5' />
      <motor name="shoulder_roll_left"    gear="1" joint="left_shoulder_roll_joint"    ctrllimited='true' ctrlrange='-15.5 15.5' />
      <motor name="shoulder_yaw_left"     gear="1" joint="left_shoulder_yaw_joint"     ctrllimited='true' ctrlrange='-15.5 15.5' />
      <motor name="elbow_left"            gear="1" joint="left_elbow_joint"            ctrllimited='true' ctrlrange='-15.5 15.5' />
      <motor name="wrist_yaw_left"        gear="1" joint="left_wrist_yaw_joint"         ctrllimited='true' ctrlrange='-10 10' />
      <motor name="wrist_roll_left"       gear="1" joint="left_wrist_roll_joint"       ctrllimited='true' ctrlrange='-10 10' />
      <motor name="wrist_pitch_left"      gear="1" joint="left_wrist_pitch_joint"      ctrllimited='true' ctrlrange='-10 10' />
      
  
      <motor name="shoulder_pitch_right"  gear="1" joint="right_shoulder_pitch_joint"   ctrllimited='true' ctrlrange='-15.5 15.5' />
      <motor name="shoulder_roll_right"   gear="1" joint="right_shoulder_roll_joint"    ctrllimited='true' ctrlrange='-15.5 15.5' />
      <motor name="shoulder_yaw_right"    gear="1" joint="right_shoulder_yaw_joint"     ctrllimited='true' ctrlrange='-15.5 15.5' />
      <motor name="elbow_right"           gear="1" joint="right_elbow_joint"            ctrllimited='true' ctrlrange='-15.5 15.5' />
      <motor name="wrist_yaw_right"       gear="1" joint="right_wrist_yaw_joint"         ctrllimited='true' ctrlrange='-10 10' />
      <motor name="wrist_roll_right"      gear="1" joint="right_wrist_roll_joint"       ctrllimited='true' ctrlrange='-10 10' />
      <motor name="wrist_pitch_right"     gear="1" joint="right_wrist_pitch_joint"      ctrllimited='true' ctrlrange='-10 10' />      
    </actuator>
  
    <sensor>
      <jointpos name="neck_yaw_pos"    joint="neck_yaw_joint"    noise="0.0" />
      <jointpos name="neck_pitch_pos"  joint="neck_pitch_joint"  noise="0.0" />

      <jointpos name="shoulder_pitch_left_pos"    joint="left_shoulder_pitch_joint" noise="0.0" />
      <jointpos name="shoulder_roll_left_pos"     joint="left_shoulder_roll_joint"  noise="0.0" />
      <jointpos name="shoulder_yaw_left_pos"      joint="left_shoulder_yaw_joint"   noise="0.0" />
      <jointpos name="elbow_left_pos"             joint="left_elbow_joint"          noise="0.0" />
      <jointpos name="wrist_yaw_left_pos"         joint="left_wrist_yaw_joint"       noise="0.0" />
      <jointpos name="wrist_roll_left_pos"        joint="left_wrist_roll_joint"        noise="0.0" />
      <jointpos name="wrist_pitch_left_pos"       joint="left_wrist_pitch_joint"        noise="0.0" />
      
  
      <jointpos name="shoulder_pitch_right_pos"   joint="right_shoulder_pitch_joint" noise="0.0" />
      <jointpos name="shoulder_roll_right_pos"    joint="right_shoulder_roll_joint"  noise="0.0" />
      <jointpos name="shoulder_yaw_right_pos"     joint="right_shoulder_yaw_joint"   noise="0.0" />
      <jointpos name="elbow_right_pos"            joint="right_elbow_joint"          noise="0.0" />
      <jointpos name="wrist_yaw_right_pos"        joint="right_wrist_yaw_joint"       noise="0.0" />
      <jointpos name="wrist_roll_right_pos"       joint="right_wrist_roll_joint"        noise="0.0" />
      <jointpos name="wrist_pitch_right_pos"      joint="right_wrist_pitch_joint"        noise="0.0" />
  
      <jointvel name="neck_yaw_vel" joint="neck_yaw_joint" noise="0.0" />
      <jointvel name="neck_pitch_vel"   joint="neck_pitch_joint"   noise="0.0" /> 
      
      <jointvel name="shoulder_pitch_left_vel"    joint="left_shoulder_pitch_joint" noise="0.0" />
      <jointvel name="shoulder_roll_left_vel"     joint="left_shoulder_roll_joint"  noise="0.0" />
      <jointvel name="shoulder_yaw_left_vel"      joint="left_shoulder_yaw_joint"   noise="0.0" />
      <jointvel name="elbow_left_vel"             joint="left_elbow_joint"          noise="0.0" />
      <jointvel name="wrist_yaw_left_vel"         joint="left_wrist_yaw_joint"       noise="0.0" />
      <jointvel name="wrist_roll_left_vel"        joint="left_wrist_roll_joint"        noise="0.0" />
      <jointvel name="wrist_pitch_left_vel"       joint="left_wrist_pitch_joint"        noise="0.0" />
  
      <jointvel name="shoulder_pitch_right_vel"   joint="right_shoulder_pitch_joint" noise="0.0" />
      <jointvel name="shoulder_roll_right_vel"    joint="right_shoulder_roll_joint"  noise="0.0" />
      <jointvel name="shoulder_yaw_right_vel"     joint="right_shoulder_yaw_joint"   noise="0.0" />
      <jointvel name="elbow_right_vel"            joint="right_elbow_joint"          noise="0.0" />
      <jointvel name="wrist_yaw_right_vel"        joint="right_wrist_yaw_joint"       noise="0.0" />
      <jointvel name="wrist_roll_right_vel"       joint="right_wrist_roll_joint"        noise="0.0" />
      <jointvel name="wrist_pitch_right_vel"      joint="right_wrist_pitch_joint"        noise="0.0" />
    </sensor>
  </mujoco>