<?xml version="1.0" encoding="utf-8"?>
<!-- This URDF was automatically created by SolidWorks to URDF Exporter! Originally created by Stephen Brawner (brawner@gmail.com) 
     Commit Version: 1.6.0-4-g7f85cfe  Build Version: 1.6.7995.38578
     For more information, please see http://wiki.ros.org/sw_urdf_exporter -->
<robot name="DA_D03_01">
  
  <link name="world" />
    <origin rpy="0 0 0" xyz="0.0 0.0 0.5" />
  <joint name="fixed" type="fixed">
    <parent link="world" />
    <child link="base_link" />
  </joint>

  <link
    name="base_link">
    <inertial>
      <origin
        xyz="-0.00943 0.00116 0.31369"
        rpy="0 0 0" />
      <mass
        value="4.93193684873739" />
      <inertia
        ixx="0.21069723"
        ixy="0.00010004"
        ixz="0.00569500"
        iyy="0.18074077"
        iyz="-0.00074177"
        izz="0.08261326" />
    </inertial>
    <visual>
      <origin
        xyz="0 0 0"
        rpy="0 0 0" />
      <geometry>
        <mesh
          filename="package://DA_D03_01_description/meshes/base_link.STL" />
      </geometry>
      <material
        name="">
        <color
          rgba="1 1 1 1" />
      </material>
    </visual>
    <collision>
      <origin
        xyz="0 0 0"
        rpy="0 0 0" />
      <geometry>
        <mesh
          filename="package://DA_D03_01_description/meshes/base_link.STL" />
      </geometry>
    </collision>
  </link>
  <!-- left arm -->
  <link name="left_shoulder_pitch_link">
    <inertial>
      <origin
        xyz="0.00727 0.0353 0"
        rpy="0 0 0" />
      <mass value="0.268" />
      <inertia
        ixx="307.877939E-06"
        ixy="-63.709473E-06"
        ixz="0.007018E-06"
        iyy="447.093993E-06"
        iyz="0.032674E-06"
        izz="487.055703E-06" />
    </inertial>
    <visual>
      <origin
        xyz="0 0 0"
        rpy="0 0 0" />
      <geometry>
        <mesh
          filename="package://DA_D03_description/meshes/DA_D03_01/left_shoulder_pitch_link.STL" />
      </geometry>
      <material
        name="">
        <color
          rgba="0.898039215686275 0.917647058823529 0.929411764705882 1" />
      </material>
    </visual>
  </link>
  <joint name="left_shoulder_pitch_joint" type="revolute">
    <origin
      xyz="0 0.1525 0.3957"
      rpy="0 0 0" />
    <parent link="base_link" />
    <child link="left_shoulder_pitch_link" />
    <axis xyz="0 1 0" />
    <limit
      lower="-3.14"
      upper="3.14"
      effort="15.5"
      velocity="16" />
  </joint>
  
  <link name="left_shoulder_roll_link">
    <inertial>
      <origin
        xyz="0.00374 0 -0.05126"
        rpy="0 0 0" />
      <mass value="1.817" />
      <inertia
        ixx="6428.062884E-06"
        ixy="4.363539E-06"
        ixz="-381.621256E-06"
        iyy="6639.669557E-06"
        iyz="-19.299648E-06"
        izz="1707.334120E-06" />
    </inertial>
    <visual>
      <origin
        xyz="0 0 0"
        rpy="0 0 0" />
      <geometry>
        <mesh
          filename="package://DA_D03_description/meshes/DA_D03_01/left_shoulder_roll_link.STL" />
      </geometry>
      <material
        name="">
        <color
          rgba="0.792156862745098 0.819607843137255 0.933333333333333 1" />
      </material>
    </visual>
  </link>
  <joint name="left_shoulder_roll_joint" type="revolute">
    <origin
      xyz="0 0.0685 0"
      rpy="0 0 0" />
    <parent link="left_shoulder_pitch_link" />
    <child link="left_shoulder_roll_link" />
    <axis xyz="1 0 0" />
    <limit
      lower="-0.0262"
      upper="3.1678"
      effort="15.5"
      velocity="16" />
  </joint>
  
  <link name="left_shoulder_yaw_link">
    <inertial>
      <origin
        xyz="-0.00735 0.00248 -0.07621"
        rpy="0 0 0" />
      <mass value="0.3466" />
      <inertia
        ixx="1232.765984E-06"
        ixy="-4.307641E-06"
        ixz="-35.505806E-06"
        iyy="1008.280275E-06"
        iyz="44.184513E-06"
        izz="527.495140E-06" />
    </inertial>
    <visual>
      <origin
        xyz="0 0 0"
        rpy="0 0 0" />
      <geometry>
        <mesh
          filename="package://DA_D03_description/meshes/DA_D03_01/left_shoulder_yaw_link.STL" />
      </geometry>
      <material
        name="">
        <color
          rgba="0.898039215686275 0.917647058823529 0.929411764705882 1" />
      </material>
    </visual>
  </link>
  <joint name="left_shoulder_yaw_joint" type="revolute">
    <origin
      xyz="0 0 -0.1378"
      rpy="0 0 0" />
    <parent link="left_shoulder_roll_link" />
    <child link="left_shoulder_yaw_link" />
    <axis xyz="0 0 1" />
    <limit
      lower="-1.5708"
      upper="1.5708"
      effort="15.5"
      velocity="16" />
  </joint>
  
  <link name="left_elbow_link">
    <inertial>
      <origin
        xyz="-0.00121 0.00736 0.00424"
        rpy="0 0 0" />
      <mass value="0.992" />
      <inertia
        ixx="1112.383468E-06"
        ixy="-10.768578E-06"
        ixz="-28.412523E-06"
        iyy="988.811840E-06"
        iyz="-12.407378E-06"
        izz="955.189444E-06" />
    </inertial>
    <visual>
      <origin
        xyz="0 0 0"
        rpy="0 0 0" />
      <geometry>
        <mesh
          filename="package://DA_D03_description/meshes/DA_D03_01/left_elbow_link.STL" />
      </geometry>
      <material
        name="">
        <color
          rgba="0.180392156862745 0.180392156862745 0.180392156862745 1" />
      </material>
    </visual>
  </link>
  <joint name="left_elbow_joint" type="revolute">
    <origin
      xyz="0 0 -0.1322"
      rpy="0 0 0" />
    <parent link="left_shoulder_yaw_link" />
    <child link="left_elbow_link" />
    <axis xyz="0 1 0" />
    <limit
      lower="-2.4958"
      upper="0"
      effort="15.5"
      velocity="16" />
  </joint>
  
  <link name="left_wrist_yaw_link">
    <inertial>
      <origin
        xyz="-0.00117 0.00328 -0.08889"
        rpy="0 0 0" />
      <mass value="1.2269" />
      <inertia
        ixx="5222.709361E-06"
        ixy="1.754376E-06"
        ixz="27.094430E-06"
        iyy="5121.021103E-06"
        iyz="90.696007E-06"
        izz="676.565940E-06" />
    </inertial>
    <visual>
      <origin
        xyz="0 0 0"
        rpy="0 0 0" />
      <geometry>
        <mesh
          filename="package://DA_D03_description/meshes/DA_D03_01/left_wrist_yaw_link.STL" />
      </geometry>
      <material
        name="">
        <color
          rgba="0.898039215686275 0.917647058823529 0.929411764705882 1" />
      </material>
    </visual>
  </link>
  <joint name="left_wrist_yaw_joint" type="revolute">
    <origin
      xyz="0 0 -0.0591"
      rpy="0 0 0" />
    <parent link="left_elbow_link" />
    <child link="left_wrist_yaw_link" />
    <axis xyz="0 0 1" />
    <limit
      lower="-1.5708"
      upper="1.5708"
      effort="10"
      velocity="15" />
  </joint>
  
  <link name="left_wrist_roll_link">
    <inertial>
      <origin
        xyz="0.00228 -0.0321 0.00331"
        rpy="0 0 0" />
      <mass value="0.497" />
      <inertia
        ixx="329.990110E-06"
        ixy="0.975745E-06"
        ixz="0.203073E-06"
        iyy="332.816281E-06"
        iyz="-50.533228E-06"
        izz="274.709694E-06" />
    </inertial>
    <visual>
      <origin
        xyz="0 0 0"
        rpy="0 0 0" />
      <geometry>
        <mesh
          filename="package://DA_D03_description/meshes/DA_D03_01/left_wrist_roll_link.STL" />
      </geometry>
      <material
        name="">
        <color
          rgba="0.898039215686275 0.917647058823529 0.929411764705882 1" />
      </material>
    </visual>
  </link>
  <joint name="left_wrist_roll_joint" type="revolute">
    <origin
      xyz="0 0 -0.2254"
      rpy="0 0 0" />
    <parent link="left_wrist_yaw_link" />
    <child link="left_wrist_roll_link" />
    <axis xyz="0 1 0" />
    <limit
      lower="-0.6981"
      upper="0.5236"
      effort="10"
      velocity="15" />
  </joint>
  
  <link name="left_wrist_pitch_link">
    <inertial>
      <origin
        xyz="-0.00067 0 -0.068634"
        rpy="0 0 0" />
      <mass
        value="0.2249" />
      <inertia
        ixx="355.979848E-06"
        ixy="0.000006E-06"
        ixz="4.750950E-06"
        iyy="424.050358E-06"
        iyz="0.000025E-06"
        izz="157.047882E-06" />
    </inertial>
    <visual>
      <origin
        xyz="0 0 0"
        rpy="0 0 0" />
      <geometry>
        <mesh
          filename="package://DA_D03_description/meshes/DA_D03_01/left_wrist_pitch_link.STL" />
      </geometry>
      <material
        name="">
        <color
          rgba="0.898039215686275 0.917647058823529 0.929411764705882 1" />
      </material>
    </visual>
  </link>
  <joint name="left_wrist_pitch_joint" type="revolute">
    <origin
      xyz="0 0 0"
      rpy="0 0 0" />
    <parent link="left_wrist_roll_link" />
    <child link="left_wrist_pitch_link" />
    <axis xyz="1 0 0" />
    <limit
      lower="-1.5708"
      upper="0.7854"
      effort="10"
      velocity="15" />
  </joint>


  <!-- right arm -->
  <link name="right_shoulder_pitch_link">
    <inertial>
      <origin
        xyz="0.00727 -0.0353 0"
        rpy="0 0 0" />
      <mass value="0.268" />
      <inertia
        ixx="307.877939E-06"
        ixy="63.709473E-06"
        ixz="0.007018E-06"
        iyy="447.093993E-06"
        iyz="-0.032674E-06"
        izz="487.055703E-06" />
    </inertial>
    <visual>
      <origin
        xyz="0 0 0"
        rpy="0 0 0" />
      <geometry>
        <mesh
          filename="package://DA_D03_description/meshes/DA_D03_01/right_shoulder_pitch_link.STL" />
      </geometry>
      <material
        name="">
        <color
          rgba="0.9 0.9 0.9 1" />
      </material>
    </visual>
  </link>
  <joint name="right_shoulder_pitch_joint" type="revolute">
    <origin
      xyz="0 -0.1525 0.3957"
      rpy="0 0 0" />
    <parent link="base_link" />
    <child link="right_shoulder_pitch_link" />
    <axis xyz="0 1 0" />
    <limit
      lower="-3.14"
      upper="3.14"
      effort="15.5"
      velocity="16" />
  </joint>
  
  <link name="right_shoulder_roll_link">
    <inertial>
      <origin
        xyz="0.00374 0 -0.05126"
        rpy="0 0 0" />
      <mass value="1.817" />
      <inertia
        ixx="6428.062884E-06"
        ixy="-4.363539E-06"
        ixz="-381.621256E-06"
        iyy="6639.669557E-06"
        iyz="19.299648E-06"
        izz="1707.334120E-06" />
    </inertial>
    <visual>
      <origin
        xyz="0 0 0"
        rpy="0 0 0" />
      <geometry>
        <mesh
          filename="package://DA_D03_description/meshes/DA_D03_01/right_shoulder_roll_link.STL" />
      </geometry>
      <material
        name="">
        <color
          rgba="0.9 0.9 0.9 1" />
      </material>
    </visual>
  </link>
  <joint name="right_shoulder_roll_joint" type="revolute">
    <origin
      xyz="0 -0.0685 0"
      rpy="0 0 0" />
    <parent link="right_shoulder_pitch_link" />
    <child link="right_shoulder_roll_link" />
    <axis xyz="1 0 0" />
    <limit
      lower="-3.1678"
      upper="0.0262"
      effort="15.5"
      velocity="16" />
  </joint>
  
  <link name="right_shoulder_yaw_link">
    <inertial>
      <origin
        xyz="-0.00735 -0.00248 -0.07621"
        rpy="0 0 0" />
      <mass value="0.3466" />
      <inertia
        ixx="1232.765984E-06"
        ixy="4.307641E-06"
        ixz="-35.505806E-06"
        iyy="1008.280275E-06"
        iyz="-44.184513E-06"
        izz="527.495140E-06" />
    </inertial>
    <visual>
      <origin
        xyz="0 0 0"
        rpy="0 0 0" />
      <geometry>
        <mesh
          filename="package://DA_D03_description/meshes/DA_D03_01/right_shoulder_yaw_link.STL" />
      </geometry>
      <material
        name="">
        <color
          rgba="0.898039215686275 0.917647058823529 0.929411764705882 1" />
      </material>
    </visual>
  </link>
  <joint name="right_shoulder_yaw_joint" type="revolute">
    <origin
      xyz="0 0 -0.1378"
      rpy="0 0 0" />
    <parent link="right_shoulder_roll_link" />
    <child link="right_shoulder_yaw_link" />
    <axis xyz="0 0 1" />
    <limit
      lower="-1.5708"
      upper="1.5708"
      effort="15.5"
      velocity="16" />
  </joint>
  
  <link name="right_elbow_link">
    <inertial>
      <origin
        xyz="-0.00121 -0.00736 0.00424"
        rpy="0 0 0" />
      <mass value="0.992" />
      <inertia
        ixx="1112.383468E-06"
        ixy="10.768578E-06"
        ixz="-28.412523E-06"
        iyy="988.811840E-06"
        iyz="12.407378E-06"
        izz="955.189444E-06" />
    </inertial>
    <visual>
      <origin
        xyz="0 0 0"
        rpy="0 0 0" />
      <geometry>
        <mesh
          filename="package://DA_D03_description/meshes/DA_D03_01/right_elbow_link.STL" />
      </geometry>
      <material
        name="">
        <color
          rgba="0.792156862745098 0.819607843137255 0.933333333333333 1" />
      </material>
    </visual>
  </link>
  <joint name="right_elbow_joint" type="revolute">
    <origin
      xyz="0 0 -0.1322"
      rpy="0 0 0" />
    <parent link="right_shoulder_yaw_link" />
    <child link="right_elbow_link" />
    <axis xyz="0 1 0" />
    <limit
      lower="-2.4958"
      upper="0"
      effort="15.5"
      velocity="16" />
  </joint>
  
  <link name="right_wrist_yaw_link">
    <inertial>
      <origin
        xyz="-0.00117 -0.00328 -0.08889"
        rpy="0 0 0" />
      <mass value="1.2269" />
      <inertia
        ixx="5222.709361E-06"
        ixy="-1.754376E-06"
        ixz="27.094430E-06"
        iyy="5121.021103E-06"
        iyz="-90.696007E-06"
        izz="676.565940E-06" />
    </inertial>
    <visual>
      <origin
        xyz="0 0 0"
        rpy="0 0 0" />
      <geometry>
        <mesh
          filename="package://DA_D03_description/meshes/DA_D03_01/right_wrist_yaw_link.STL" />
      </geometry>
      <material
        name="">
        <color
          rgba="0.898039215686275 0.917647058823529 0.929411764705882 1" />
      </material>
    </visual>
  </link>
  <joint name="right_wrist_yaw_joint" type="revolute">
    <origin
      xyz="0 0 -0.0591"
      rpy="0 0 0" />
    <parent link="right_elbow_link" />
    <child link="right_wrist_yaw_link" />
    <axis xyz="0 0 1" />
    <limit
      lower="-1.5708"
      upper="1.5708"
      effort="10"
      velocity="15" />
  </joint>
  
  <link name="right_wrist_roll_link">
    <inertial>
      <origin
        xyz="0.00228 0.0321 0.00331"
        rpy="0 0 0" />
      <mass value="0.497" />
      <inertia
        ixx="329.990110E-06"
        ixy="-0.975745E-06"
        ixz="0.203073E-06"
        iyy="332.816281E-06"
        iyz="50.533228E-06"
        izz="274.709694E-06" />
    </inertial>
    <visual>
      <origin
        xyz="0 0 0"
        rpy="0 0 0" />
      <geometry>
        <mesh
          filename="package://DA_D03_description/meshes/DA_D03_01/right_wrist_roll_link.STL" />
      </geometry>
      <material
        name="">
        <color
          rgba="0.898039215686275 0.917647058823529 0.929411764705882 1" />
      </material>
    </visual>
  </link>
  <joint name="right_wrist_roll_joint" type="revolute">
    <origin
      xyz="0 0 -0.2254"
      rpy="0 0 0" />
    <parent link="right_wrist_yaw_link" />
    <child link="right_wrist_roll_link" />
    <axis xyz="0 1 0" />
    <limit
      lower="-0.6981"
      upper="0.5236"
      effort="10"
      velocity="15" />
  </joint>
  
  <link name="right_wrist_pitch_link">
    <inertial>
      <origin
        xyz="-0.00067 0 -0.068634"
        rpy="0 0 0" />
      <mass
        value="0.2249" />
      <inertia
        ixx="355.979848E-06"
        ixy="-0.000006E-06"
        ixz="4.750950E-06"
        iyy="424.050358E-06"
        iyz="-0.000025E-06"
        izz="157.047882E-06" />
    </inertial>
    <visual>
      <origin
        xyz="0 0 0"
        rpy="0 0 0" />
      <geometry>
        <mesh
          filename="package://DA_D03_description/meshes/DA_D03_01/right_wrist_pitch_link.STL" />
      </geometry>
      <material
        name="">
        <color
          rgba="0.898039215686275 0.917647058823529 0.929411764705882 0.25" />
      </material>
    </visual>
  </link>
  <joint name="right_wrist_pitch_joint" type="revolute">
    <origin
      xyz="0 0 0"
      rpy="0 0 0" />
    <parent link="right_wrist_roll_link" />
    <child link="right_wrist_pitch_link" />
    <axis xyz="1 0 0" />
    <limit
      lower="-0.7854"
      upper="1.5708"
      effort="10"
      velocity="15" />
  </joint>
  
  <link name="head_yaw_link">
    <inertial>
      <origin
        xyz="0.00009 0.00313 0.04319"
        rpy="0 0 0" />
      <mass
        value="0.146953052787906" />
      <inertia
        ixx="223.88E-06"
        ixy="-0.04E-06"
        ixz="1.37E-06"
        iyy="187.75E-06"
        iyz="3.13E-06"
        izz="202.82E-06" />
    </inertial>
    <visual>
      <origin
        xyz="0 0 0"
        rpy="0 0 0" />
      <geometry>
        <mesh
          filename="package://DA_D03_01_description/meshes/neck_yaw_link.STL" />
      </geometry>
      <material
        name="">
        <color
          rgba="0.898039215686275 0.917647058823529 0.929411764705882 1" />
      </material>
    </visual>
    <collision>
      <origin
        xyz="0 0 0"
        rpy="0 0 0" />
      <geometry>
        <mesh
          filename="package://DA_D03_01_description/meshes/neck_yaw_link.STL" />
      </geometry>
    </collision>
  </link>
  <joint
    name="neck_yaw_joint"
    type="revolute">
    <origin
      xyz="-0.013 0 0.5027"
      rpy="0 0 0" />
    <parent
      link="base_link" />
    <child
      link="head_yaw_link" />
    <axis
      xyz="0 0 1" />
    <limit
      lower="-0.7854"
      upper="0.7854"
      effort="6"
      velocity="10" />
  </joint>
  <link
    name="neck_pitch_link">
    <inertial>
      <origin
        xyz="0.06315 -0.02533 00.05810"
        rpy="0 0 0" />
      <mass
        value="0.106119315352685" />
      <inertia
        ixx="136.959450E-06"
        ixy="29.544002E-06"
        ixz="-65.052272E-06"
        iyy="200.209540E-06"
        iyz="17.643495E-06"
        izz="253.810027E-06" />
    </inertial>
    <visual>
      <origin
        xyz="0 0 0"
        rpy="0 0 0" />
      <geometry>
        <mesh
          filename="package://DA_D03_01_description/meshes/neck_pitch_link.STL" />
      </geometry>
      <material
        name="">
        <color
          rgba="0.513725490196078 0.917647058823529 1 1" />
      </material>
    </visual>
    <collision>
      <origin
        xyz="0 0 0"
        rpy="0 0 0" />
      <geometry>
        <mesh
          filename="package://DA_D03_01_description/meshes/neck_pitch_link.STL" />
      </geometry>
    </collision>
  </link>
  <joint
    name="neck_pitch_joint"
    type="revolute">
    <origin
      xyz="0 0.0282 0.045"
      rpy="0 0 0" />
    <parent
      link="head_yaw_link" />
    <child
      link="neck_pitch_link" />
    <axis
      xyz="0 1 0" />
    <limit
      lower="-0.9599"
      upper="0.9599"
      effort="6"
      velocity="10" />
  </joint>
</robot>