<?xml version="1.0" encoding="utf-8"?>
<!-- This URDF was automatically created by SolidWorks to URDF Exporter! Originally created by Stephen Brawner (brawner@gmail.com) 
     Commit Version: 1.6.0-4-g7f85cfe  Build Version: 1.6.7995.38578
     For more information, please see http://wiki.ros.org/sw_urdf_exporter -->
<robot name="HU_D03_02">

  <!-- <link name="root_link">
    <inertial>
      <origin xyz="0 0 0" rpy="0 0 0" />
      <mass value="0.001" />
      <inertia ixx="1E-10" ixy="0" ixz="0" iyy="1E-10" iyz="0" izz="1E-10" />
    </inertial>
  </link>
  <joint name="floating_base_joint" type="floating">
    <origin xyz="0.0 0.0 0.0" rpy="0 0 0" />
    <parent link="root_link" />
    <child link="base_link" />
  </joint> -->

  <link name="base_link">
    <inertial>
      <origin
        xyz="-3.70E-03 0.06E-03 34.67E-03"
        rpy="0 0 0" />
      <mass
        value="5.76" />
      <inertia
        ixx="36268.77E-06"
        ixy="10.17E-06"
        ixz="1787.32E-06"
        iyy="14780.36E-06"
        iyz="-17.53E-06"
        izz="38778.09E-06" />
    </inertial>
    <visual>
      <origins
        xyz="0 0 0"
        rpy="0 0 0" />
      <geometry>
        <mesh
          filename="../meshes/HU_D03_02/base_link.STL" />
      </geometry>
      <material
        name="">
        <color
          rgba="0.898039215686275 0.917647058823529 0.929411764705882 1" />
      </material>
    </visual>
    <collision>
      <origin xyz="0. 0. 0." rpy="0. 0. 0."/>
      <geometry>
        <mesh filename="../meshes/HU_D03_02/base_link.STL" scale="1. 1. 1."/>
      </geometry>
    </collision>
    <!--<collision>
      <origin
        xyz="0 0 0"
        rpy="0 0 0" />
      <geometry>
        <mesh
          filename="../meshes/HU_D03_02/base_link.STL" />
      </geometry>
    </collision>-->
  </link>
  <link
    name="left_hip_pitch_link">
    <inertial>
      <origin
        xyz="-0.5E-03 8.73E-03 -89.61E-03"
        rpy="0 0 0" />
      <mass
        value="2.16" />
      <inertia
        ixx="3512.99E-06"
        ixy="16.75E-06"
        ixz="-31.83E-06"
        iyy="3712.12E-06"
        iyz="-7.32E-06"
        izz="2874.63E-06" />
    </inertial>
    <visual>
      <origin
        xyz="0 0 0"
        rpy="0 0 0" />
      <geometry>
        <mesh
          filename="../meshes/HU_D03_02/left_hip_pitch_link.STL" />
      </geometry>
      <material
        name="">
        <color
          rgba="0.792156862745098 0.819607843137255 0.929411764705882 1" />
      </material>
    </visual>
    <collision>
      <origin xyz="0. 0. 0." rpy="0. 0. 0."/>
      <geometry>
        <mesh filename="../meshes/HU_D03_02/left_hip_pitch_link.STL" scale="1. 1. 1."/>
      </geometry>
    </collision>
    <!--<collision>
      <origin
        xyz="0 0 0"
        rpy="0 0 0" />
      <geometry>
        <mesh
          filename="../meshes/HU_D03_02/left_hip_pitch_link.STL" />
      </geometry>
    </collision>-->
  </link>
  <joint
    name="left_hip_pitch_joint"
    type="revolute">
    <origin
      xyz="0.00999999999999992 0.121089928152532 0.00692261826173951"
      rpy="0 0 0" />
    <parent
      link="base_link" />
    <child
      link="left_hip_pitch_link" />
    <axis
      xyz="0 0.906307787036648 -0.422618261740705" />
    <limit
      lower="-3.1415926"
      upper="3.1415926"
      effort="120"
      velocity="12" />
  </joint>
  <link
    name="left_hip_roll_link">
    <inertial>
      <origin
        xyz="1.4E-03 0.13E-03 -34.98E-03"
        rpy="0 0 0" />
      <mass
        value="0.49" />
      <inertia
        ixx="942.42E-06"
        ixy="-0.26E-06"
        ixz="-17.56E-06"
        iyy="1832.87E-06"
        iyz="1.70E-06"
        izz="1545.72E-06" />
    </inertial>
    <visual>
      <origin
        xyz="0 0 0"
        rpy="0 0 0" />
      <geometry>
        <mesh
          filename="../meshes/HU_D03_02/left_hip_roll_link.STL" />
      </geometry>
      <material
        name="">
        <color
          rgba="0.792156862745098 0.819607843137255 0.933333333333333 1" />
      </material>
    </visual>
    <!--<collision>
      <origin
        xyz="0 0 0"
        rpy="0 0 0" />
      <geometry>
        <mesh
          filename="../meshes/HU_D03_02/left_hip_roll_link.STL" />
      </geometry>
    </collision>-->
  </link>
  <joint
    name="left_hip_roll_joint"
    type="revolute">
    <origin
      xyz="-0.00999999999999996 0.00891007184747122 -0.0954226182617487"
      rpy="0 0 0" />
    <parent
      link="left_hip_pitch_link" />
    <child
      link="left_hip_roll_link" />
    <axis
      xyz="1 0 0" />
    <limit
      lower="-0.523598775598299"
      upper="2.0943951023932"
      effort="120"
      velocity="12" />
  </joint>
  <link
    name="left_hip_yaw_link">
    <inertial>
      <origin
        xyz="4.47E-03 3.13E-03 -172.25E-03"
        rpy="0 0 0" />
      <mass
        value="4.48" />
      <inertia
        ixx="72804.63E-06"
        ixy="9.20E-06"
        ixz="220.63E-06"
        iyy="73647.20E-06"
        iyz="1391.21E-06"
        izz="6849.69E-06" />
    </inertial>
    <visual>
      <origin
        xyz="0 0 0"
        rpy="0 0 0" />
      <geometry>
        <mesh
          filename="../meshes/HU_D03_02/left_hip_yaw_link.STL" />
      </geometry>
      <material
        name="">
        <color
          rgba="1 1 1 1" />
      </material>
    </visual>
    <collision>
      <origin xyz="0. 0. 0." rpy="0. 0. 0."/>
      <geometry>
        <mesh filename="../meshes/HU_D03_02/left_hip_yaw_link.STL" scale="1. 1. 1."/>
      </geometry>
    </collision>
    <!--<collision>
      <origin
        xyz="0 0 0"
        rpy="0 0 0" />
      <geometry>
        <mesh
          filename="../meshes/HU_D03_02/left_hip_yaw_link.STL" />
      </geometry>
    </collision>-->
  </link>
  <joint
    name="left_hip_yaw_joint"
    type="revolute">
    <origin
      xyz="0 0 -0.0705000000000011"
      rpy="0 0 0" />
    <parent
      link="left_hip_roll_link" />
    <child
      link="left_hip_yaw_link" />
    <axis
      xyz="0 0 1" />
    <limit
      lower="-2.70526034059121"
      upper="2.70526034059121"
      effort="120"
      velocity="12" />
  </joint>
  <link
    name="left_knee_link">
    <inertial>
      <origin
        xyz="7.45E-03 7.51E-03 -136.44E-03"
        rpy="0 0 0" />
      <mass
        value="2.95" />
      <inertia
        ixx="27850.14E-06"
        ixy="86.65E-06"
        ixz="263.56E-06"
        iyy="27425.54E-06"
        iyz="-2329.92E-06"
        izz="3445.88E-06" />
    </inertial>
    <visual>
      <origin
        xyz="0 0 0"
        rpy="0 0 0" />
      <geometry>
        <mesh
          filename="../meshes/HU_D03_02/left_knee_link.STL" />
      </geometry>
      <material
        name="">
        <color
          rgba="0.666666666666667 0.698039215686274 0.768627450980392 1" />
      </material>
    </visual>
    <collision>
      <origin xyz="0.01432 0.0 -0.15368" rpy="0. 0. 0. "/>
      <geometry>
        <box size="0.07 0.08 0.18 "/>
      </geometry>
    </collision>
    <collision>
      <origin xyz="0.01528 0.00138 -0.29299" rpy="0. 0.13465 0. "/>
      <geometry>
        <box size="0.03 0.025 0.095 "/>
      </geometry>
    </collision>
    <!--<collision>
      <origin
        xyz="0 0 0"
        rpy="0 0 0" />
      <geometry>
        <mesh
          filename="../meshes/HU_D03_02/left_knee_link.STL" />
      </geometry>
    </collision>-->
  </link>
  <joint
    name="left_knee_joint"
    type="revolute">
    <origin
      xyz="0 0 -0.304499999998743"
      rpy="0 0 0" />
    <parent
      link="left_hip_yaw_link" />
    <child
      link="left_knee_link" />
    <axis
      xyz="0 1 0" />
    <limit
      lower="-0.0872664625997165"
      upper="2.58308729295161"
      effort="120"
      velocity="12" />
  </joint>
  <link
    name="left_ankle_pitch_link">
    <inertial>
      <origin
        xyz="0.15E-03 0 0.47E-03"
        rpy="0 0 0" />
      <mass
        value="0.1" />
      <inertia
        ixx="19.29E-06"
        ixy="0"
        ixz="0.01E-06"
        iyy="6.94E-06"
        iyz="0"
        izz="22.08E-06" />
    </inertial>
    <visual>
      <origin
        xyz="0 0 0"
        rpy="0 0 0" />
      <geometry>
        <mesh
          filename="../meshes/HU_D03_02/left_ankle_pitch_link.STL" />
      </geometry>
      <material
        name="">
        <color
          rgba="0.776470588235294 0.756862745098039 0.737254901960784 1" />
      </material>
    </visual>
    <!--<collision>
      <origin
        xyz="0 0 0"
        rpy="0 0 0" />
      <geometry>
        <mesh
          filename="../meshes/HU_D03_02/left_ankle_pitch_link.STL" />
      </geometry>
    </collision>-->
  </link>
  <joint
    name="left_ankle_pitch_joint"
    type="revolute">
    <origin
      xyz="0 0.0013982197557 -0.385000000001259"
      rpy="0 0 0" />
    <parent
      link="left_knee_link" />
    <child
      link="left_ankle_pitch_link" />
    <axis
      xyz="0 1 0" />
    <limit
      lower="-0.785"
      upper="0.611"
      effort="45"
      velocity="16" />
  </joint>
  <link
    name="left_ankle_roll_link">
    <inertial>
      <origin
        xyz="1.4E-03 0.13E-03 -34.98E-03"
        rpy="0 0 0" />
      <mass
        value="0.49" />
      <inertia
        ixx="942.42E-06"
        ixy="-0.26E-06"
        ixz="-17.56E-06"
        iyy="1832.87E-06"
        iyz="1.70E-06"
        izz="1545.72E-06" />
    </inertial>
    <visual>
      <origin
        xyz="0 0 0"
        rpy="0 0 0" />
      <geometry>
        <mesh
          filename="../meshes/HU_D03_02/left_ankle_roll_link.STL" />
      </geometry>
      <material
        name="">
        <color
          rgba="1 1 1 1" />
      </material>
    </visual>
    <collision>
      <origin xyz="0. 0. 0." rpy="0. 0. 0."/>
      <geometry>
        <mesh filename="../meshes/HU_D03_02/left_ankle_roll_link.STL" scale="1. 1. 1."/>
      </geometry>
    </collision>
    <!--<collision>
      <origin
        xyz="0 0 0"
        rpy="0 0 0" />
      <geometry>
        <mesh
          filename="../meshes/HU_D03_02/left_ankle_roll_link.STL" />
      </geometry>
    </collision>-->
  </link>
  <joint
    name="left_ankle_roll_joint"
    type="revolute">
    <origin
      xyz="0 0 0"
      rpy="0 0 0" />
    <parent
      link="left_ankle_pitch_link" />
    <child
      link="left_ankle_roll_link" />
    <axis
      xyz="1 0 0" />
    <limit
      lower="-0.436332312998582"
      upper="0.436332312998582"
      effort="45"
      velocity="16" />
  </joint>

  <!-- Left Foot Contact -->
  <joint name="contact_foot_center_joint_L" type="fixed">
    <origin xyz="0.001 0 -0.0635" rpy="0 0 0" />
    <parent link="left_ankle_roll_link" />
    <child link="contact_foot_center_L" />
  </joint>
  <link name="contact_foot_center_L">
    <inertial>
      <origin xyz=".0 .0 .0" rpy="0 0 0" />
      <mass value="0.001" />
      <inertia ixx="0.0000001" ixy="0.0" ixz="0.0" iyy="0.0000001" iyz="0.0" izz="0.0000001" />
    </inertial>
    <visual>
      <origin xyz="0 0 0" rpy="0 0 0" />
      <geometry>
        <box size="0.01 0.01 0.01"/>
      </geometry>
      <material name="">
        <color rgba="1 0 0 1" />
      </material>
    </visual>
  </link>

  <joint name="contact_foot_heel_joint_L" type="fixed">
    <origin xyz="-0.124 0 -0.0635" rpy="0 0 0" />
    <parent link="left_ankle_roll_link" />
    <child link="contact_foot_heel_L" />
  </joint>
  <link name="contact_foot_heel_L">
    <inertial>
      <origin xyz=".0 .0 .0" rpy="0 0 0" />
      <mass value="0.001" />
      <inertia ixx="0.0000001" ixy="0.0" ixz="0.0" iyy="0.0000001" iyz="0.0" izz="0.0000001" />
    </inertial>
    <visual>
      <origin xyz="0 0 0" rpy="0 0 0" />
      <geometry>
        <box size="0.01 0.01 0.01"/>
      </geometry>
      <material name="">
        <color rgba="1 0 0 1" />
      </material>
    </visual>
  </link>

  <joint name="contact_foot_tip_joint_L" type="fixed">
    <origin xyz="0.126 0 -0.0635" rpy="0 0 0" />
    <parent link="left_ankle_roll_link" />
    <child link="contact_foot_tip_L" />
  </joint>
  <link name="contact_foot_tip_L">
    <inertial>
      <origin xyz=".0 .0 .0" rpy="0 0 0" />
      <mass value="0.001" />
      <inertia ixx="0.0000001" ixy="0.0" ixz="0.0" iyy="0.0000001" iyz="0.0" izz="0.0000001" />
    </inertial>
    <visual>
      <origin xyz="0 0 0" rpy="0 0 0" />
      <geometry>
        <box size="0.01 0.01 0.01"/>
      </geometry>
      <material name="">
        <color rgba="1 0 0 1" />
      </material>
    </visual>
  </link>

  <!-- right leg -->
  <link
    name="right_hip_pitch_link">
    <inertial>
      <origin
        xyz="-0.5E-03 -8.73E-03 -89.61E-03"
        rpy="0 0 0" />
      <mass
        value="2.16" />
      <inertia
        ixx="3512.99E-06"
        ixy="-16.75E-06"
        ixz="-31.83E-06"
        iyy="3712.12E-06"
        iyz="7.32E-06"
        izz="2874.63E-06" />
    </inertial>
    <visual>
      <origin
        xyz="0 0 0"
        rpy="0 0 0" />
      <geometry>
        <mesh
          filename="../meshes/HU_D03_02/right_hip_pitch_link.STL" />
      </geometry>
      <material
        name="">
        <color
          rgba="0.898039215686275 0.917647058823529 0.929411764705882 1" />
      </material>
    </visual>
    <collision>
      <origin xyz="0. 0. 0." rpy="0. 0. 0."/>
      <geometry>
        <mesh filename="../meshes/HU_D03_02/right_hip_pitch_link.STL" scale="1. 1. 1."/>
      </geometry>
    </collision>
    <!--<collision>
      <origin
        xyz="0 0 0"
        rpy="0 0 0" />
      <geometry>
        <mesh
          filename="../meshes/HU_D03_02/right_hip_pitch_link.STL" />
      </geometry>
    </collision>-->
  </link>
  <joint
    name="right_hip_pitch_joint"
    type="revolute">
    <origin
      xyz="0.0100000000000003 -0.121089928152483 0.00692261826173957"
      rpy="0 0 0" />
    <parent
      link="base_link" />
    <child
      link="right_hip_pitch_link" />
    <axis
      xyz="0 0.906307787036649 0.422618261740702" />
    <limit
      lower="-3.14159265358979"
      upper="3.14159265358979"
      effort="120"
      velocity="12" />
  </joint>
  <link
    name="right_hip_roll_link">
    <inertial>
      <origin
        xyz="1.4E-03 -0.13E-03 -34.98E-03"
        rpy="0 0 0" />
      <mass
        value="0.49" />
      <inertia
        ixx="942.42E-06"
        ixy="0.26E-06"
        ixz="-17.56E-06"
        iyy="1832.87E-06"
        iyz="-1.70E-06"
        izz="1545.72E-06" />
    </inertial>
    <visual>
      <origin
        xyz="0 0 0"
        rpy="0 0 0" />
      <geometry>
        <mesh
          filename="../meshes/HU_D03_02/right_hip_roll_link.STL" />
      </geometry>
      <material
        name="">
        <color
          rgba="0.792156862745098 0.819607843137255 0.933333333333333 1" />
      </material>
    </visual>
    <!--<collision>
      <origin
        xyz="0 0 0"
        rpy="0 0 0" />
      <geometry>
        <mesh
          filename="../meshes/HU_D03_02/right_hip_roll_link.STL" />
      </geometry>
    </collision>-->
  </link>
  <joint
    name="right_hip_roll_joint"
    type="revolute">
    <origin
      xyz="-0.0100000000000004 -0.00891007184751309 -0.0954226182617506"
      rpy="0 0 0" />
    <parent
      link="right_hip_pitch_link" />
    <child
      link="right_hip_roll_link" />
    <axis
      xyz="1 0 0" />
    <limit
      lower="-2.0943951023932"
      upper="0.523598775598299"
      effort="120"
      velocity="12" />
  </joint>
  <link
    name="right_hip_yaw_link">
    <inertial>
      <origin
        xyz="4.47E-03 -3.13E-03 -172.25E-03"
        rpy="0 0 0" />
      <mass
        value="4.48" />
      <inertia
        ixx="72804.63E-06"
        ixy="-9.20E-06"
        ixz="220.63E-06"
        iyy="73647.20E-06"
        iyz="-1391.21E-06"
        izz="6849.69E-06" />
    </inertial>
    <visual>
      <origin
        xyz="0 0 0"
        rpy="0 0 0" />
      <geometry>
        <mesh
          filename="../meshes/HU_D03_02/right_hip_yaw_link.STL" />
      </geometry>
      <material
        name="">
        <color
          rgba="0.498039215686275 0.498039215686275 0.498039215686275 1" />
      </material>
    </visual>
    <collision>
      <origin xyz="0. 0. 0." rpy="0. 0. 0."/>
      <geometry>
        <mesh filename="../meshes/HU_D03_02/right_hip_yaw_link.STL" scale="1. 1. 1."/>
      </geometry>
    </collision>
    <!--<collision>
      <origin
        xyz="0 0 0"
        rpy="0 0 0" />
      <geometry>
        <mesh
          filename="../meshes/HU_D03_02/right_hip_yaw_link.STL" />
      </geometry>
    </collision>-->
  </link>
  <joint
    name="right_hip_yaw_joint"
    type="revolute">
    <origin
      xyz="0 0 -0.0705000000000018"
      rpy="0 0 0" />
    <parent
      link="right_hip_roll_link" />
    <child
      link="right_hip_yaw_link" />
    <axis
      xyz="0 0 1" />
    <limit
      lower="-2.70526034059121"
      upper="2.70526034059121"
      effort="120"
      velocity="12" />
  </joint>
  <link
    name="right_knee_link">
    <inertial>
      <origin
        xyz="7.45E-03 -7.51E-03 -136.44E-03"
        rpy="0 0 0" />
      <mass
        value="2.95" />
      <inertia
        ixx="27850.14E-06"
        ixy="-86.65E-06"
        ixz="263.56E-06"
        iyy="27425.54E-06"
        iyz="2329.92E-06"
        izz="3445.88E-06" />
    </inertial>
    <visual>
      <origin
        xyz="0 0 0"
        rpy="0 0 0" />
      <geometry>
        <mesh
          filename="../meshes/HU_D03_02/right_knee_link.STL" />
      </geometry>
      <material
        name="">
        <color
          rgba="0.792156862745098 0.819607843137255 0.933333333333333 1" />
      </material>
    </visual>
    <collision>
      <origin xyz="0.01432 0.0 -0.15368" rpy="0. 0. 0. "/>
      <geometry>
        <box size="0.07 0.08 0.18 "/>
      </geometry>
    </collision>
    <collision>
      <origin xyz="0.01528 -0.00138 -0.29299" rpy="0. 0.13465 0. "/>
      <geometry>
        <box size="0.03 0.025 0.095 "/>
      </geometry>
    </collision>
    <!--<collision>
      <origin
        xyz="0 0 0"
        rpy="0 0 0" />
      <geometry>
        <mesh
          filename="../meshes/HU_D03_02/right_knee_link.STL" />
      </geometry>
    </collision>-->
  </link>
  <joint
    name="right_knee_joint"
    type="revolute">
    <origin
      xyz="0 0 -0.304499999999999"
      rpy="0 0 0" />
    <parent
      link="right_hip_yaw_link" />
    <child
      link="right_knee_link" />
    <axis
      xyz="0 1 0" />
    <limit
      lower="-0.0872664625997165"
      upper="2.58308729295161"
      effort="120"
      velocity="12" />
  </joint>
  <link
    name="right_ankle_pitch_link">
    <inertial>
      <origin
        xyz="0.15E-03 0 0.47E-03"
        rpy="0 0 0" />
      <mass
        value="0.10" />
      <inertia
        ixx="19.29E-06"
        ixy="0"
        ixz="0.01E-06"
        iyy="6.94E-06"
        iyz="0"
        izz="22.08E-06" />
    </inertial>
    <visual>
      <origin
        xyz="0 0 0"
        rpy="0 0 0" />
      <geometry>
        <mesh
          filename="../meshes/HU_D03_02/right_ankle_pitch_link.STL" />
      </geometry>
      <material
        name="">
        <color
          rgba="0.776470588235294 0.756862745098039 0.737254901960784 1" />
      </material>
    </visual>
    <!--<collision>
      <origin
        xyz="0 0 0"
        rpy="0 0 0" />
      <geometry>
        <mesh
          filename="../meshes/HU_D03_02/right_ankle_pitch_link.STL" />
      </geometry>
    </collision>-->
  </link>
  <joint
    name="right_ankle_pitch_joint"
    type="revolute">
    <origin
      xyz="0 -0.0013982197557 -0.385000000000011"
      rpy="0 0 0" />
    <parent
      link="right_knee_link" />
    <child
      link="right_ankle_pitch_link" />
    <axis
      xyz="0 1 0" />
    <limit
      lower="-0.785"
      upper="0.611"
      effort="45"
      velocity="16" />
  </joint>
  <link
    name="right_ankle_roll_link">
    <inertial>
      <origin
        xyz="-7.17E-03 0 -35.09E-03"
        rpy="0 0 0" />
      <mass
        value="0.88" />
      <inertia
        ixx="671.32E-06"
        ixy="-0.02E-06"
        ixz="164.80E-06"
        iyy="3158.27E-06"
        iyz="0"
        izz="3252.60E-06" />
    </inertial>
    <visual>
      <origin
        xyz="0 0 0"
        rpy="0 0 0" />
      <geometry>
        <mesh
          filename="../meshes/HU_D03_02/right_ankle_roll_link.STL" />
      </geometry>
      <material
        name="">
        <color
          rgba="0.776470588235294 0.756862745098039 0.737254901960784 1" />
      </material>
    </visual>
    <collision>
      <origin xyz="0. 0. 0." rpy="0. 0. 0."/>
      <geometry>
        <mesh filename="../meshes/HU_D03_02/right_ankle_roll_link.STL" scale="1. 1. 1."/>
      </geometry>
    </collision>
    <!--<collision>
      <origin
        xyz="0 0 0"
        rpy="0 0 0" />
      <geometry>
        <mesh
          filename="../meshes/HU_D03_02/right_ankle_roll_link.STL" />
      </geometry>
    </collision>-->
  </link>
  <joint
    name="right_ankle_roll_joint"
    type="revolute">
    <origin
      xyz="0 0 0"
      rpy="0 0 0" />
    <parent
      link="right_ankle_pitch_link" />
    <child
      link="right_ankle_roll_link" />
    <axis
      xyz="1 0 0" />
    <limit
      lower="-0.436332312998582"
      upper="0.436332312998582"
      effort="45"
      velocity="16" />
  </joint>

  <!-- Right Foot Contact -->
  <joint name="contact_foot_center_joint_R" type="fixed">
    <origin xyz="0.001 0 -0.0635" rpy="0 0 0" />
    <parent link="right_ankle_roll_link" />
    <child link="contact_foot_center_R" />
  </joint>
  <link name="contact_foot_center_R">
    <inertial>
      <origin xyz=".0 .0 .0" rpy="0 0 0" />
      <mass value="0.001" />
      <inertia ixx="0.0000001" ixy="0.0" ixz="0.0" iyy="0.0000001" iyz="0.0" izz="0.0000001" />
    </inertial>
    <visual>
      <origin xyz="0 0 0" rpy="0 0 0" />
      <geometry>
        <box size="0.01 0.01 0.01"/>
      </geometry>
      <material name="">
        <color rgba="1 0 0 1" />
      </material>
    </visual>
  </link>

  <joint name="contact_foot_heel_joint_R" type="fixed">
    <origin xyz="-0.124 0 -0.0635" rpy="0 0 0" />
    <parent link="right_ankle_roll_link" />
    <child link="contact_foot_heel_R" />
  </joint>
  <link name="contact_foot_heel_R">
    <inertial>
      <origin xyz=".0 .0 .0" rpy="0 0 0" />
      <mass value="0.001" />
      <inertia ixx="0.0000001" ixy="0.0" ixz="0.0" iyy="0.0000001" iyz="0.0" izz="0.0000001" />
    </inertial>
    <visual>
      <origin xyz="0 0 0" rpy="0 0 0" />
      <geometry>
        <box size="0.01 0.01 0.01"/>
      </geometry>
      <material name="">
        <color rgba="1 0 0 1" />
      </material>
    </visual>
  </link>

  <joint name="contact_foot_tip_joint_R" type="fixed">
    <origin xyz="0.126 0 -0.0635" rpy="0 0 0" />
    <parent link="right_ankle_roll_link" />
    <child link="contact_foot_tip_R" />
  </joint>
  <link name="contact_foot_tip_R">
    <inertial>
      <origin xyz=".0 .0 .0" rpy="0 0 0" />
      <mass value="0.001" />
      <inertia ixx="0.0000001" ixy="0.0" ixz="0.0" iyy="0.0000001" iyz="0.0" izz="0.0000001" />
    </inertial>
    <visual>
      <origin xyz="0 0 0" rpy="0 0 0" />
      <geometry>
        <box size="0.01 0.01 0.01"/>
      </geometry>
      <material name="">
        <color rgba="1 0 0 1" />
      </material>
    </visual>
  </link>

  <!-- waist -->
  <link
    name="waist_yaw_link">
    <inertial>
      <origin
        xyz="15.10E-03 0.07E-03 26.61E-03"
        rpy="0 0 0" />
      <mass
        value="0.86" />
      <inertia
        ixx="929.27E-06"
        ixy="7.64E-06"
        ixz="-116.33E-06"
        iyy="1496.78E-06"
        iyz="-4.64E-06"
        izz="1372.67E-06" />
    </inertial>
    <visual>
      <origin
        xyz="0 0 0"
        rpy="0 0 0" />
      <geometry>
        <mesh
          filename="../meshes/HU_D03_02/waist_yaw_link.STL" />
      </geometry>
      <material
        name="">
        <color
          rgba="0.898039215686275 0.917647058823529 0.929411764705882 1" />
      </material>
    </visual>
    <!--<collision>
      <origin
        xyz="0 0 0"
        rpy="0 0 0" />
      <geometry>
        <mesh
          filename="../meshes/HU_D03_02/waist_yaw_link.STL" />
      </geometry>
    </collision>-->
  </link>
  <joint
    name="waist_yaw_joint"
    type="revolute">
    <origin
      xyz="0 0 0.0925000000000001"
      rpy="0 0 0" />
    <parent
      link="base_link" />
    <child
      link="waist_yaw_link" />
    <axis
      xyz="0 0 1" />
    <limit
      lower="-2.61799387799149"
      upper="2.61799387799149"
      effort="45"
      velocity="16" />
  </joint>
  <link
    name="waist_roll_link">
    <inertial>
      <origin
        xyz="-0.16E-03 0.08E-03 -0.09E-03"
        rpy="0 0 0" />
      <mass
        value="0.46" />
      <inertia
        ixx="222.64E-06"
        ixy="-0.01E-06"
        ixz="0.01E-06"
        iyy="117.04E-06"
        iyz="0"
        izz="289.21E-06" />
    </inertial>
    <!--inertial>
      <origin
        xyz="0.24E-03 0.08E-03 -0.09E-03"
        rpy="0 0 0" />
      <mass
        value="0.46" />
      <inertia
        ixx="222.64E-06"
        ixy="0.01"
        ixz="-0.05"
        iyy="117.04E-06"
        iyz="0"
        izz="289.21E-06" />
    </inertial-->
    <visual>
      <origin
        xyz="0 0 0"
        rpy="0 0 0" />
      <geometry>
        <mesh
          filename="../meshes/HU_D03_02/waist_roll_link.STL" />
      </geometry>
      <material
        name="">
        <color
          rgba="0.776470588235294 0.756862745098039 0.737254901960784 1" />
      </material>
    </visual>
    <!--<collision>
      <origin
        xyz="0 0 0"
        rpy="0 0 0" />
      <geometry>
        <mesh
          filename="../meshes/HU_D03_02/waist_roll_link.STL" />
      </geometry>
    </collision>-->
  </link>
  <joint
    name="waist_roll_joint"
    type="revolute">
    <origin
      xyz="0 0 0.062"
      rpy="0 0 0" />
    <parent
      link="waist_yaw_link" />
    <child
      link="waist_roll_link" />
    <axis
      xyz="1 0 0" />
    <limit
      lower="-0.523598775598299"
      upper="0.523598775598299"
      effort="45"
      velocity="16" />
  </joint>
  <link
    name="waist_pitch_link">
    <inertial>
      <origin
        xyz="-10.35E-03 0.53E-03 201.70E-03"
        rpy="0 0 0" />
      <mass
        value="10.96" />
      <inertia
        ixx="168599.35E-06"
        ixy="58.05E-06"
        ixz="8975.03E-06"
        iyy="132952.81E-06"
        iyz="-368.29E-06"
        izz="90027.22E-06" />
    </inertial>
    <visual>
      <origin
        xyz="0 0 0"
        rpy="0 0 0" />
      <geometry>
        <mesh
          filename="../meshes/HU_D03_02/waist_pitch_link.STL" />
      </geometry>
      <material
        name="">
        <color
          rgba="0.898039215686275 0.92156862745098 0.929411764705882 1" />
      </material>
    </visual>
    <collision>
      <origin xyz="0. 0. 0." rpy="0. 0. 0."/>
      <geometry>
        <mesh filename="../meshes/HU_D03_02/waist_pitch_link.STL" scale="1. 1. 1."/>
      </geometry>
    </collision>
    <!--<collision>
      <origin
        xyz="0 0 0"
        rpy="0 0 0" />
      <geometry>
        <mesh
          filename="../meshes/HU_D03_02/waist_pitch_link.STL" />
      </geometry>
    </collision>-->
  </link>
  <joint
    name="waist_pitch_joint"
    type="revolute">
    <origin
      xyz="0 0 0"
      rpy="0 0 0" />
    <parent
      link="waist_roll_link" />
    <child
      link="waist_pitch_link" />
    <axis
      xyz="0 1 0" />
    <limit
      lower="-0.523598775598299"
      upper="0.523598775598299"
      effort="45"
      velocity="16" />
  </joint>

  <link
    name="left_shoulder_pitch_link">
    <inertial>
      <origin
        xyz="4.75E-03 24.22E-03 -0.34E-03"
        rpy="0 0 0" />
      <mass
        value="0.18" />
      <inertia
        ixx="195.93E-06"
        ixy="-28.87E-06"
        ixz="0"
        iyy="218.99E-06"
        iyz="0.01E-06"
        izz="282.66E-06" />
    </inertial>
    <visual>
      <origin
        xyz="0 0 0"
        rpy="0 0 0" />
      <geometry>
        <mesh
          filename="../meshes/HU_D03_02/left_shoulder_pitch_link.STL" />
      </geometry>
      <material
        name="">
        <color
          rgba="0.898039215686275 0.917647058823529 0.929411764705882 1" />
      </material>
    </visual>
    <!--<collision>
      <origin
        xyz="0 0 0"
        rpy="0 0 0" />
      <geometry>
        <mesh
          filename="../meshes/HU_D03_02/left_shoulder_pitch_link.STL" />
      </geometry>
    </collision>-->
  </link>
  <joint
    name="left_shoulder_pitch_joint"
    type="revolute">
    <origin
      xyz="0 0.1575 0.282199999999999"
      rpy="0 0 0" />
    <parent
      link="waist_pitch_link" />
    <child
      link="left_shoulder_pitch_link" />
    <axis
      xyz="0 1 0" />
    <limit
      lower="-2.79252680319093"
      upper="2.79252680319093"
      effort="30"
      velocity="20" />
  </joint>
  <link
    name="left_shoulder_roll_link">
    <inertial>
      <origin
        xyz="3.51E-03 -2.09E-03 -43.67E-03"
        rpy="0 0 0" />
      <mass
        value="1.84" />
      <inertia
        ixx="5383.77E-06"
        ixy="-17.24E-06"
        ixz="-297.15E-06"
        iyy="5314.04E-06"
        iyz="169.64E-06"
        izz="1649.72E-06" />
    </inertial>
    <visual>
      <origin
        xyz="0 0 0"
        rpy="0 0 0" />
      <geometry>
        <mesh
          filename="../meshes/HU_D03_02/left_shoulder_roll_link.STL" />
      </geometry>
      <material
        name="">
        <color
          rgba="0.792156862745098 0.819607843137255 0.933333333333333 1" />
      </material>
    </visual>
    <collision>
      <origin xyz="0. 0. 0." rpy="0. 0. 0."/>
      <geometry>
        <mesh filename="../meshes/HU_D03_02/left_shoulder_roll_link.STL" scale="1. 1. 1."/>
      </geometry>
    </collision>
    <!--<collision>
      <origin
        xyz="0 0 0"
        rpy="0 0 0" />
      <geometry>
        <mesh
          filename="../meshes/HU_D03_02/left_shoulder_roll_link.STL" />
      </geometry>
    </collision>-->
  </link>
  <joint
    name="left_shoulder_roll_joint"
    type="revolute">
    <origin
      xyz="0 0.055 0"
      rpy="0 0 0" />
    <parent
      link="left_shoulder_pitch_link" />
    <child
      link="left_shoulder_roll_link" />
    <axis
      xyz="1 0 0" />
    <limit
      lower="-0.0872664625997165"
      upper="3.22885911618951"
      effort="30"
      velocity="20" />
  </joint>
  <link
    name="left_shoulder_yaw_link">
    <inertial>
      <origin
        xyz="-9.39E-03 4.12E-03 -60.99E-03"
        rpy="0 0 0" />
      <mass
        value="0.27" />
      <inertia
        ixx="740.56E-06"
        ixy="-8.72E-06"
        ixz="-16.80E-06"
        iyy="653.45E-06"
        iyz="52.31E-06"
        izz="332.02E-06" />
    </inertial>
    <visual>
      <origin
        xyz="0 0 0"
        rpy="0 0 0" />
      <geometry>
        <mesh
          filename="../meshes/HU_D03_02/left_shoulder_yaw_link.STL" />
      </geometry>
      <material
        name="">
        <color
          rgba="0.898039215686275 0.917647058823529 0.929411764705882 1" />
      </material>
    </visual>
    <collision>
      <origin xyz="0. 0. 0." rpy="0. 0. 0."/>
      <geometry>
        <mesh filename="../meshes/HU_D03_02/left_shoulder_yaw_link.STL" scale="1. 1. 1."/>
      </geometry>
    </collision>
    <!--<collision>
      <origin
        xyz="0 0 0"
        rpy="0 0 0" />
      <geometry>
        <mesh
          filename="../meshes/HU_D03_02/left_shoulder_yaw_link.STL" />
      </geometry>
    </collision>-->
  </link>
  <joint
    name="left_shoulder_yaw_joint"
    type="revolute">
    <origin
      xyz="0 0 -0.130599999999999"
      rpy="0 0 0" />
    <parent
      link="left_shoulder_roll_link" />
    <child
      link="left_shoulder_yaw_link" />
    <axis
      xyz="0 0 1" />
    <limit
      lower="-1.5707963267949"
      upper="1.5707963267949"
      effort="30"
      velocity="20" />
  </joint>
  <link
    name="left_elbow_link">
    <inertial>
      <origin
        xyz="0.09E-03 5.10E-03 -25.53E-03"
        rpy="0 0 0" />
      <mass
        value="1.20" />
      <inertia
        ixx="2405.34E-06"
        ixy="2.58E-06"
        ixz="-1.81E-06"
        iyy="2451.07E-06"
        iyz="-132.29E-06"
        izz="816.85E-06" />
    </inertial>
    <visual>
      <origin
        xyz="0 0 0"
        rpy="0 0 0" />
      <geometry>
        <mesh
          filename="../meshes/HU_D03_02/left_elbow_link.STL" />
      </geometry>
      <material
        name="">
        <color
          rgba="0.792156862745098 0.819607843137255 0.933333333333333 1" />
      </material>
    </visual>
    <collision>
      <origin xyz="0. 0. 0." rpy="0. 0. 0."/>
      <geometry>
        <mesh filename="../meshes/HU_D03_02/left_elbow_link.STL" scale="1. 1. 1."/>
      </geometry>
    </collision>
    <!--<collision>
      <origin
        xyz="0 0 0"
        rpy="0 0 0" />
      <geometry>
        <mesh
          filename="../meshes/HU_D03_02/left_elbow_link.STL" />
      </geometry>
    </collision>-->
  </link>
  <joint
    name="left_elbow_joint"
    type="revolute">
    <origin
      xyz="0 0 -0.115699999999999"
      rpy="0 0 0" />
    <parent
      link="left_shoulder_yaw_link" />
    <child
      link="left_elbow_link" />
    <axis
      xyz="0 1 0" />
    <limit
      lower="-2.0943951023932"
      upper="1.0471975511966"
      effort="30"
      velocity="20" />
  </joint>
  <link
    name="left_wrist_yaw_link">
    <inertial>
      <origin
        xyz="0 0.32E-03 -10.30E-03"
        rpy="0 0 0" />
      <mass
        value="0.07" />
      <inertia
        ixx="53.83E-06"
        ixy="0"
        ixz="0.01E-06"
        iyy="32E-06"
        iyz="-0.49E-06"
        izz="54.05E-06" />
    </inertial>
    <visual>
      <origin
        xyz="0 0 0"
        rpy="0 0 0" />
      <geometry>
        <mesh
          filename="../meshes/HU_D03_02/left_wrist_yaw_link.STL" />
      </geometry>
      <material
        name="">
        <color
          rgba="0.898039215686275 0.917647058823529 0.929411764705882 1" />
      </material>
    </visual>
    <!--<collision>
      <origin
        xyz="0 0 0"
        rpy="0 0 0" />
      <geometry>
        <mesh
          filename="../meshes/HU_D03_02/left_wrist_yaw_link.STL" />
      </geometry>
    </collision>-->
  </link>
  <joint
    name="left_wrist_yaw_joint"
    type="revolute">
    <origin
      xyz="0 0 -0.1048"
      rpy="0 0 0" />
    <parent
      link="left_elbow_link" />
    <child
      link="left_wrist_yaw_link" />
    <axis
      xyz="0 0 1" />
    <limit
      lower="-1.5707963267949"
      upper="1.5707963267949"
      effort="18"
      velocity="14" />
  </joint>
  <link
    name="left_wrist_pitch_link">
    <inertial>
      <origin
        xyz="1.25E-03 2.72E-03 -65.60E-03"
        rpy="0 0 0" />
      <mass
        value="0.62" />
      <inertia
        ixx="860.54E-06"
        ixy="2.18E-06"
        ixz="24.00E-06"
        iyy="884.66E-06"
        iyz="-56.17E-06"
        izz="301.32E-06" />
    </inertial>
    <visual>
      <origin
        xyz="0 0 0"
        rpy="0 0 0" />
      <geometry>
        <mesh
          filename="../meshes/HU_D03_02/left_wrist_pitch_link.STL" />
      </geometry>
      <material
        name="">
        <color
          rgba="0.898039215686275 0.917647058823529 0.929411764705882 1" />
      </material>
    </visual>
    <collision>
      <origin xyz="0.0 0.0 -0.03331" rpy="0. 0. 0. "/>
      <geometry>
        <box size="0.042 0.042 0.09543 "/>
      </geometry>
    </collision>
    <!-- <collision>
      <origin xyz="0.05236 0.0 -0.0675" rpy="0. 0. 0. "/>
      <geometry>
        <box size="0.042 0.042 0.03 "/>
      </geometry>
    </collision> -->
    <!--<collision>
      <origin
        xyz="0 0 0"
        rpy="0 0 0" />
      <geometry>
        <mesh
          filename="../meshes/HU_D03_02/left_wrist_pitch_link.STL" />
      </geometry>
    </collision>-->
  </link>
  <joint
    name="left_wrist_pitch_joint"
    type="revolute">
    <origin
      xyz="0 0 -0.0315000000000003"
      rpy="0 0 0" />
    <parent
      link="left_wrist_yaw_link" />
    <child
      link="left_wrist_pitch_link" />
    <axis
      xyz="0 1 0" />
    <limit
      lower="-1.5707963267949"
      upper="1.5707963267949"
      effort="18"
      velocity="14" />
  </joint>
  <link
    name="left_hand_yaw_link">
    <inertial>
      <origin
        xyz="0 -0.01E-03 -54.74E-03"
        rpy="0 0 0" />
      <mass
        value="0.24" />
      <inertia
        ixx="495.34E-06"
        ixy="0.01E-06"
        ixz="0.02E-06"
        iyy="391.26E-06"
        iyz="0.09E-06"
        izz="131.39E-06" />
    </inertial>
    <visual>
      <origin
        xyz="0 0 0"
        rpy="0 0 0" />
      <geometry>
        <mesh
          filename="../meshes/HU_D03_02/left_hand_yaw_link.STL" />
      </geometry>
      <material
        name="">
        <color
          rgba="0.792156862745098 0.819607843137255 0.933333333333333 1" />
      </material>
    </visual>
    <collision>
      <origin xyz="0. 0. 0." rpy="0. 0. 0."/>
      <geometry>
        <mesh filename="../meshes/HU_D03_02/left_hand_yaw_link.STL" scale="1. 1. 1."/>
      </geometry>
    </collision>
    <!--<collision>
      <origin
        xyz="0 0 0"
        rpy="0 0 0" />
      <geometry>
        <mesh
          filename="../meshes/HU_D03_02/left_hand_yaw_link.STL" />
      </geometry>
    </collision>-->
  </link>
  <joint
    name="left_hand_yaw_joint"
    type="revolute">
    <origin
      xyz="0 0 -0.0844999999999993"
      rpy="0 0 0" />
    <parent
      link="left_wrist_pitch_link" />
    <child
      link="left_hand_yaw_link" />
    <axis
      xyz="0 0 1" />
    <limit
      lower="-3.14159265358979"
      upper="3.14159265358979"
      effort="18"
      velocity="14" />
  </joint>

  <!-- Left hand Contact -->
  <joint name="left_hand_contact_joint" type="fixed">
    <origin xyz="0 0 0" rpy="0 0 0" />
    <parent link="left_hand_yaw_link" />
    <child link="left_hand_contact" />
  </joint>
  <link name="left_hand_contact">
    <inertial>
      <origin xyz=".0 .0 .0" rpy="0 0 0" />
      <mass value="0.001" />
      <inertia 
        ixx="0.0000001" 
        ixy="0.0" 
        ixz="0.0" 
        iyy="0.0000001" 
        iyz="0.0" 
        izz="0.0000001" />
    </inertial>
    <visual>
      <origin xyz="0 0 0" rpy="0 0 0" />
      <geometry>
        <box size="0.01 0.01 0.01"/>
      </geometry>
      <material name="">
        <color rgba="1 0 0 1" />
      </material>
    </visual>
  </link>

  <link
    name="right_shoulder_pitch_link">
    <inertial>
      <origin
        xyz="4.75E-03 -24.22E-03 -0.34E-03"
        rpy="0 0 0" />
      <mass
        value="0.18" />
      <inertia
        ixx="195.93E-06"
        ixy="28.87E-06"
        ixz="0"
        iyy="218.99E-06"
        iyz=" -0.01E-06"
        izz="282.66E-06" />
    </inertial>
    <visual>
      <origin
        xyz="0 0 0"
        rpy="0 0 0" />
      <geometry>
        <mesh
          filename="../meshes/HU_D03_02/right_shoulder_pitch_link.STL" />
      </geometry>
      <material
        name="">
        <color
          rgba="0.898039215686275 0.917647058823529 0.929411764705882 1" />
      </material>
    </visual>
    <!--<collision>
      <origin
        xyz="0 0 0"
        rpy="0 0 0" />
      <geometry>
        <mesh
          filename="../meshes/HU_D03_02/right_shoulder_pitch_link.STL" />
      </geometry>
    </collision>-->
  </link>
  <joint
    name="right_shoulder_pitch_joint"
    type="revolute">
    <origin
      xyz="0 -0.1575 0.2822"
      rpy="0 0 0" />
    <parent
      link="waist_pitch_link" />
    <child
      link="right_shoulder_pitch_link" />
    <axis
      xyz="0 1 0" />
    <limit
      lower="-2.79252680319093"
      upper="2.79252680319093"
      effort="30"
      velocity="20" />
  </joint>
  <link
    name="right_shoulder_roll_link">
    <inertial>
      <origin
        xyz="3.51E-03 2.09E-03 -43.67E-03"
        rpy="0 0 0" />
      <mass
        value="1.84" />
      <inertia
        ixx="5383.77E-06"
        ixy="17.24E-06"
        ixz="-297.15E-06"
        iyy="5314.04E-06"
        iyz="-169.64E-06"
        izz="1649.72E-06" />
    </inertial>
    <visual>
      <origin
        xyz="0 0 0"
        rpy="0 0 0" />
      <geometry>
        <mesh
          filename="../meshes/HU_D03_02/right_shoulder_roll_link.STL" />
      </geometry>
      <material
        name="">
        <color
          rgba="0.698039215686274 0.698039215686274 0.698039215686274 1" />
      </material>
    </visual>
    <collision>
      <origin xyz="0. 0. 0." rpy="0. 0. 0."/>
      <geometry>
        <mesh filename="../meshes/HU_D03_02/right_shoulder_roll_link.STL" scale="1. 1. 1."/>
      </geometry>
    </collision>
    <!--<collision>
      <origin
        xyz="0 0 0"
        rpy="0 0 0" />
      <geometry>
        <mesh
          filename="../meshes/HU_D03_02/right_shoulder_roll_link.STL" />
      </geometry>
    </collision>-->
  </link>
  <joint
    name="right_shoulder_roll_joint"
    type="revolute">
    <origin
      xyz="0 -0.055 0"
      rpy="0 0 0" />
    <parent
      link="right_shoulder_pitch_link" />
    <child
      link="right_shoulder_roll_link" />
    <axis
      xyz="1 0 0" />
    <limit
      lower="-3.22885911618951"
      upper="0.0872664625997165"
      effort="30"
      velocity="20" />
  </joint>
  <link
    name="right_shoulder_yaw_link">
    <inertial>
      <origin
        xyz="-9.39E-03 -4.12E-03 -60.99E-03"
        rpy="0 0 0" />
      <mass
        value="0.27" />
      <inertia
        ixx="740.56E-06"
        ixy="8.72E-06"
        ixz="-16.80E-06"
        iyy="653.45E-06"
        iyz="-52.31E-06"
        izz="332.02E-06" />
    </inertial>
    <visual>
      <origin
        xyz="0 0 0"
        rpy="0 0 0" />
      <geometry>
        <mesh
          filename="../meshes/HU_D03_02/right_shoulder_yaw_link.STL" />
      </geometry>
      <material
        name="">
        <color
          rgba="0.898039215686275 0.917647058823529 0.929411764705882 1" />
      </material>
    </visual>
    <collision>
      <origin xyz="0. 0. 0." rpy="0. 0. 0."/>
      <geometry>
        <mesh filename="../meshes/HU_D03_02/right_shoulder_yaw_link.STL" scale="1. 1. 1."/>
      </geometry>
    </collision>
    <!--<collision>
      <origin
        xyz="0 0 0"
        rpy="0 0 0" />
      <geometry>
        <mesh
          filename="../meshes/HU_D03_02/right_shoulder_yaw_link.STL" />
      </geometry>
    </collision>-->
  </link>
  <joint
    name="right_shoulder_yaw_joint"
    type="revolute">
    <origin
      xyz="0 0 -0.130599999999999"
      rpy="0 0 0" />
    <parent
      link="right_shoulder_roll_link" />
    <child
      link="right_shoulder_yaw_link" />
    <axis
      xyz="0 0 1" />
    <limit
      lower="-1.5707963267949"
      upper="1.5707963267949"
      effort="30"
      velocity="20" />
  </joint>
  <link
    name="right_elbow_link">
    <inertial>
      <origin
        xyz="0.09E-03 -5.10E-03 -25.53E-03"
        rpy="0 0 0" />
      <mass
        value="1.20" />
      <inertia
        ixx="2405.34E-06"
        ixy="-2.58E-06"
        ixz="-1.81E-06"
        iyy="2451.07E-06"
        iyz="132.29E-06"
        izz="816.85E-06" />
    </inertial>
    <visual>
      <origin
        xyz="0 0 0"
        rpy="0 0 0" />
      <geometry>
        <mesh
          filename="../meshes/HU_D03_02/right_elbow_link.STL" />
      </geometry>
      <material
        name="">
        <color
          rgba="0.792156862745098 0.819607843137255 0.933333333333333 1" />
      </material>
    </visual>
    <collision>
      <origin xyz="0. 0. 0." rpy="0. 0. 0."/>
      <geometry>
        <mesh filename="../meshes/HU_D03_02/right_elbow_link.STL" scale="1. 1. 1."/>
      </geometry>
    </collision>
    <!--<collision>
      <origin
        xyz="0 0 0"
        rpy="0 0 0" />
      <geometry>
        <mesh
          filename="../meshes/HU_D03_02/right_elbow_link.STL" />
      </geometry>
    </collision>-->
  </link>
  <joint
    name="right_elbow_joint"
    type="revolute">
    <origin
      xyz="0 0 -0.115699999999999"
      rpy="0 0 0" />
    <parent
      link="right_shoulder_yaw_link" />
    <child
      link="right_elbow_link" />
    <axis
      xyz="0 1 0" />
    <limit
      lower="-2.0943951023932"
      upper="1.0471975511966"
      effort="30"
      velocity="20" />
  </joint>
  <link
    name="right_wrist_yaw_link">
    <inertial>
      <origin
        xyz="0 -0.32E-03 -10.30E-03"
        rpy="0 0 0" />
      <mass
        value="0.07" />
      <inertia
        ixx="53.83E-06"
        ixy="0"
        ixz="0.01E-06"
        iyy="32E-06"
        iyz="0.49E-06"
        izz="54.05E-06" />
    </inertial>
    <visual>
      <origin
        xyz="0 0 0"
        rpy="0 0 0" />
      <geometry>
        <mesh
          filename="../meshes/HU_D03_02/right_wrist_yaw_link.STL" />
      </geometry>
      <material
        name="">
        <color
          rgba="0.898039215686275 0.917647058823529 0.929411764705882 1" />
      </material>
    </visual>
    <!--<collision>
      <origin
        xyz="0 0 0"
        rpy="0 0 0" />
      <geometry>
        <mesh
          filename="../meshes/HU_D03_02/right_wrist_yaw_link.STL" />
      </geometry>
    </collision>-->
  </link>
  <joint
    name="right_wrist_yaw_joint"
    type="revolute">
    <origin
      xyz="0 0 -0.104800000000001"
      rpy="0 0 0" />
    <parent
      link="right_elbow_link" />
    <child
      link="right_wrist_yaw_link" />
    <axis
      xyz="0 0 1" />
    <limit
      lower="-1.5707963267949"
      upper="1.5707963267949"
      effort="18"
      velocity="14" />
  </joint>
  <link
    name="right_wrist_pitch_link">
    <inertial>
      <origin
        xyz="1.25E-03 -2.72E-03 -65.60E-03"
        rpy="0 0 0" />
      <mass
        value="0.62" />
      <inertia
        ixx="860.54E-06"
        ixy="-2.18E-06"
        ixz="24.00E-06"
        iyy="884.66E-06"
        iyz="56.17E-06"
        izz="301.32E-06" />
    </inertial>
    <visual>
      <origin
        xyz="0 0 0"
        rpy="0 0 0" />
      <geometry>
        <mesh
          filename="../meshes/HU_D03_02/right_wrist_pitch_link.STL" />
      </geometry>
      <material
        name="">
        <color
          rgba="1 1 1 1" />
      </material>
    </visual>
    <collision>
      <origin xyz="0.0 0.0 -0.03331" rpy="0. 0. 0. "/>
      <geometry>
        <box size="0.042 0.042 0.09543 "/>
      </geometry>
    </collision>
    <!-- <collision>
      <origin xyz="0.05236 0.0 -0.0675" rpy="0. 0. 0. "/>
      <geometry>
        <box size="0.042 0.042 0.03 "/>
      </geometry>
    </collision> -->
    <!--<collision>
      <origin
        xyz="0 0 0"
        rpy="0 0 0" />
      <geometry>
        <mesh
          filename="../meshes/HU_D03_02/right_wrist_pitch_link.STL" />
      </geometry>
    </collision>-->
  </link>
  <joint
    name="right_wrist_pitch_joint"
    type="revolute">
    <origin
      xyz="0 0 -0.0315000000000004"
      rpy="0 0 0" />
    <parent
      link="right_wrist_yaw_link" />
    <child
      link="right_wrist_pitch_link" />
    <axis
      xyz="0 1 0" />
    <limit
      lower="-1.5707963267949"
      upper="1.5707963267949"
      effort="18"
      velocity="14" />
  </joint>
  <link
    name="right_hand_yaw_link">
    <inertial>
      <origin
        xyz="0 0.01E-03 -54.74E-03"
        rpy="0 0 0" />
      <mass
        value="0.24" />
      <inertia
        ixx="495.34E-06"
        ixy="-0.01E-06"
        ixz="0.02E-06"
        iyy="391.26E-06"
        iyz="-0.09E-06"
        izz="131.39E-06" />
    </inertial>
    <visual>
      <origin
        xyz="0 0 0"
        rpy="0 0 0" />
      <geometry>
        <mesh
          filename="../meshes/HU_D03_02/right_hand_yaw_link.STL" />
      </geometry>
      <material
        name="">
        <color
          rgba="0.792156862745098 0.819607843137255 0.933333333333333 1" />
      </material>
    </visual>
    <collision>
      <origin xyz="0. 0. 0." rpy="0. 0. 0."/>
      <geometry>
        <mesh filename="../meshes/HU_D03_02/right_hand_yaw_link.STL" scale="1. 1. 1."/>
      </geometry>
    </collision>
    <!--<collision>
      <origin
        xyz="0 0 0"
        rpy="0 0 0" />
      <geometry>
        <mesh
          filename="../meshes/HU_D03_02/right_hand_yaw_link.STL" />
      </geometry>
    </collision>-->
  </link>
  <joint
    name="right_hand_yaw_joint"
    type="revolute">
    <origin
      xyz="0 0 -0.0845"
      rpy="0 0 0" />
    <parent
      link="right_wrist_pitch_link" />
    <child
      link="right_hand_yaw_link" />
    <axis
      xyz="0 0 1" />
    <limit
      lower="-3.14159265358979"
      upper="3.14159265358979"
      effort="18"
      velocity="14" />
  </joint>

  <!-- Right hand Contact -->
  <joint name="right_hand_contact_joint" type="fixed">
    <origin xyz="0 0 0.0" rpy="0 0 0" />
    <parent link="right_hand_yaw_link" />
    <child link="right_hand_contact" />
  </joint>
  <link name="right_hand_contact">
    <inertial>
      <origin xyz=".0 .0 .0" rpy="0 0 0" />
      <mass value="0.001" />
      <inertia 
        ixx="0.0000001" 
        ixy="0.0" 
        ixz="0.0" 
        iyy="0.0000001" 
        iyz="0.0" 
        izz="0.0000001" />
    </inertial>
    <visual>
      <origin xyz="0 0 0" rpy="0 0 0" />
      <geometry>
        <box size="0.01 0.01 0.01"/>
      </geometry>
      <material name="">
        <color rgba="1 0 0 1" />
      </material>
    </visual>
  </link>

  <link
    name="head_yaw_link">
    <inertial>
      <origin
        xyz="0.16E-03 5.14E-03 39.84E-03"
        rpy="0 0 0" />
      <mass
        value="0.30" />
      <inertia
        ixx="140.11E-06"
        ixy="0.44E-06"
        ixz="1.10E-06"
        iyy="137.90E-06"
        iyz="-2.56E-06"
        izz="125.53E-06" />
    </inertial>
    <visual>
      <origin
        xyz="0 0 0"
        rpy="0 0 0" />
      <geometry>
        <mesh
          filename="../meshes/HU_D03_02/neck_yaw_link.STL" />
      </geometry>
      <material
        name="">
        <color
          rgba="0.898039215686275 0.917647058823529 0.929411764705882 1" />
      </material>
    </visual>
    <!--<collision>
      <origin
        xyz="0 0 0"
        rpy="0 0 0" />
      <geometry>
        <mesh
          filename="../meshes/HU_D03_02/neck_yaw_link.STL" />
      </geometry>
    </collision>-->
  </link>
  <joint
    name="head_yaw_joint"
    type="revolute">
    <origin
      xyz="-0.0129999999999993 0 0.3837"
      rpy="0 0 0" />
    <parent
      link="waist_pitch_link" />
    <child
      link="head_yaw_link" />
    <axis
      xyz="0 0 1" />
    <limit
      lower="-0.785398163397448"
      upper="0.785398163397448"
      effort="18"
      velocity="14" />
  </joint>
  <link
    name="head_pitch_link">
    <inertial>
      <origin
        xyz="-0.82E-03 -22.59E-03 77.56E-03"
        rpy="0 0 0" />
      <mass
        value="0.61" />
      <inertia
        ixx="1615.62E-06"
        ixy="2.76E-06"
        ixz="146.35E-06"
        iyy="2052.54E-06"
        iyz="32.83E-06"
        izz="2820.41E-06" />
    </inertial>
    <visual>
      <origin
        xyz="0 0 0"
        rpy="0 0 0" />
      <geometry>
        <mesh
          filename="../meshes/HU_D03_02/neck_pitch_link.STL" />
      </geometry>
      <material
        name="">
        <color
          rgba="0.792156862745098 0.819607843137255 0.933333333333333 1" />
      </material>
    </visual>
    <collision>
      <origin xyz="0.00949 -0.02325 0.076" rpy="0. 0. 0. "/>
      <geometry>
        <box size="0.15 0.1 0.03 "/>
      </geometry>
    </collision>
    <!--<collision>
      <origin
        xyz="0 0 0"
        rpy="0 0 0" />
      <geometry>
        <mesh
          filename="../meshes/HU_D03_02/neck_pitch_link.STL" />
      </geometry>
    </collision>-->
  </link>
  <joint
    name="head_pitch_joint"
    type="revolute">
    <origin
      xyz="0 0.02325 0.0415"
      rpy="0 0 0" />
    <parent
      link="head_yaw_link" />
    <child
      link="head_pitch_link" />
    <axis
      xyz="0 1 0" />
    <limit
      lower="-0.523598775598299"
      upper="0.959931088596881"
      effort="18"
      velocity="14" />
  </joint>
</robot>