<?xml version="1.0" encoding="utf-8"?>
<robot
  name="HU_D03_03">
  
  <!-- <link name="root_link">
    <inertial>
      <origin xyz="0 0 0" rpy="0 0 0" />
      <mass value="0.001" />
      <inertia ixx="1E-10" ixy="0" ixz="0" iyy="1E-10" iyz="0" izz="1E-10" />
    </inertial>
  </link>
  <joint name="floating_base_joint" type="floating">
    <origin xyz="0.0 0.0 0.0" rpy="0 0 0" />
    <parent link="root_link" />
    <child link="base_link" />
  </joint> -->

  <link
    name="base_link">
    <inertial>
      <origin
        xyz="-0.0041214 5.036E-05 0.034849"
        rpy="0 0 0" />
      <mass
        value="5.765" />
      <inertia
        ixx="0.036047"
        ixy="9.6E-06"
        ixz="0.0018589"
        iyy="0.014476"
        iyz="-7.93E-06"
        izz="0.038467" />
    </inertial>
    <visual>
      <origin
        xyz="0 0 0"
        rpy="0 0 0" />
      <geometry>
        <mesh
          filename="package://HU_D03_description/meshes/HU_D03_03/base_link.STL" />
      </geometry>
      <material
        name="">
        <color
          rgba="1 1 1 1" />
      </material>
    </visual>
    <!-- <collision>
      <origin
        xyz="0 0 0"
        rpy="0 0 0" />
      <geometry>
        <mesh
          filename="package://HU_D03_description/meshes/HU_D03_03/base_link.STL" />
      </geometry>
    </collision> -->
  </link>
  <link
    name="left_hip_pitch_link">
    <inertial>
      <origin
        xyz="-0.00067024 0.0087587 -0.088316"
        rpy="0 0 0" />
      <mass
        value="2.186" />
      <inertia
        ixx="0.0036435"
        ixy="4.23E-06"
        ixz="-2.708E-05"
        iyy="0.0039017"
        iyz="3.745E-05"
        izz="0.0029015" />
    </inertial>
    <visual>
      <origin
        xyz="0 0 0"
        rpy="0 0 0" />
      <geometry>
        <mesh
          filename="package://HU_D03_description/meshes/HU_D03_03/left_hip_pitch_link.STL" />
      </geometry>
      <material
        name="">
        <color
          rgba="1 1 1 1" />
      </material>
    </visual>
    <!-- <collision>
      <origin
        xyz="0 0 0"
        rpy="0 0 0" />
      <geometry>
        <mesh
          filename="package://HU_D03_description/meshes/HU_D03_03/left_hip_pitch_link.STL" />
      </geometry>
    </collision> -->
  </link>
  <joint
    name="left_hip_pitch_joint"
    type="revolute">
    <origin
      xyz="0.01 0.12109 0.0069226"
      rpy="0 0 0" />
    <parent
      link="base_link" />
    <child
      link="left_hip_pitch_link" />
    <axis
      xyz="0 0.90631 -0.42262" />
    <limit
      lower="-3.1415"
      upper="3.1415"
      effort="120"
      velocity="12" />
  </joint>
  <link
    name="left_hip_roll_link">
    <inertial>
      <origin
        xyz="0.002905 0.00013123 -0.0338674"
        rpy="0 0 0" />
      <mass
        value="0.5" />
      <inertia
        ixx="0.00097173"
        ixy="-1.6E-07"
        ixz="-3.421E-05"
        iyy="0.00189967"
        iyz="1.78E-06"
        izz="0.00159113" />
    </inertial>
    <visual>
      <origin
        xyz="0 0 0"
        rpy="0 0 0" />
      <geometry>
        <mesh
          filename="package://HU_D03_description/meshes/HU_D03_03/left_hip_roll_link.STL" />
      </geometry>
      <material
        name="">
        <color
          rgba="1 1 1 1" />
      </material>
    </visual>
    <!-- <collision>
      <origin
        xyz="0 0 0"
        rpy="0 0 0" />
      <geometry>
        <mesh
          filename="package://HU_D03_description/meshes/HU_D03_03/left_hip_roll_link.STL" />
      </geometry>
    </collision> -->
  </link>
  <joint
    name="left_hip_roll_joint"
    type="revolute">
    <origin
      xyz="-0.01 0.0089101 -0.095423"
      rpy="0 0 0" />
    <parent
      link="left_hip_pitch_link" />
    <child
      link="left_hip_roll_link" />
    <axis
      xyz="1 0 0" />
    <limit
      lower="-0.524"
      upper="2.094"
      effort="120"
      velocity="12" />
  </joint>
  <link
    name="left_hip_yaw_link">
    <inertial>
      <origin
        xyz="0.00460206 0.00320001 -0.17187698"
        rpy="0 0 0" />
      <mass
        value="4.43" />
      <inertia
        ixx="0.07177311"
        ixy="1.9E-05"
        ixz="0.00023829"
        iyy="0.07259765"
        iyz="0.00139524"
        izz="0.0067474" />
    </inertial>
    <visual>
      <origin
        xyz="0 0 0"
        rpy="0 0 0" />
      <geometry>
        <mesh
          filename="package://HU_D03_description/meshes/HU_D03_03/left_hip_yaw_link.STL" />
      </geometry>
      <material
        name="">
        <color
          rgba="1 1 1 1" />
      </material>
    </visual>
    <!-- <collision>
      <origin
        xyz="0 0 0"
        rpy="0 0 0" />
      <geometry>
        <mesh
          filename="package://HU_D03_description/meshes/HU_D03_03/left_hip_yaw_link.STL" />
      </geometry>
    </collision> -->
  </link>
  <joint
    name="left_hip_yaw_joint"
    type="revolute">
    <origin
      xyz="0 0 -0.0705"
      rpy="0 0 0" />
    <parent
      link="left_hip_roll_link" />
    <child
      link="left_hip_yaw_link" />
    <axis
      xyz="0 0 1" />
    <limit
      lower="-2.705"
      upper="2.705"
      effort="120"
      velocity="12" />
  </joint>
  <link
    name="left_knee_link">
    <inertial>
      <origin
        xyz="0.0095585 0.0080121 -0.13546"
        rpy="0 0 0" />
      <mass
        value="2.844" />
      <inertia
        ixx="0.027551"
        ixy="0.00010241"
        ixz="0.00039987"
        iyy="0.026965"
        iyz="-0.00221"
        izz="0.0033989" />
    </inertial>
    <visual>
      <origin
        xyz="0 0 0"
        rpy="0 0 0" />
      <geometry>
        <mesh
          filename="package://HU_D03_description/meshes/HU_D03_03/left_knee_link.STL" />
      </geometry>
      <material
        name="">
        <color
          rgba="1 1 1 1" />
      </material>
    </visual>
    <!-- <collision>
      <origin
        xyz="0 0 0"
        rpy="0 0 0" />
      <geometry>
        <mesh
          filename="package://HU_D03_description/meshes/HU_D03_03/left_knee_link.STL" />
      </geometry>
    </collision> -->
  </link>
  <joint
    name="left_knee_joint"
    type="revolute">
    <origin
      xyz="0 0 -0.3045"
      rpy="0 0 0" />
    <parent
      link="left_hip_yaw_link" />
    <child
      link="left_knee_link" />
    <axis
      xyz="0 1 0" />
    <limit
      lower="-0.087"
      upper="2.583"
      effort="120"
      velocity="12" />
  </joint>
  <link
    name="left_ankle_pitch_link">
    <inertial>
      <origin
        xyz="0.00014602 0.00019049 0.00096596"
        rpy="0 0 0" />
      <mass
        value="0.099" />
      <inertia
        ixx="1.98E-05"
        ixy="0"
        ixz="0"
        iyy="6.94E-06"
        iyz="0"
        izz="2.26E-05" />
    </inertial>
    <visual>
      <origin
        xyz="0 0 0"
        rpy="0 0 0" />
      <geometry>
        <mesh
          filename="package://HU_D03_description/meshes/HU_D03_03/left_ankle_pitch_link.STL" />
      </geometry>
      <material
        name="">
        <color
          rgba="1 1 1 1" />
      </material>
    </visual>
    <!-- <collision>
      <origin
        xyz="0 0 0"
        rpy="0 0 0" />
      <geometry>
        <mesh
          filename="package://HU_D03_description/meshes/HU_D03_03/left_ankle_pitch_link.STL" />
      </geometry>
    </collision> -->
  </link>
  <joint
    name="left_ankle_pitch_joint"
    type="revolute">
    <origin
      xyz="0 0.0013982 -0.3855"
      rpy="0 0 0" />
    <parent
      link="left_knee_link" />
    <child
      link="left_ankle_pitch_link" />
    <axis
      xyz="0 1 0" />
    <limit
      lower="-0.95"
      upper="0.611"
      effort="45"
      velocity="16" />
  </joint>
  <link
    name="left_ankle_roll_link">
    <inertial>
      <origin
        xyz="13.29E-03 0.0 -37.04E-03"
        rpy="0 0 0" />
      <mass
        value="1.25" />
      <inertia
        ixx="910662E-09"
        ixy="-132E-09"
        ixz="436169E-09"
        iyy="5168345E-09"
        iyz="-28E-09"
        izz="5419687E-09" />
    </inertial>
    <visual>
      <origin
        xyz="0 0 0"
        rpy="0 0 0" />
      <geometry>
        <mesh
          filename="package://HU_D03_description/meshes/HU_D03_03/left_ankle_roll_link.STL" />
      </geometry>
      <material
        name="">
        <color
          rgba="1 1 1 1" />
      </material>
    </visual>
    <collision>
      <origin rpy="0 0 0" xyz="0.018 0 -0.0535"/>
      <geometry>
        <box size="0.25 0.094 0.02"/>
      </geometry>
    </collision>
    <!-- <collision>
      <origin
        xyz="0 0 0"
        rpy="0 0 0" />
      <geometry>
        <mesh
          filename="package://HU_D03_description/meshes/HU_D03_03/left_ankle_roll_link.STL" />
      </geometry>
    </collision> -->
  </link>
  <joint
    name="left_ankle_roll_joint"
    type="revolute">
    <origin
      xyz="0 0 0"
      rpy="0 0 0" />
    <parent
      link="left_ankle_pitch_link" />
    <child
      link="left_ankle_roll_link" />
    <axis
      xyz="1 0 0" />
    <limit
      lower="-0.436"
      upper="0.436"
      effort="45"
      velocity="16" />
  </joint>

    <!-- Left Foot Contact -->
  <joint name="contact_foot_center_joint_L" type="fixed">
    <origin xyz="0.0 0 -0.0625" rpy="0 0 0" />
    <parent link="left_ankle_roll_link" />
    <child link="contact_foot_center_L" />
  </joint>
  <link name="contact_foot_center_L">
    <inertial>
      <origin xyz=".0 .0 .0" rpy="0 0 0" />
      <mass value="0.001" />
      <inertia ixx="0.0000001" ixy="0.0" ixz="0.0" iyy="0.0000001" iyz="0.0" izz="0.0000001" />
    </inertial>
    <visual>
      <origin xyz="0 0 0" rpy="0 0 0" />
      <geometry>
        <box size="0.01 0.01 0.01"/>
      </geometry>
      <material name="">
        <color rgba="1 0 0 1" />
      </material>
    </visual>
  </link>

  <joint name="contact_foot_heel_joint_L" type="fixed">
    <origin xyz="-0.106 0 -0.0625" rpy="0 0 0" />
    <parent link="left_ankle_roll_link" />
    <child link="contact_foot_heel_L" />
  </joint>
  <link name="contact_foot_heel_L">
    <inertial>
      <origin xyz=".0 .0 .0" rpy="0 0 0" />
      <mass value="0.001" />
      <inertia ixx="0.0000001" ixy="0.0" ixz="0.0" iyy="0.0000001" iyz="0.0" izz="0.0000001" />
    </inertial>
    <visual>
      <origin xyz="0 0 0" rpy="0 0 0" />
      <geometry>
        <box size="0.01 0.01 0.01"/>
      </geometry>
      <material name="">
        <color rgba="1 0 0 1" />
      </material>
    </visual>
  </link>

  <joint name="contact_foot_tip_joint_L" type="fixed">
    <origin xyz="0.154 0 -0.0625" rpy="0 0 0" />
    <parent link="left_ankle_roll_link" />
    <child link="contact_foot_tip_L" />
  </joint>
  <link name="contact_foot_tip_L">
    <inertial>
      <origin xyz=".0 .0 .0" rpy="0 0 0" />
      <mass value="0.001" />
      <inertia ixx="0.0000001" ixy="0.0" ixz="0.0" iyy="0.0000001" iyz="0.0" izz="0.0000001" />
    </inertial>
    <visual>
      <origin xyz="0 0 0" rpy="0 0 0" />
      <geometry>
        <box size="0.01 0.01 0.01"/>
      </geometry>
      <material name="">
        <color rgba="1 0 0 1" />
      </material>
    </visual>
  </link>

  <link
    name="right_hip_pitch_link">
    <inertial>
      <origin
        xyz="-0.00064502 -0.0086743 -0.088248"
        rpy="0 0 0" />
      <mass
        value="2.187" />
      <inertia
        ixx="0.0036558"
        ixy="-1.833E-05"
        ixz="-3.154E-05"
        iyy="0.0039148"
        iyz="8.39E-06"
        izz="0.0029022" />
    </inertial>
    <visual>
      <origin
        xyz="0 0 0"
        rpy="0 0 0" />
      <geometry>
        <mesh
          filename="package://HU_D03_description/meshes/HU_D03_03/right_hip_pitch_link.STL" />
      </geometry>
      <material
        name="">
        <color
          rgba="1 1 1 1" />
      </material>
    </visual>
    <!-- <collision>
      <origin
        xyz="0 0 0"
        rpy="0 0 0" />
      <geometry>
        <mesh
          filename="package://HU_D03_description/meshes/HU_D03_03/right_hip_pitch_link.STL" />
      </geometry>
    </collision> -->
  </link>
  <joint
    name="right_hip_pitch_joint"
    type="revolute">
    <origin
      xyz="0.01 -0.12109 0.0069226"
      rpy="0 0 0" />
    <parent
      link="base_link" />
    <child
      link="right_hip_pitch_link" />
    <axis
      xyz="0 0.90631 0.42262" />
    <limit
      lower="-3.1415"
      upper="3.1415"
      effort="120"
      velocity="12" />
  </joint>
  <link
    name="right_hip_roll_link">
    <inertial>
      <origin
        xyz="0.002905 0.00013123 -0.0338674"
        rpy="0 0 0" />
      <mass
        value="0.5" />
      <inertia
        ixx="0.00097173"
        ixy="-1.6E-07"
        ixz="-3.421E-05"
        iyy="0.00189967"
        iyz="1.78E-06"
        izz="0.00159113" />
    </inertial>
    <visual>
      <origin
        xyz="0 0 0"
        rpy="0 0 0" />
      <geometry>
        <mesh
          filename="package://HU_D03_description/meshes/HU_D03_03/right_hip_roll_link.STL" />
      </geometry>
      <material
        name="">
        <color
          rgba="1 1 1 1" />
      </material>
    </visual>
    <!-- <collision>
      <origin
        xyz="0 0 0"
        rpy="0 0 0" />
      <geometry>
        <mesh
          filename="package://HU_D03_description/meshes/HU_D03_03/right_hip_roll_link.STL" />
      </geometry>
    </collision> -->
  </link>
  <joint
    name="right_hip_roll_joint"
    type="revolute">
    <origin
      xyz="-0.01 -0.0089101 -0.095423"
      rpy="0 0 0" />
    <parent
      link="right_hip_pitch_link" />
    <child
      link="right_hip_roll_link" />
    <axis
      xyz="1 0 0" />
    <limit
      lower="-2.094"
      upper="0.524"
      effort="120"
      velocity="12" />
  </joint>
  <link
    name="right_hip_yaw_link">
    <inertial>
      <origin
        xyz="0.00457981 -0.00320377 -0.17185267"
        rpy="0 0 0" />
      <mass
        value="4.43" />
      <inertia
        ixx="0.07174692"
        ixy="-1.294E-05"
        ixz="0.00022502"
        iyy="0.07257205"
        iyz="-0.00139864"
        izz="0.00674786" />
    </inertial>
    <visual>
      <origin
        xyz="0 0 0"
        rpy="0 0 0" />
      <geometry>
        <mesh
          filename="package://HU_D03_description/meshes/HU_D03_03/right_hip_yaw_link.STL" />
      </geometry>
      <material
        name="">
        <color
          rgba="1 1 1 1" />
      </material>
    </visual>
    <!-- <collision>
      <origin
        xyz="0 0 0"
        rpy="0 0 0" />
      <geometry>
        <mesh
          filename="package://HU_D03_description/meshes/HU_D03_03/right_hip_yaw_link.STL" />
      </geometry>
    </collision> -->
  </link>
  <joint
    name="right_hip_yaw_joint"
    type="revolute">
    <origin
      xyz="0 0 -0.0705"
      rpy="0 0 0" />
    <parent
      link="right_hip_roll_link" />
    <child
      link="right_hip_yaw_link" />
    <axis
      xyz="0 0 1" />
    <limit
      lower="-2.705"
      upper="2.705"
      effort="120"
      velocity="12" />
  </joint>
  <link
    name="right_knee_link">
    <inertial>
      <origin
        xyz="0.0095547 -0.0079958 -0.13546"
        rpy="0 0 0" />
      <mass
        value="2.845" />
      <inertia
        ixx="0.027576"
        ixy="-0.00010161"
        ixz="0.00041019"
        iyy="0.026986"
        iyz="0.0022045"
        izz="0.0034029" />
    </inertial>
    <visual>
      <origin
        xyz="0 0 0"
        rpy="0 0 0" />
      <geometry>
        <mesh
          filename="package://HU_D03_description/meshes/HU_D03_03/right_knee_link.STL" />
      </geometry>
      <material
        name="">
        <color
          rgba="1 1 1 1" />
      </material>
    </visual>
    <!-- <collision>
      <origin
        xyz="0 0 0"
        rpy="0 0 0" />
      <geometry>
        <mesh
          filename="package://HU_D03_description/meshes/HU_D03_03/right_knee_link.STL" />
      </geometry>
    </collision> -->
  </link>
  <joint
    name="right_knee_joint"
    type="revolute">
    <origin
      xyz="0 0 -0.3045"
      rpy="0 0 0" />
    <parent
      link="right_hip_yaw_link" />
    <child
      link="right_knee_link" />
    <axis
      xyz="0 1 0" />
    <limit
      lower="-0.087"
      upper="2.583"
      effort="120"
      velocity="12" />
  </joint>
  <link
    name="right_ankle_pitch_link">
    <inertial>
      <origin
        xyz="0.00014602 -0.00019049 0.00096596"
        rpy="0 0 0" />
      <mass
        value="0.099" />
      <inertia
        ixx="1.98E-05"
        ixy="0"
        ixz="0"
        iyy="6.94E-06"
        iyz="0"
        izz="2.26E-05" />
    </inertial>
    <visual>
      <origin
        xyz="0 0 0"
        rpy="0 0 0" />
      <geometry>
        <mesh
          filename="package://HU_D03_description/meshes/HU_D03_03/right_ankle_pitch_link.STL" />
      </geometry>
      <material
        name="">
        <color
          rgba="1 1 1 1" />
      </material>
    </visual>
    <!-- <collision>
      <origin
        xyz="0 0 0"
        rpy="0 0 0" />
      <geometry>
        <mesh
          filename="package://HU_D03_description/meshes/HU_D03_03/right_ankle_pitch_link.STL" />
      </geometry>
    </collision> -->
  </link>
  <joint
    name="right_ankle_pitch_joint"
    type="revolute">
    <origin
      xyz="0 -0.0013982 -0.3855"
      rpy="0 0 0" />
    <parent
      link="right_knee_link" />
    <child
      link="right_ankle_pitch_link" />
    <axis
      xyz="0 1 0" />
    <limit
      lower="-0.95"
      upper="0.611"
      effort="45"
      velocity="16" />
  </joint>
  <link
    name="right_ankle_roll_link">
    <inertial>
      <origin
        xyz="13.29E-03 0.0 -37.04E-03"
        rpy="0 0 0" />
      <mass
        value="1.25" />
      <inertia
        ixx="910662E-09"
        ixy="-132E-09"
        ixz="436169E-09"
        iyy="5168345E-09"
        iyz="-28E-09"
        izz="5419687E-09" />
    </inertial>
    <visual>
      <origin
        xyz="0 0 0"
        rpy="0 0 0" />
      <geometry>
        <mesh
          filename="package://HU_D03_description/meshes/HU_D03_03/right_ankle_roll_link.STL" />
      </geometry>
      <material
        name="">
        <color
          rgba="1 1 1 1" />
      </material>
    </visual>
    <collision>
      <origin rpy="0 0 0" xyz="0.018 0 -0.0535"/>
      <geometry>
        <box size="0.25 0.094 0.02"/>
      </geometry>
    </collision>
    <!-- <collision>
      <origin
        xyz="0 0 0"
        rpy="0 0 0" />
      <geometry>
        <mesh
          filename="package://HU_D03_description/meshes/HU_D03_03/right_ankle_roll_link.STL" />
      </geometry>
    </collision> -->
  </link>
  <joint
    name="right_ankle_roll_joint"
    type="revolute">
    <origin
      xyz="0 0 0"
      rpy="0 0 0" />
    <parent
      link="right_ankle_pitch_link" />
    <child
      link="right_ankle_roll_link" />
    <axis
      xyz="1 0 0" />
    <limit
      lower="-0.436"
      upper="0.436"
      effort="45"
      velocity="16" />
  </joint>

    <!-- Right Foot Contact -->
  <joint name="contact_foot_center_joint_R" type="fixed">
    <origin xyz="0.0 0 -0.0625" rpy="0 0 0" />
    <parent link="right_ankle_roll_link" />
    <child link="contact_foot_center_R" />
  </joint>
  <link name="contact_foot_center_R">
    <inertial>
      <origin xyz=".0 .0 .0" rpy="0 0 0" />
      <mass value="0.001" />
      <inertia ixx="0.0000001" ixy="0.0" ixz="0.0" iyy="0.0000001" iyz="0.0" izz="0.0000001" />
    </inertial>
    <visual>
      <origin xyz="0 0 0" rpy="0 0 0" />
      <geometry>
        <box size="0.01 0.01 0.01"/>
      </geometry>
      <material name="">
        <color rgba="1 0 0 1" />
      </material>
    </visual>
  </link>

  <joint name="contact_foot_heel_joint_R" type="fixed">
    <origin xyz="-0.106 0 -0.0625" rpy="0 0 0" />
    <parent link="right_ankle_roll_link" />
    <child link="contact_foot_heel_R" />
  </joint>
  <link name="contact_foot_heel_R">
    <inertial>
      <origin xyz=".0 .0 .0" rpy="0 0 0" />
      <mass value="0.001" />
      <inertia ixx="0.0000001" ixy="0.0" ixz="0.0" iyy="0.0000001" iyz="0.0" izz="0.0000001" />
    </inertial>
    <visual>
      <origin xyz="0 0 0" rpy="0 0 0" />
      <geometry>
        <box size="0.01 0.01 0.01"/>
      </geometry>
      <material name="">
        <color rgba="1 0 0 1" />
      </material>
    </visual>
  </link>

  <joint name="contact_foot_tip_joint_R" type="fixed">
    <origin xyz="0.154 0 -0.0625" rpy="0 0 0" />
    <parent link="right_ankle_roll_link" />
    <child link="contact_foot_tip_R" />
  </joint>
  <link name="contact_foot_tip_R">
    <inertial>
      <origin xyz=".0 .0 .0" rpy="0 0 0" />
      <mass value="0.001" />
      <inertia ixx="0.0000001" ixy="0.0" ixz="0.0" iyy="0.0000001" iyz="0.0" izz="0.0000001" />
    </inertial>
    <visual>
      <origin xyz="0 0 0" rpy="0 0 0" />
      <geometry>
        <box size="0.01 0.01 0.01"/>
      </geometry>
      <material name="">
        <color rgba="1 0 0 1" />
      </material>
    </visual>
  </link>

  <link
    name="waist_yaw_link">
    <inertial>
      <origin
        xyz="0.019524 -0.0001341 0.023212"
        rpy="0 0 0" />
      <mass
        value="0.778" />
      <inertia
        ixx="0.00090134"
        ixy="4.58E-06"
        ixz="-0.00019608"
        iyy="0.0013518"
        iyz="2.09E-06"
        izz="0.0014869" />
    </inertial>
    <visual>
      <origin
        xyz="0 0 0"
        rpy="0 0 0" />
      <geometry>
        <mesh
          filename="package://HU_D03_description/meshes/HU_D03_03/waist_yaw_link.STL" />
      </geometry>
      <material
        name="">
        <color
          rgba="1 1 1 1" />
      </material>
    </visual>
    <!-- <collision>
      <origin
        xyz="0 0 0"
        rpy="0 0 0" />
      <geometry>
        <mesh
          filename="package://HU_D03_description/meshes/HU_D03_03/waist_yaw_link.STL" />
      </geometry>
    </collision> -->
  </link>
  <joint
    name="waist_yaw_joint"
    type="revolute">
    <origin
      xyz="0 0 0.0925"
      rpy="0 0 0" />
    <parent
      link="base_link" />
    <child
      link="waist_yaw_link" />
    <axis
      xyz="0 0 1" />
    <limit
      lower="-2.618"
      upper="2.618"
      effort="45"
      velocity="16" />
  </joint>
  <link
    name="waist_roll_link">
    <inertial>
      <origin
        xyz="-0.00014211 8.87E-05 -0.00011009"
        rpy="0 0 0" />
      <mass
        value="0.392" />
      <inertia
        ixx="0.00016746"
        ixy="0"
        ixz="0"
        iyy="8.157E-05"
        iyz="0"
        izz="0.00021059" />
    </inertial>
    <visual>
      <origin
        xyz="0 0 0"
        rpy="0 0 0" />
      <geometry>
        <mesh
          filename="package://HU_D03_description/meshes/HU_D03_03/waist_roll_link.STL" />
      </geometry>
      <material
        name="">
        <color
          rgba="1 1 1 1" />
      </material>
    </visual>
    <!-- <collision>
      <origin
        xyz="0 0 0"
        rpy="0 0 0" />
      <geometry>
        <mesh
          filename="package://HU_D03_description/meshes/HU_D03_03/waist_roll_link.STL" />
      </geometry>
    </collision> -->
  </link>
  <joint
    name="waist_roll_joint"
    type="revolute">
    <origin
      xyz="0 0 0.062"
      rpy="0 0 0" />
    <parent
      link="waist_yaw_link" />
    <child
      link="waist_roll_link" />
    <axis
      xyz="1 0 0" />
    <limit
      lower="-0.524"
      upper="0.524"
      effort="45"
      velocity="16" />
  </joint>
  <link
    name="waist_pitch_link">
    <inertial>
      <origin
        xyz="-0.01194049 -0.00204706 0.21730147"
        rpy="0 0 0" />
      <mass
        value="11.989" />
      <inertia
        ixx="0.20231142"
        ixy="-0.00016139"
        ixz="0.00821077"
        iyy="0.1704776"
        iyz="0.00047625"
        izz="0.11458452" />
    </inertial>
    <visual>
      <origin
        xyz="0 0 0"
        rpy="0 0 0" />
      <geometry>
        <mesh
          filename="package://HU_D03_description/meshes/HU_D03_03/waist_pitch_link.STL" />
      </geometry>
      <material
        name="">
        <color
          rgba="1 1 1 1" />
      </material>
    </visual>
    <!-- <collision>
      <origin
        xyz="0 0 0"
        rpy="0 0 0" />
      <geometry>
        <mesh
          filename="package://HU_D03_description/meshes/HU_D03_03/waist_pitch_link.STL" />
      </geometry>
    </collision> -->
  </link>
  <joint
    name="waist_pitch_joint"
    type="revolute">
    <origin
      xyz="0 0 0"
      rpy="0 0 0" />
    <parent
      link="waist_roll_link" />
    <child
      link="waist_pitch_link" />
    <axis
      xyz="0 1 0" />
    <limit
      lower="-0.524"
      upper="0.524"
      effort="45"
      velocity="16" />
  </joint>

  <link
    name="left_shoulder_pitch_link">
    <inertial>
      <origin
        xyz="0.0060726 0.02897752 0"
        rpy="0 0 0" />
      <mass
        value="0.158" />
      <inertia
        ixx="0.00016865"
        ixy="-2.657E-05"
        ixz="0"
        iyy="0.00021233"
        iyz="0"
        izz="0.00025338" />
    </inertial>
    <visual>
      <origin
        xyz="0 0 0"
        rpy="0 0 0" />
      <geometry>
        <mesh
          filename="package://HU_D03_description/meshes/HU_D03_03/left_shoulder_pitch_link.STL" />
      </geometry>
      <material
        name="">
        <color
          rgba="1 1 1 1" />
      </material>
    </visual>
    <!-- <collision>
      <origin
        xyz="0 0 0"
        rpy="0 0 0" />
      <geometry>
        <mesh
          filename="package://HU_D03_description/meshes/HU_D03_03/left_shoulder_pitch_link.STL" />
      </geometry>
    </collision> -->
  </link>
  <joint
    name="left_shoulder_pitch_joint"
    type="revolute">
    <origin
      xyz="0 0.1575 0.2822"
      rpy="0 0 0" />
    <parent
      link="waist_pitch_link" />
    <child
      link="left_shoulder_pitch_link" />
    <axis
      xyz="0 1 0" />
    <limit
      lower="-2.793"
      upper="2.793"
      effort="30"
      velocity="20" />
  </joint>
  <link
    name="left_shoulder_roll_link">
    <inertial>
      <origin
        xyz="0.00335434 4.779E-05 -0.04643687"
        rpy="0 0 0" />
      <mass
        value="1.746" />
      <inertia
        ixx="0.0049148"
        ixy="1.48E-06"
        ixz="-0.00025247"
        iyy="0.00488557"
        iyz="-1.82E-06"
        izz="0.00136983" />
    </inertial>
    <visual>
      <origin
        xyz="0 0 0"
        rpy="0 0 0" />
      <geometry>
        <mesh
          filename="package://HU_D03_description/meshes/HU_D03_03/left_shoulder_roll_link.STL" />
      </geometry>
      <material
        name="">
        <color
          rgba="1 1 1 1" />
      </material>
    </visual>
    <!-- <collision>
      <origin
        xyz="0 0 0"
        rpy="0 0 0" />
      <geometry>
        <mesh
          filename="package://HU_D03_description/meshes/HU_D03_03/left_shoulder_roll_link.STL" />
      </geometry>
    </collision> -->
  </link>
  <joint
    name="left_shoulder_roll_joint"
    type="revolute">
    <origin
      xyz="0 0.055 0"
      rpy="0 0 0" />
    <parent
      link="left_shoulder_pitch_link" />
    <child
      link="left_shoulder_roll_link" />
    <axis
      xyz="1 0 0" />
    <limit
      lower="-0.087"
      upper="3.229"
      effort="30"
      velocity="20" />
  </joint>
  <link
    name="left_shoulder_yaw_link">
    <inertial>
      <origin
        xyz="-0.00949724 0.00403644 -0.060625"
        rpy="0 0 0" />
      <mass
        value="0.265" />
      <inertia
        ixx="0.00073701"
        ixy="-8.11E-06"
        ixz="-1.755E-05"
        iyy="0.00064793"
        iyz="5.117E-05"
        izz="0.00033412" />
    </inertial>
    <visual>
      <origin
        xyz="0 0 0"
        rpy="0 0 0" />
      <geometry>
        <mesh
          filename="package://HU_D03_description/meshes/HU_D03_03/left_shoulder_yaw_link.STL" />
      </geometry>
      <material
        name="">
        <color
          rgba="1 1 1 1" />
      </material>
    </visual>
    <!-- <collision>
      <origin
        xyz="0 0 0"
        rpy="0 0 0" />
      <geometry>
        <mesh
          filename="package://HU_D03_description/meshes/HU_D03_03/left_shoulder_yaw_link.STL" />
      </geometry>
    </collision> -->
  </link>
  <joint
    name="left_shoulder_yaw_joint"
    type="revolute">
    <origin
      xyz="0 0 -0.1306"
      rpy="0 0 0" />
    <parent
      link="left_shoulder_roll_link" />
    <child
      link="left_shoulder_yaw_link" />
    <axis
      xyz="0 0 1" />
    <limit
      lower="-1.571"
      upper="1.571"
      effort="30"
      velocity="20" />
  </joint>
  <link
    name="left_elbow_link">
    <inertial>
      <origin
        xyz="-5.874E-05 0.00486789 -0.0240026"
        rpy="0 0 0" />
      <mass
        value="1.216" />
      <inertia
        ixx="0.00241616"
        ixy="-1.66E-06"
        ixz="1.08E-06"
        iyy="0.00245492"
        iyz="-0.00011637"
        izz="0.00083774" />
    </inertial>
    <visual>
      <origin
        xyz="0 0 0"
        rpy="0 0 0" />
      <geometry>
        <mesh
          filename="package://HU_D03_description/meshes/HU_D03_03/left_elbow_link.STL" />
      </geometry>
      <material
        name="">
        <color
          rgba="1 1 1 1" />
      </material>
    </visual>
    <!-- <collision>
      <origin
        xyz="0 0 0"
        rpy="0 0 0" />
      <geometry>
        <mesh
          filename="package://HU_D03_description/meshes/HU_D03_03/left_elbow_link.STL" />
      </geometry>
    </collision> -->
  </link>
  <joint
    name="left_elbow_joint"
    type="revolute">
    <origin
      xyz="0 0 -0.1157"
      rpy="0 0 0" />
    <parent
      link="left_shoulder_yaw_link" />
    <child
      link="left_elbow_link" />
    <axis
      xyz="0 1 0" />
    <limit
      lower="-2.5307"
      upper="1.2915"
      effort="30"
      velocity="20" />
  </joint>
  <link
    name="left_wrist_yaw_link">
    <inertial>
      <origin
        xyz="0 0.00240189 -0.01766389"
        rpy="0 0 0" />
      <mass
        value="0.116" />
      <inertia
        ixx="0.0001312"
        ixy="0"
        ixz="-9E-08"
        iyy="8.102E-05"
        iyz="3.04E-06"
        izz="0.00011668" />
    </inertial>
    <visual>
      <origin
        xyz="0 0 0"
        rpy="0 0 0" />
      <geometry>
        <mesh
          filename="package://HU_D03_description/meshes/HU_D03_03/left_wrist_yaw_link.STL" />
      </geometry>
      <material
        name="">
        <color
          rgba="1 1 1 1" />
      </material>
    </visual>
    <!-- <collision>
      <origin
        xyz="0 0 0"
        rpy="0 0 0" />
      <geometry>
        <mesh
          filename="package://HU_D03_description/meshes/HU_D03_03/left_wrist_yaw_link.STL" />
      </geometry>
    </collision> -->
  </link>
  <joint
    name="left_wrist_yaw_joint"
    type="revolute">
    <origin
      xyz="0 0 -0.1048"
      rpy="0 0 0" />
    <parent
      link="left_elbow_link" />
    <child
      link="left_wrist_yaw_link" />
    <axis
      xyz="0 0 1" />
    <limit
      lower="-1.571"
      upper="1.571"
      effort="18"
      velocity="14" />
  </joint>
  <link
    name="left_wrist_pitch_link">
    <inertial>
      <origin
        xyz="-3.73E-06 0.00334909 -0.03135721"
        rpy="0 0 0" />
      <mass
        value="0.651" />
      <inertia
        ixx="0.00092892"
        ixy="1.9E-07"
        ixz="-8.8E-07"
        iyy="0.00092506"
        iyz="-5.909E-05"
        izz="0.00033651" />
    </inertial>
    <visual>
      <origin
        xyz="0 0 0"
        rpy="0 0 0" />
      <geometry>
        <mesh
          filename="package://HU_D03_description/meshes/HU_D03_03/left_wrist_pitch_link.STL" />
      </geometry>
      <material
        name="">
        <color
          rgba="1 1 1 1" />
      </material>
    </visual>
    <!-- <collision>
      <origin
        xyz="0 0 0"
        rpy="0 0 0" />
      <geometry>
        <mesh
          filename="package://HU_D03_description/meshes/HU_D03_03/left_wrist_pitch_link.STL" />
      </geometry>
    </collision> -->
  </link>
  <joint
    name="left_wrist_pitch_joint"
    type="revolute">
    <origin
      xyz="0 0 -0.0345"
      rpy="0 0 0" />
    <parent
      link="left_wrist_yaw_link" />
    <child
      link="left_wrist_pitch_link" />
    <axis
      xyz="0 1 0" />
    <limit
      lower="-1.571"
      upper="1.571"
      effort="18"
      velocity="14" />
  </joint>
  <link
    name="left_hand_yaw_link">
    <inertial>
      <origin
        xyz="2.8E-06 -4.277E-05 -0.05887156"
        rpy="0 0 0" />
      <mass
        value="0.261" />
      <inertia
        ixx="0.00057637"
        ixy="0"
        ixz="-2E-08"
        iyy="0.00047053"
        iyz="5.1E-07"
        izz="0.00013901" />
    </inertial>
    <visual>
      <origin
        xyz="0 0 0"
        rpy="0 0 0" />
      <geometry>
        <mesh
          filename="package://HU_D03_description/meshes/HU_D03_03/left_hand_yaw_link.STL" />
      </geometry>
      <material
        name="">
        <color
          rgba="1 1 1 1" />
      </material>
    </visual>
    <!-- <collision>
      <origin
        xyz="0 0 0"
        rpy="0 0 0" />
      <geometry>
        <mesh
          filename="package://HU_D03_description/meshes/HU_D03_03/left_hand_yaw_link.STL" />
      </geometry>
    </collision> -->
  </link>
  <joint
    name="left_hand_yaw_joint"
    type="revolute">
    <origin
      xyz="0 0 -0.0815"
      rpy="0 0 0" />
    <parent
      link="left_wrist_pitch_link" />
    <child
      link="left_hand_yaw_link" />
    <axis
      xyz="0 0 1" />
    <limit
      lower="-2.356"
      upper="2.356"
      effort="18"
      velocity="14" />
  </joint>

  <!-- Left hand Contact -->
  <joint name="left_hand_contact_joint" type="fixed">
    <origin xyz="0 0 0" rpy="0 0 0" />
    <parent link="left_hand_yaw_link" />
    <child link="left_hand_contact" />
  </joint>
  <link name="left_hand_contact">
    <inertial>
      <origin xyz=".0 .0 .0" rpy="0 0 0" />
      <mass value="0.001" />
      <inertia 
        ixx="0.0000001" 
        ixy="0.0" 
        ixz="0.0" 
        iyy="0.0000001" 
        iyz="0.0" 
        izz="0.0000001" />
    </inertial>
    <visual>
      <origin xyz="0 0 0" rpy="0 0 0" />
      <geometry>
        <box size="0.01 0.01 0.01"/>
      </geometry>
      <material name="">
        <color rgba="1 0 0 1" />
      </material>
    </visual>
  </link>

  <!-- Left hand For Manipulation -->
  <joint name="left_hand_manip_joint" type="fixed">
    <origin xyz="0 0 0.0" rpy="0 1.5708 0" />
    <parent link="left_hand_yaw_link" />
    <child link="left_hand_manip" />
  </joint>
  <link name="left_hand_manip">
    <inertial>
      <origin xyz=".0 .0 .0" rpy="0 0 0" />
      <mass value="0.001" />
      <inertia 
        ixx="0.0000001" 
        ixy="0.0" 
        ixz="0.0" 
        iyy="0.0000001" 
        iyz="0.0" 
        izz="0.0000001" />
    </inertial>
    <visual>
      <origin xyz="0 0 0" rpy="0 0 0" />
      <geometry>
        <box size="0.01 0.01 0.01"/>
      </geometry>
      <material name="">
        <color rgba="1 0 0 1" />
      </material>
    </visual>
  </link>

  <link
    name="right_shoulder_pitch_link">
    <inertial>
      <origin
        xyz="0.00608318 -0.02889547 -7.462E-05"
        rpy="0 0 0" />
      <mass
        value="0.159" />
      <inertia
        ixx="0.00016917"
        ixy="2.654E-05"
        ixz="3E-08"
        iyy="0.00021258"
        iyz="2.6E-07"
        izz="0.00025368" />
    </inertial>
    <visual>
      <origin
        xyz="0 0 0"
        rpy="0 0 0" />
      <geometry>
        <mesh
          filename="package://HU_D03_description/meshes/HU_D03_03/right_shoulder_pitch_link.STL" />
      </geometry>
      <material
        name="">
        <color
          rgba="1 1 1 1" />
      </material>
    </visual>
    <!-- <collision>
      <origin
        xyz="0 0 0"
        rpy="0 0 0" />
      <geometry>
        <mesh
          filename="package://HU_D03_description/meshes/HU_D03_03/right_shoulder_pitch_link.STL" />
      </geometry>
    </collision> -->
  </link>
  <joint
    name="right_shoulder_pitch_joint"
    type="revolute">
    <origin
      xyz="0 -0.1575 0.2822"
      rpy="0 0 0" />
    <parent
      link="waist_pitch_link" />
    <child
      link="right_shoulder_pitch_link" />
    <axis
      xyz="0 1 0" />
    <limit
      lower="-2.793"
      upper="2.793"
      effort="30"
      velocity="20" />
  </joint>
  <link
    name="right_shoulder_roll_link">
    <inertial>
      <origin
        xyz="0.00333695 4.67E-05 -0.04641655"
        rpy="0 0 0" />
      <mass
        value="1.744" />
      <inertia
        ixx="0.00490313"
        ixy="1.53E-06"
        ixz="-0.00025087"
        iyy="0.00487395"
        iyz="-1.67E-06"
        izz="0.00136829" />
    </inertial>
    <visual>
      <origin
        xyz="0 0 0"
        rpy="0 0 0" />
      <geometry>
        <mesh
          filename="package://HU_D03_description/meshes/HU_D03_03/right_shoulder_roll_link.STL" />
      </geometry>
      <material
        name="">
        <color
          rgba="1 1 1 1" />
      </material>
    </visual>
    <!-- <collision>
      <origin
        xyz="0 0 0"
        rpy="0 0 0" />
      <geometry>
        <mesh
          filename="package://HU_D03_description/meshes/HU_D03_03/right_shoulder_roll_link.STL" />
      </geometry>
    </collision> -->
  </link>
  <joint
    name="right_shoulder_roll_joint"
    type="revolute">
    <origin
      xyz="0 -0.055 0"
      rpy="0 0 0" />
    <parent
      link="right_shoulder_pitch_link" />
    <child
      link="right_shoulder_roll_link" />
    <axis
      xyz="1 0 0" />
    <limit
      lower="-3.229"
      upper="0.087"
      effort="30"
      velocity="20" />
  </joint>
  <link
    name="right_shoulder_yaw_link">
    <inertial>
      <origin
        xyz="-0.00951399 -0.00405211 -0.06053064"
        rpy="0 0 0" />
      <mass
        value="0.265" />
      <inertia
        ixx="0.00073708"
        ixy="8.18E-06"
        ixz="-1.756E-05"
        iyy="0.00064809"
        iyz="-5.102E-05"
        izz="0.0003342" />
    </inertial>
    <visual>
      <origin
        xyz="0 0 0"
        rpy="0 0 0" />
      <geometry>
        <mesh
          filename="package://HU_D03_description/meshes/HU_D03_03/right_shoulder_yaw_link.STL" />
      </geometry>
      <material
        name="">
        <color
          rgba="1 1 1 1" />
      </material>
    </visual>
    <!-- <collision>
      <origin
        xyz="0 0 0"
        rpy="0 0 0" />
      <geometry>
        <mesh
          filename="package://HU_D03_description/meshes/HU_D03_03/right_shoulder_yaw_link.STL" />
      </geometry>
    </collision> -->
  </link>
  <joint
    name="right_shoulder_yaw_joint"
    type="revolute">
    <origin
      xyz="0 0 -0.1306"
      rpy="0 0 0" />
    <parent
      link="right_shoulder_roll_link" />
    <child
      link="right_shoulder_yaw_link" />
    <axis
      xyz="0 0 1" />
    <limit
      lower="-1.571"
      upper="1.571"
      effort="30"
      velocity="20" />
  </joint>
  <link
    name="right_elbow_link">
    <inertial>
      <origin
        xyz="5.719E-05 -0.00484446 -0.02392416"
        rpy="0 0 0" />
      <mass
        value="1.214" />
      <inertia
        ixx="0.00241424"
        ixy="-1.7E-06"
        ixz="-9.7E-07"
        iyy="0.00245286"
        iyz="0.00011576"
        izz="0.00083629" />
    </inertial>
    <visual>
      <origin
        xyz="0 0 0"
        rpy="0 0 0" />
      <geometry>
        <mesh
          filename="package://HU_D03_description/meshes/HU_D03_03/right_elbow_link.STL" />
      </geometry>
      <material
        name="">
        <color
          rgba="1 1 1 1" />
      </material>
    </visual>
    <!-- <collision>
      <origin
        xyz="0 0 0"
        rpy="0 0 0" />
      <geometry>
        <mesh
          filename="package://HU_D03_description/meshes/HU_D03_03/right_elbow_link.STL" />
      </geometry>
    </collision> -->
  </link>
  <joint
    name="right_elbow_joint"
    type="revolute">
    <origin
      xyz="0 0 -0.1157"
      rpy="0 0 0" />
    <parent
      link="right_shoulder_yaw_link" />
    <child
      link="right_elbow_link" />
    <axis
      xyz="0 1 0" />
    <limit
      lower="-2.5307"
      upper="1.2915"
      effort="30"
      velocity="20" />
  </joint>
  <link
    name="right_wrist_yaw_link">
    <inertial>
      <origin
        xyz="0 -0.00240189 -0.01756389"
        rpy="0 0 0" />
      <mass
        value="0.116" />
      <inertia
        ixx="0.0001312"
        ixy="0"
        ixz="9E-08"
        iyy="8.102E-05"
        iyz="-3.04E-06"
        izz="0.00011668" />
    </inertial>
    <visual>
      <origin
        xyz="0 0 0"
        rpy="0 0 0" />
      <geometry>
        <mesh
          filename="package://HU_D03_description/meshes/HU_D03_03/right_wrist_yaw_link.STL" />
      </geometry>
      <material
        name="">
        <color
          rgba="1 1 1 1" />
      </material>
    </visual>
    <!-- <collision>
      <origin
        xyz="0 0 0"
        rpy="0 0 0" />
      <geometry>
        <mesh
          filename="package://HU_D03_description/meshes/HU_D03_03/right_wrist_yaw_link.STL" />
      </geometry>
    </collision> -->
  </link>
  <joint
    name="right_wrist_yaw_joint"
    type="revolute">
    <origin
      xyz="0 0 -0.1048"
      rpy="0 0 0" />
    <parent
      link="right_elbow_link" />
    <child
      link="right_wrist_yaw_link" />
    <axis
      xyz="0 0 1" />
    <limit
      lower="-1.571"
      upper="1.571"
      effort="18"
      velocity="14" />
  </joint>
  <link
    name="right_wrist_pitch_link">
    <inertial>
      <origin
        xyz="3.73E-06 -0.00334909 -0.03135721"
        rpy="0 0 0" />
      <mass
        value="0.651" />
      <inertia
        ixx="0.00092892"
        ixy="1.9E-07"
        ixz="8.8E-07"
        iyy="0.00092506"
        iyz="5.909E-05"
        izz="0.00033651" />
    </inertial>
    <visual>
      <origin
        xyz="0 0 0"
        rpy="0 0 0" />
      <geometry>
        <mesh
          filename="package://HU_D03_description/meshes/HU_D03_03/right_wrist_pitch_link.STL" />
      </geometry>
      <material
        name="">
        <color
          rgba="1 1 1 1" />
      </material>
    </visual>
    <!-- <collision>
      <origin
        xyz="0 0 0"
        rpy="0 0 0" />
      <geometry>
        <mesh
          filename="package://HU_D03_description/meshes/HU_D03_03/right_wrist_pitch_link.STL" />
      </geometry>
    </collision> -->
  </link>
  <joint
    name="right_wrist_pitch_joint"
    type="revolute">
    <origin
      xyz="0 0 -0.0345"
      rpy="0 0 0" />
    <parent
      link="right_wrist_yaw_link" />
    <child
      link="right_wrist_pitch_link" />
    <axis
      xyz="0 1 0" />
    <limit
      lower="-1.571"
      upper="1.571"
      effort="18"
      velocity="14" />
  </joint>
  <link
    name="right_hand_yaw_link">
    <inertial>
      <origin
        xyz="-2.8E-06 4.277E-05 -0.05877156"
        rpy="0 0 0" />
      <mass
        value="0.261" />
      <inertia
        ixx="0.00057637"
        ixy="0"
        ixz="2E-08"
        iyy="0.00047053"
        iyz="-5.1E-07"
        izz="0.00013901" />
    </inertial>
    <visual>
      <origin
        xyz="0 0 0"
        rpy="0 0 0" />
      <geometry>
        <mesh
          filename="package://HU_D03_description/meshes/HU_D03_03/right_hand_yaw_link.STL" />
      </geometry>
      <material
        name="">
        <color
          rgba="1 1 1 1" />
      </material>
    </visual>
    <!-- <collision>
      <origin
        xyz="0 0 0"
        rpy="0 0 0" />
      <geometry>
        <mesh
          filename="package://HU_D03_description/meshes/HU_D03_03/right_hand_yaw_link.STL" />
      </geometry>
    </collision> -->
  </link>
  <joint
    name="right_hand_yaw_joint"
    type="revolute">
    <origin
      xyz="0 0 -0.0815"
      rpy="0 0 0" />
    <parent
      link="right_wrist_pitch_link" />
    <child
      link="right_hand_yaw_link" />
    <axis
      xyz="0 0 1" />
    <limit
      lower="-2.356"
      upper="2.356"
      effort="18"
      velocity="14" />
  </joint>

  <!-- Right hand Contact -->
  <joint name="right_hand_contact_joint" type="fixed">
    <origin xyz="0 0 0.0" rpy="0 0 0" />
    <parent link="right_hand_yaw_link" />
    <child link="right_hand_contact" />
  </joint>
  <link name="right_hand_contact">
    <inertial>
      <origin xyz=".0 .0 .0" rpy="0 0 0" />
      <mass value="0.001" />
      <inertia 
        ixx="0.0000001" 
        ixy="0.0" 
        ixz="0.0" 
        iyy="0.0000001" 
        iyz="0.0" 
        izz="0.0000001" />
    </inertial>
    <visual>
      <origin xyz="0 0 0" rpy="0 0 0" />
      <geometry>
        <box size="0.01 0.01 0.01"/>
      </geometry>
      <material name="">
        <color rgba="1 0 0 1" />
      </material>
    </visual>
  </link>

  <!-- Right hand For Manipulation -->
  <joint name="right_hand_manip_joint" type="fixed">
    <origin xyz="0 0 0.0" rpy="0 1.5708 0" />
    <parent link="right_hand_yaw_link" />
    <child link="right_hand_manip" />
  </joint>
  <link name="right_hand_manip">
    <inertial>
      <origin xyz=".0 .0 .0" rpy="0 0 0" />
      <mass value="0.001" />
      <inertia 
        ixx="0.0000001" 
        ixy="0.0" 
        ixz="0.0" 
        iyy="0.0000001" 
        iyz="0.0" 
        izz="0.0000001" />
    </inertial>
    <visual>
      <origin xyz="0 0 0" rpy="0 0 0" />
      <geometry>
        <box size="0.01 0.01 0.01"/>
      </geometry>
      <material name="">
        <color rgba="1 0 0 1" />
      </material>
    </visual>
  </link>
  
  <link
    name="head_yaw_link">
    <inertial>
      <origin
        xyz="1.263E-05 0.00749931 0.03957992"
        rpy="0 0 0" />
      <mass
        value="0.314" />
      <inertia
        ixx="0.00015227"
        ixy="9.6E-07"
        ixz="6.8E-07"
        iyy="0.00014564"
        iyz="7.3E-07"
        izz="0.0001379" />
    </inertial>
    <visual>
      <origin
        xyz="0 0 0"
        rpy="0 0 0" />
      <geometry>
        <mesh
          filename="package://HU_D03_description/meshes/HU_D03_03/neck_yaw_link.STL" />
      </geometry>
      <material
        name="">
        <color
          rgba="1 1 1 1" />
      </material>
    </visual>
    <!-- <collision>
      <origin
        xyz="0 0 0"
        rpy="0 0 0" />
      <geometry>
        <mesh
          filename="package://HU_D03_description/meshes/HU_D03_03/neck_yaw_link.STL" />
      </geometry>
    </collision> -->
  </link>
  <joint
    name="head_yaw_joint"
    type="revolute">
    <origin
      xyz="-0.013 0 0.3837"
      rpy="0 0 0" />
    <parent
      link="waist_pitch_link" />
    <child
      link="head_yaw_link" />
    <axis
      xyz="0 0 1" />
    <limit
      lower="-0.785"
      upper="0.785"
      effort="18"
      velocity="14" />
  </joint>
  <link
    name="head_pitch_link">
    <inertial>
      <origin
        xyz="0.00894282 -0.00017284 0.06951097"
        rpy="0 0 0" />
      <mass
        value="0.969" />
      <inertia
        ixx="0.00251828"
        ixy="1.3E-07"
        ixz="0.00022007"
        iyy="0.00242323"
        iyz="-4E-06"
        izz="0.00348849" />
    </inertial>
    <visual>
      <origin
        xyz="0 0 0"
        rpy="0 0 0" />
      <geometry>
        <mesh
          filename="package://HU_D03_description/meshes/HU_D03_03/neck_pitch_link.STL" />
      </geometry>
      <material
        name="">
        <color
          rgba="1 1 1 1" />
      </material>
    </visual>
    <!-- <collision>
      <origin
        xyz="0 0 0"
        rpy="0 0 0" />
      <geometry>
        <mesh
          filename="package://HU_D03_description/meshes/HU_D03_03/neck_pitch_link.STL" />
      </geometry>
    </collision> -->
  </link>
  <joint
    name="head_pitch_joint"
    type="revolute">
    <origin
      xyz="0 0 0.0415"
      rpy="0 0 0" />
    <parent
      link="head_yaw_link" />
    <child
      link="head_pitch_link" />
    <axis
      xyz="0 1 0" />
    <limit
      lower="-0.524"
      upper="0.96"
      effort="18"
      velocity="14" />
  </joint>


  <!-- Camera -->
  <joint name="waist_camera_joint" type="fixed">
    <origin rpy="0.0 2.1818 0.0" xyz="0.092 0.0175 0.2751"/>
    <parent link="waist_pitch_link"/>
    <child link="waist_camera_link"/>
  </joint>
  <link name="waist_camera_link">
    <visual>
        <origin rpy="0 0 0" xyz="0 0 0"/>
        <geometry>
            <mesh filename="package://HU_D03_description/meshes/HU_D03_03/d435_link.STL"/>
        </geometry>
    </visual>
  </link>

  <joint name="head_camera_joint" type="fixed">
    <origin rpy="0.0 1.5708 0.0" xyz="0.07453 0.0175 0.065"/>
    <parent link="head_pitch_link"/>
    <child link="head_camera_link"/>
  </joint>
  <link name="head_camera_link">
    <visual>
        <origin rpy="0 0 0" xyz="0 0 0"/>
        <geometry>
            <mesh filename="package://HU_D03_description/meshes/HU_D03_03/d435_link.STL"/>
        </geometry>
    </visual>
  </link>

</robot>