<?xml version="1.0" encoding="utf-8"?>
<!-- This URDF was automatically created by SolidWorks to URDF Exporter! Originally created by Stephen Brawner (brawner@gmail.com) 
     Commit Version: 1.6.0-4-g7f85cfe  Build Version: 1.6.7995.38578
     For more information, please see http://wiki.ros.org/sw_urdf_exporter -->
<robot name="UB_D03_01">

  <!-- <link name="root_link">
    <inertial>
      <origin xyz="0 0 0" rpy="0 0 0" />
      <mass value="0.001" />
      <inertia ixx="1E-10" ixy="0" ixz="0" iyy="1E-10" iyz="0" izz="1E-10" />
    </inertial>
  </link>
  <joint name="floating_base_joint" type="floating">
    <origin xyz="0.0 0.0 0.0" rpy="0 0 0" />
    <parent link="root_link" />
    <child link="base_link" />
  </joint> -->

  <link name="base_link">
    <inertial>
      <origin
        xyz="-3.72E-03 0.03E-03 34.3E-03"
        rpy="0 0 0" />
      <mass
        value="5.86" />
      <inertia
        ixx="36967.43E-06"
        ixy="12.03E-06"
        ixz="1753.69E-06"
        iyy="14780.36E-06"
        iyz="-7.09E-06"
        izz="39050.95E-06" />
    </inertial>
    <visual>
      <origin
        xyz="0 0 0"
        rpy="0 0 0" />
      <geometry>
        <mesh
          filename="package://UB_D03_description/meshes/UB_D03_01/base_link.STL" />
      </geometry>
      <material
        name="">
        <color
          rgba="0.792156862745098 0.819607843137255 0.933333333333333 1" />
      </material>
    </visual>
    <!-- <collision>
      <origin
        xyz="0 0 0"
        rpy="0 0 0" />
      <geometry>
        <mesh
          filename="package://UB_D03_description/meshes/UB_D03_01/base_link.STL" />
      </geometry>
    </collision> -->
  </link>
  
  <!-- waist -->
  <link name="waist_yaw_link">
    <inertial>
      <origin
        xyz="19.84E-03 -0.22E-03 23.15E-03"
        rpy="0 0 0" />
      <mass
        value="0.69" />
      <inertia
        ixx="660.92E-06"
        ixy="7.74E-06"
        ixz="-256.63E-06"
        iyy="1233.56E-06"
        iyz="3.29E-06"
        izz="1303.5E-06" />
    </inertial>
    <visual>
      <origin
        xyz="0 0 0"
        rpy="0 0 0" />
      <geometry>
        <mesh
          filename="package://UB_D03_description/meshes/UB_D03_01/waist_yaw_link.STL" />
      </geometry>
      <material
        name="">
        <color
          rgba="0.898039215686275 0.917647058823529 0.929411764705882 1" />
      </material>
    </visual>
    <!-- <collision>
      <origin
        xyz="0 0 0"
        rpy="0 0 0" />
      <geometry>
        <mesh
          filename="package://UB_D03_description/meshes/UB_D03_01/waist_yaw_link.STL" />
      </geometry>
    </collision> -->
  </link>
  <joint
    name="waist_yaw_joint"
    type="revolute">
    <origin
      xyz="0 0 0.0889999999999995"
      rpy="0 0 0" />
    <parent
      link="base_link" />
    <child
      link="waist_yaw_link" />
    <axis
      xyz="0 0 1" />
    <limit
      lower="-1.309"
      upper="1.309"
      effort="40"
      velocity="16" />
  </joint>
  
  <link name="waist_roll_link">
    <inertial>
      <origin
        xyz="-0.06E-03 0.08E-03 -0.1E-03"
        rpy="0 0 0" />
      <mass
        value="0.44" />
      <inertia
        ixx="168.03E-06"
        ixy="0"
        ixz="0"
        iyy="114.13E-06"
        iyz="0"
        izz="238.27E-06" />
    </inertial>
    <visual>
      <origin
        xyz="0 0 0"
        rpy="0 0 0" />
      <geometry>
        <mesh
          filename="package://UB_D03_description/meshes/UB_D03_01/waist_roll_link.STL" />
      </geometry>
      <material
        name="">
        <color
          rgba="0.776470588235294 0.756862745098039 0.737254901960784 1" />
      </material>
    </visual>
    <!-- <collision>
      <origin
        xyz="0 0 0"
        rpy="0 0 0" />
      <geometry>
        <mesh
          filename="package://UB_D03_description/meshes/UB_D03_01/waist_roll_link.STL" />
      </geometry>
    </collision> -->
  </link>
  <joint
    name="waist_roll_joint"
    type="revolute">
    <origin
      xyz="0 0 0.0613000000000001"
      rpy="0 0 0" />
    <parent
      link="waist_yaw_link" />
    <child
      link="waist_roll_link" />
    <axis
      xyz="1 0 0" />
    <limit
      lower="-0.5236"
      upper="0.5236"
      effort="80"
      velocity="16" />
  </joint>
  
  <link name="waist_pitch_link">
    <inertial>
      <origin
        xyz="-6.8E-03 0.55E-03 200.52E-03"
        rpy="0 0 0" />
      <mass
        value="12.06" />
      <inertia
        ixx="167632.84E-06"
        ixy="-201.66E-06"
        ixz="7864.31E-06"
        iyy="127458.96E-06"
        iyz="-212.04E-06"
        izz="92922.47E-06" />
    </inertial>
    <visual>
      <origin
        xyz="0 0 0"
        rpy="0 0 0" />
      <geometry>
        <mesh
          filename="package://UB_D03_description/meshes/UB_D03_01/waist_pitch_link.STL" />
      </geometry>
      <material
        name="">
        <color
          rgba="0.898039215686275 0.917647058823529 0.929411764705882 1" />
      </material>
    </visual>
    <!-- <collision>
      <origin
        xyz="0 0 0"
        rpy="0 0 0" />
      <geometry>
        <mesh
          filename="package://UB_D03_description/meshes/UB_D03_01/waist_pitch_link.STL" />
      </geometry>
    </collision> -->
  </link>
  <joint
    name="waist_pitch_joint"
    type="revolute">
    <origin
      xyz="0 0 0"
      rpy="0 0 0" />
    <parent
      link="waist_roll_link" />
    <child
      link="waist_pitch_link" />
    <axis
      xyz="0 1 0" />
    <limit
      lower="-0.5236"
      upper="0.7854"
      effort="80"
      velocity="16" />
  </joint>
  
  <!-- left arm -->
  <link name="left_shoulder_pitch_link">
    <inertial>
      <origin
        xyz="0.00727 0.0353 0"
        rpy="0 0 0" />
      <mass value="0.268" />
      <inertia
        ixx="307.877939E-06"
        ixy="-63.709473E-06"
        ixz="0.007018E-06"
        iyy="447.093993E-06"
        iyz="0.032674E-06"
        izz="487.055703E-06" />
    </inertial>
    <visual>
      <origin
        xyz="0 0 0"
        rpy="0 0 0" />
      <geometry>
        <mesh
          filename="package://UB_D03_description/meshes/UB_D03_01/left_shoulder_pitch_link.STL" />
      </geometry>
      <material
        name="">
        <color
          rgba="0.898039215686275 0.917647058823529 0.929411764705882 1" />
      </material>
    </visual>
  </link>
  <joint name="left_shoulder_pitch_joint" type="revolute">
    <origin
      xyz="0 0.1485 0.2476"
      rpy="0 0 0" />
    <parent link="waist_pitch_link" />
    <child link="left_shoulder_pitch_link" />
    <axis xyz="0 1 0" />
    <limit
      lower="-3.14"
      upper="3.14"
      effort="15.5"
      velocity="16" />
  </joint>
  
  <link name="left_shoulder_roll_link">
    <inertial>
      <origin
        xyz="0.00374 0 -0.05126"
        rpy="0 0 0" />
      <mass value="1.817" />
      <inertia
        ixx="6428.062884E-06"
        ixy="4.363539E-06"
        ixz="-381.621256E-06"
        iyy="6639.669557E-06"
        iyz="-19.299648E-06"
        izz="1707.334120E-06" />
    </inertial>
    <visual>
      <origin
        xyz="0 0 0"
        rpy="0 0 0" />
      <geometry>
        <mesh
          filename="package://UB_D03_description/meshes/UB_D03_01/left_shoulder_roll_link.STL" />
      </geometry>
      <material
        name="">
        <color
          rgba="0.792156862745098 0.819607843137255 0.933333333333333 1" />
      </material>
    </visual>
  </link>
  <joint name="left_shoulder_roll_joint" type="revolute">
    <origin
      xyz="0 0.0685 0"
      rpy="0 0 0" />
    <parent link="left_shoulder_pitch_link" />
    <child link="left_shoulder_roll_link" />
    <axis xyz="1 0 0" />
    <limit
      lower="-0.0262"
      upper="3.1678"
      effort="15.5"
      velocity="16" />
  </joint>
  
  <link name="left_shoulder_yaw_link">
    <inertial>
      <origin
        xyz="-0.00735 0.00248 -0.07621"
        rpy="0 0 0" />
      <mass value="0.3466" />
      <inertia
        ixx="1232.765984E-06"
        ixy="-4.307641E-06"
        ixz="-35.505806E-06"
        iyy="1008.280275E-06"
        iyz="44.184513E-06"
        izz="527.495140E-06" />
    </inertial>
    <visual>
      <origin
        xyz="0 0 0"
        rpy="0 0 0" />
      <geometry>
        <mesh
          filename="package://UB_D03_description/meshes/UB_D03_01/left_shoulder_yaw_link.STL" />
      </geometry>
      <material
        name="">
        <color
          rgba="0.898039215686275 0.917647058823529 0.929411764705882 1" />
      </material>
    </visual>
  </link>
  <joint name="left_shoulder_yaw_joint" type="revolute">
    <origin
      xyz="0 0 -0.1378"
      rpy="0 0 0" />
    <parent link="left_shoulder_roll_link" />
    <child link="left_shoulder_yaw_link" />
    <axis xyz="0 0 1" />
    <limit
      lower="-1.5708"
      upper="1.5708"
      effort="15.5"
      velocity="16" />
  </joint>
  
  <link name="left_elbow_link">
    <inertial>
      <origin
        xyz="-0.00121 0.00736 0.00424"
        rpy="0 0 0" />
      <mass value="0.992" />
      <inertia
        ixx="1112.383468E-06"
        ixy="-10.768578E-06"
        ixz="-28.412523E-06"
        iyy="988.811840E-06"
        iyz="-12.407378E-06"
        izz="955.189444E-06" />
    </inertial>
    <visual>
      <origin
        xyz="0 0 0"
        rpy="0 0 0" />
      <geometry>
        <mesh
          filename="package://UB_D03_description/meshes/UB_D03_01/left_elbow_link.STL" />
      </geometry>
      <material
        name="">
        <color
          rgba="0.180392156862745 0.180392156862745 0.180392156862745 1" />
      </material>
    </visual>
  </link>
  <joint name="left_elbow_joint" type="revolute">
    <origin
      xyz="0 0 -0.1322"
      rpy="0 0 0" />
    <parent link="left_shoulder_yaw_link" />
    <child link="left_elbow_link" />
    <axis xyz="0 1 0" />
    <limit
      lower="-2.4958"
      upper="0"
      effort="15.5"
      velocity="16" />
  </joint>
  
  <link name="left_wrist_yaw_link">
    <inertial>
      <origin
        xyz="-0.00117 0.00328 -0.08889"
        rpy="0 0 0" />
      <mass value="1.2269" />
      <inertia
        ixx="5222.709361E-06"
        ixy="1.754376E-06"
        ixz="27.094430E-06"
        iyy="5121.021103E-06"
        iyz="90.696007E-06"
        izz="676.565940E-06" />
    </inertial>
    <visual>
      <origin
        xyz="0 0 0"
        rpy="0 0 0" />
      <geometry>
        <mesh
          filename="package://UB_D03_description/meshes/UB_D03_01/left_wrist_yaw_link.STL" />
      </geometry>
      <material
        name="">
        <color
          rgba="0.898039215686275 0.917647058823529 0.929411764705882 1" />
      </material>
    </visual>
  </link>
  <joint name="left_wrist_yaw_joint" type="revolute">
    <origin
      xyz="0 0 -0.0591"
      rpy="0 0 0" />
    <parent link="left_elbow_link" />
    <child link="left_wrist_yaw_link" />
    <axis xyz="0 0 1" />
    <limit
      lower="-1.5708"
      upper="1.5708"
      effort="10"
      velocity="15" />
  </joint>
  
  <link name="left_wrist_roll_link">
    <inertial>
      <origin
        xyz="0.00228 -0.0321 0.00331"
        rpy="0 0 0" />
      <mass value="0.497" />
      <inertia
        ixx="329.990110E-06"
        ixy="0.975745E-06"
        ixz="0.203073E-06"
        iyy="332.816281E-06"
        iyz="-50.533228E-06"
        izz="274.709694E-06" />
    </inertial>
    <visual>
      <origin
        xyz="0 0 0"
        rpy="0 0 0" />
      <geometry>
        <mesh
          filename="package://UB_D03_description/meshes/UB_D03_01/left_wrist_roll_link.STL" />
      </geometry>
      <material
        name="">
        <color
          rgba="0.898039215686275 0.917647058823529 0.929411764705882 1" />
      </material>
    </visual>
  </link>
  <joint name="left_wrist_roll_joint" type="revolute">
    <origin
      xyz="0 0 -0.2254"
      rpy="0 0 0" />
    <parent link="left_wrist_yaw_link" />
    <child link="left_wrist_roll_link" />
    <axis xyz="0 1 0" />
    <limit
      lower="-0.6981"
      upper="0.5236"
      effort="10"
      velocity="15" />
  </joint>
  
  <link name="left_wrist_pitch_link">
    <inertial>
      <origin
        xyz="-0.00067 0 -0.068634"
        rpy="0 0 0" />
      <mass
        value="0.2249" />
      <inertia
        ixx="355.979848E-06"
        ixy="0.000006E-06"
        ixz="4.750950E-06"
        iyy="424.050358E-06"
        iyz="0.000025E-06"
        izz="157.047882E-06" />
    </inertial>
    <visual>
      <origin
        xyz="0 0 0"
        rpy="0 0 0" />
      <geometry>
        <mesh
          filename="package://UB_D03_description/meshes/UB_D03_01/left_wrist_pitch_link.STL" />
      </geometry>
      <material
        name="">
        <color
          rgba="0.898039215686275 0.917647058823529 0.929411764705882 1" />
      </material>
    </visual>
  </link>
  <joint name="left_wrist_pitch_joint" type="revolute">
    <origin
      xyz="0 0 0"
      rpy="0 0 0" />
    <parent link="left_wrist_roll_link" />
    <child link="left_wrist_pitch_link" />
    <axis xyz="1 0 0" />
    <limit
      lower="-1.5708"
      upper="0.7854"
      effort="10"
      velocity="15" />
  </joint>
  
  <!-- Left hand Contact -->
  <joint name="left_hand_contact_joint" type="fixed">
    <origin xyz="0 0 -0.0521" rpy="0 0 0" />
    <parent link="left_wrist_pitch_link" />
    <child link="left_hand_contact" />
  </joint>
  <link name="left_hand_contact">
    <inertial>
      <origin xyz=".0 .0 .0" rpy="0 0 0" />
      <mass value="0.001" />
      <inertia
        ixx="0.0000001"
        ixy="0.0"
        ixz="0.0"
        iyy="0.0000001"
        iyz="0.0"
        izz="0.0000001" />
    </inertial>
    <visual>
      <origin xyz="0 0 0" rpy="0 0 0" />
      <geometry>
        <box size="0.01 0.01 0.01"/>
      </geometry>
      <material name="">
        <color rgba="1 0 0 1" />
      </material>
    </visual>
  </link>
  
  <joint name="left_hand_contact_finger_joint" type="fixed">
    <origin xyz="0 0.03 -0.082" rpy="0 0 0" />
    <parent link="left_wrist_pitch_link" />
    <child link="left_hand_contact_finger" />
  </joint>
  <link name="left_hand_contact_finger">
    <inertial>
      <origin xyz=".0 .0 .0" rpy="0 0 0" />
      <mass value="0.001" />
      <inertia
        ixx="0.0000001"
        ixy="0.0"
        ixz="0.0"
        iyy="0.0000001"
        iyz="0.0"
        izz="0.0000001" />
    </inertial>
    <visual>
      <origin xyz="0 0 0" rpy="0 0 0" />
      <geometry>
        <box size="0.01 0.01 0.01"/>
      </geometry>
      <material name="">
        <color rgba="1 0 0 1" />
      </material>
    </visual>
  </link>
  
  <joint name="left_hand_contact_thumb_joint" type="fixed">
    <origin xyz="0 -0.03 -0.082" rpy="0 0 0" />
    <parent link="left_wrist_pitch_link" />
    <child link="left_hand_contact_thumb" />
  </joint>
  <link name="left_hand_contact_thumb">
    <inertial>
      <origin xyz=".0 .0 .0" rpy="0 0 0" />
      <mass value="0.001" />
      <inertia
        ixx="0.0000001"
        ixy="0.0"
        ixz="0.0"
        iyy="0.0000001"
        iyz="0.0"
        izz="0.0000001" />
    </inertial>
    <visual>
      <origin xyz="0 0 0" rpy="0 0 0" />
      <geometry>
        <box size="0.01 0.01 0.01"/>
      </geometry>
      <material name="">
        <color rgba="1 0 0 1" />
      </material>
    </visual>
  </link>
  
  <!-- right arm -->
  <link name="right_shoulder_pitch_link">
    <inertial>
      <origin
        xyz="0.00727 -0.0353 0"
        rpy="0 0 0" />
      <mass value="0.268" />
      <inertia
        ixx="307.877939E-06"
        ixy="63.709473E-06"
        ixz="0.007018E-06"
        iyy="447.093993E-06"
        iyz="-0.032674E-06"
        izz="487.055703E-06" />
    </inertial>
    <visual>
      <origin
        xyz="0 0 0"
        rpy="0 0 0" />
      <geometry>
        <mesh
          filename="package://UB_D03_description/meshes/UB_D03_01/right_shoulder_pitch_link.STL" />
      </geometry>
      <material
        name="">
        <color
          rgba="0.9 0.9 0.9 1" />
      </material>
    </visual>
  </link>
  <joint name="right_shoulder_pitch_joint" type="revolute">
    <origin
      xyz="0 -0.1485 0.2476"
      rpy="0 0 0" />
    <parent link="waist_pitch_link" />
    <child link="right_shoulder_pitch_link" />
    <axis xyz="0 1 0" />
    <limit
      lower="-3.14"
      upper="3.14"
      effort="15.5"
      velocity="16" />
  </joint>
  
  <link name="right_shoulder_roll_link">
    <inertial>
      <origin
        xyz="0.00374 0 -0.05126"
        rpy="0 0 0" />
      <mass value="1.817" />
      <inertia
        ixx="6428.062884E-06"
        ixy="-4.363539E-06"
        ixz="-381.621256E-06"
        iyy="6639.669557E-06"
        iyz="19.299648E-06"
        izz="1707.334120E-06" />
    </inertial>
    <visual>
      <origin
        xyz="0 0 0"
        rpy="0 0 0" />
      <geometry>
        <mesh
          filename="package://UB_D03_description/meshes/UB_D03_01/right_shoulder_roll_link.STL" />
      </geometry>
      <material
        name="">
        <color
          rgba="0.9 0.9 0.9 1" />
      </material>
    </visual>
  </link>
  <joint name="right_shoulder_roll_joint" type="revolute">
    <origin
      xyz="0 -0.0685 0"
      rpy="0 0 0" />
    <parent link="right_shoulder_pitch_link" />
    <child link="right_shoulder_roll_link" />
    <axis xyz="1 0 0" />
    <limit
      lower="-3.1678"
      upper="0.0262"
      effort="15.5"
      velocity="16" />
  </joint>
  
  <link name="right_shoulder_yaw_link">
    <inertial>
      <origin
        xyz="-0.00735 -0.00248 -0.07621"
        rpy="0 0 0" />
      <mass value="0.3466" />
      <inertia
        ixx="1232.765984E-06"
        ixy="4.307641E-06"
        ixz="-35.505806E-06"
        iyy="1008.280275E-06"
        iyz="-44.184513E-06"
        izz="527.495140E-06" />
    </inertial>
    <visual>
      <origin
        xyz="0 0 0"
        rpy="0 0 0" />
      <geometry>
        <mesh
          filename="package://UB_D03_description/meshes/UB_D03_01/right_shoulder_yaw_link.STL" />
      </geometry>
      <material
        name="">
        <color
          rgba="0.898039215686275 0.917647058823529 0.929411764705882 1" />
      </material>
    </visual>
  </link>
  <joint name="right_shoulder_yaw_joint" type="revolute">
    <origin
      xyz="0 0 -0.1378"
      rpy="0 0 0" />
    <parent link="right_shoulder_roll_link" />
    <child link="right_shoulder_yaw_link" />
    <axis xyz="0 0 1" />
    <limit
      lower="-1.5708"
      upper="1.5708"
      effort="15.5"
      velocity="16" />
  </joint>
  
  <link name="right_elbow_link">
    <inertial>
      <origin
        xyz="-0.00121 -0.00736 0.00424"
        rpy="0 0 0" />
      <mass value="0.992" />
      <inertia
        ixx="1112.383468E-06"
        ixy="10.768578E-06"
        ixz="-28.412523E-06"
        iyy="988.811840E-06"
        iyz="12.407378E-06"
        izz="955.189444E-06" />
    </inertial>
    <visual>
      <origin
        xyz="0 0 0"
        rpy="0 0 0" />
      <geometry>
        <mesh
          filename="package://UB_D03_description/meshes/UB_D03_01/right_elbow_link.STL" />
      </geometry>
      <material
        name="">
        <color
          rgba="0.792156862745098 0.819607843137255 0.933333333333333 1" />
      </material>
    </visual>
  </link>
  <joint name="right_elbow_joint" type="revolute">
    <origin
      xyz="0 0 -0.1322"
      rpy="0 0 0" />
    <parent link="right_shoulder_yaw_link" />
    <child link="right_elbow_link" />
    <axis xyz="0 1 0" />
    <limit
      lower="-2.4958"
      upper="0"
      effort="15.5"
      velocity="16" />
  </joint>
  
  <link name="right_wrist_yaw_link">
    <inertial>
      <origin
        xyz="-0.00117 -0.00328 -0.08889"
        rpy="0 0 0" />
      <mass value="1.2269" />
      <inertia
        ixx="5222.709361E-06"
        ixy="-1.754376E-06"
        ixz="27.094430E-06"
        iyy="5121.021103E-06"
        iyz="-90.696007E-06"
        izz="676.565940E-06" />
    </inertial>
    <visual>
      <origin
        xyz="0 0 0"
        rpy="0 0 0" />
      <geometry>
        <mesh
          filename="package://UB_D03_description/meshes/UB_D03_01/right_wrist_yaw_link.STL" />
      </geometry>
      <material
        name="">
        <color
          rgba="0.898039215686275 0.917647058823529 0.929411764705882 1" />
      </material>
    </visual>
  </link>
  <joint name="right_wrist_yaw_joint" type="revolute">
    <origin
      xyz="0 0 -0.0591"
      rpy="0 0 0" />
    <parent link="right_elbow_link" />
    <child link="right_wrist_yaw_link" />
    <axis xyz="0 0 1" />
    <limit
      lower="-1.5708"
      upper="1.5708"
      effort="10"
      velocity="15" />
  </joint>
  
  <link name="right_wrist_roll_link">
    <inertial>
      <origin
        xyz="0.00228 0.0321 0.00331"
        rpy="0 0 0" />
      <mass value="0.497" />
      <inertia
        ixx="329.990110E-06"
        ixy="-0.975745E-06"
        ixz="0.203073E-06"
        iyy="332.816281E-06"
        iyz="50.533228E-06"
        izz="274.709694E-06" />
    </inertial>
    <visual>
      <origin
        xyz="0 0 0"
        rpy="0 0 0" />
      <geometry>
        <mesh
          filename="package://UB_D03_description/meshes/UB_D03_01/right_wrist_roll_link.STL" />
      </geometry>
      <material
        name="">
        <color
          rgba="0.898039215686275 0.917647058823529 0.929411764705882 1" />
      </material>
    </visual>
  </link>
  <joint name="right_wrist_roll_joint" type="revolute">
    <origin
      xyz="0 0 -0.2254"
      rpy="0 0 0" />
    <parent link="right_wrist_yaw_link" />
    <child link="right_wrist_roll_link" />
    <axis xyz="0 1 0" />
    <limit
      lower="-0.6981"
      upper="0.5236"
      effort="10"
      velocity="15" />
  </joint>
  
  <link name="right_wrist_pitch_link">
    <inertial>
      <origin
        xyz="-0.00067 0 -0.068634"
        rpy="0 0 0" />
      <mass
        value="0.2249" />
      <inertia
        ixx="355.979848E-06"
        ixy="-0.000006E-06"
        ixz="4.750950E-06"
        iyy="424.050358E-06"
        iyz="-0.000025E-06"
        izz="157.047882E-06" />
    </inertial>
    <visual>
      <origin
        xyz="0 0 0"
        rpy="0 0 0" />
      <geometry>
        <mesh
          filename="package://UB_D03_description/meshes/UB_D03_01/right_wrist_pitch_link.STL" />
      </geometry>
      <material
        name="">
        <color
          rgba="0.898039215686275 0.917647058823529 0.929411764705882 0.25" />
      </material>
    </visual>
  </link>
  <joint name="right_wrist_pitch_joint" type="revolute">
    <origin
      xyz="0 0 0"
      rpy="0 0 0" />
    <parent link="right_wrist_roll_link" />
    <child link="right_wrist_pitch_link" />
    <axis xyz="1 0 0" />
    <limit
      lower="-0.7854"
      upper="1.5708"
      effort="10"
      velocity="15" />
  </joint>

  <!-- Right hand Contact -->
  <joint name="right_hand_contact_joint" type="fixed">
    <origin xyz="0 0 -0.0521" rpy="0 0 0" />
    <parent link="right_wrist_pitch_link" />
    <child link="right_hand_contact" />
  </joint>
  <link name="right_hand_contact">
    <inertial>
      <origin xyz=".0 .0 .0" rpy="0 0 0" />
      <mass value="0.001" />
      <inertia 
        ixx="0.0000001" 
        ixy="0.0" 
        ixz="0.0" 
        iyy="0.0000001" 
        iyz="0.0" 
        izz="0.0000001" />
    </inertial>
    <visual>
      <origin xyz="0 0 0" rpy="0 0 0" />
      <geometry>
        <box size="0.01 0.01 0.01"/>
      </geometry>
      <material name="">
        <color rgba="1 0 0 1" />
      </material>
    </visual>
  </link>
  
  <joint name="right_hand_contact_finger_joint" type="fixed">
    <origin xyz="0 -0.03 -0.082" rpy="0 0 0" />
    <parent link="right_wrist_pitch_link" />
    <child link="right_hand_contact_finger" />
  </joint>
  <link name="right_hand_contact_finger">
    <inertial>
      <origin xyz=".0 .0 .0" rpy="0 0 0" />
      <mass value="0.001" />
      <inertia 
        ixx="0.0000001" 
        ixy="0.0" 
        ixz="0.0" 
        iyy="0.0000001" 
        iyz="0.0" 
        izz="0.0000001" />
    </inertial>
    <visual>
      <origin xyz="0 0 0" rpy="0 0 0" />
      <geometry>
        <box size="0.01 0.01 0.01"/>
      </geometry>
      <material name="">
        <color rgba="1 0 0 1" />
      </material>
    </visual>
  </link>
  
  <joint name="right_hand_contact_thumb_joint" type="fixed">
    <origin xyz="0 0.03 -0.082" rpy="0 0 0" />
    <parent link="right_wrist_pitch_link" />
    <child link="right_hand_contact_thumb" />
  </joint>
  <link name="right_hand_contact_thumb">
    <inertial>
      <origin xyz=".0 .0 .0" rpy="0 0 0" />
      <mass value="0.001" />
      <inertia 
        ixx="0.0000001" 
        ixy="0.0" 
        ixz="0.0" 
        iyy="0.0000001" 
        iyz="0.0" 
        izz="0.0000001" />
    </inertial>
    <visual>
      <origin xyz="0 0 0" rpy="0 0 0" />
      <geometry>
        <box size="0.01 0.01 0.01"/>
      </geometry>
      <material name="">
        <color rgba="1 0 0 1" />
      </material>
    </visual>
  </link>
  
  <!-- head -->
  <link name="head_yaw_link">
    <inertial>
      <origin
        xyz="0.11E-03 2.53E-03 43.05E-03"
        rpy="0 0 0" />
      <mass
        value="0.46" />
      <inertia
        ixx="233.88E-06"
        ixy="0.23E-06"
        ixz="1.29E-06"
        iyy="190.93E-06"
        iyz="0.97E-06"
        izz="213.14E-06" />
    </inertial>
    <visual>
      <origin
        xyz="0 0 0"
        rpy="0 0 0" />
      <geometry>
        <mesh
          filename="package://UB_D03_description/meshes/UB_D03_01/head_yaw_link.STL" />
      </geometry>
      <material
        name="">
        <color
          rgba="0.898039215686275 0.917647058823529 0.929411764705882 1" />
      </material>
    </visual>
    <!-- <collision>
      <origin
        xyz="0 0 0"
        rpy="0 0 0" />
      <geometry>
        <mesh
          filename="package://UB_D03_description/meshes/UB_D03_01/head_yaw_link.STL" />
      </geometry>
    </collision> -->
  </link>
  <joint
    name="head_yaw_joint"
    type="revolute">
    <origin
      xyz="-0.013 0 0.3732"
      rpy="0 0 0" />
    <parent
      link="waist_pitch_link" />
    <child
      link="head_yaw_link" />
    <axis
      xyz="0 0 1" />
    <limit
      lower="-0.7854"
      upper="0.7854"
      effort="10"
      velocity="15" />
  </joint>
  
  <link name="head_pitch_link">
    <inertial>
      <origin
        xyz="0.81E-03 1.38E-03 72.15E-03"
        rpy="0 0 0" />
      <mass
        value="0.45" />
      <inertia
        ixx="2209.54E-06"
        ixy="0.04E-06"
        ixz="243.89E-06"
        iyy="2463.27E-06"
        iyz="36.46E-06"
        izz="3367.16E-06" />
    </inertial>
    <visual>
      <origin
        xyz="0 0 0"
        rpy="0 0 0" />
      <geometry>
        <mesh
          filename="package://UB_D03_description/meshes/UB_D03_01/head_pitch_link.STL" />
      </geometry>
      <material
        name="">
        <color
          rgba="0.513725490196078 0.917647058823529 1 1" />
      </material>
    </visual>
    <!-- <collision>
      <origin
        xyz="0 0 0"
        rpy="0 0 0" />
      <geometry>
        <mesh
          filename="package://UB_D03_description/meshes/UB_D03_01/head_pitch_link.STL" />
      </geometry>
    </collision> -->
  </link>
  <joint
    name="head_pitch_joint"
    type="revolute">
    <origin
      xyz="0 0 0.045"
      rpy="0 0 0" />
    <parent
      link="head_yaw_link" />
    <child
      link="head_pitch_link" />
    <axis
      xyz="0 1 0" />
    <limit
      lower="-0.9599"
      upper="0.9599"
      effort="10"
      velocity="15" />
  </joint>

  <!-- head -->
  <joint name="head_middle_joint" type="fixed">
    <origin xyz="0 0 0.07" rpy="0 0 0" />
    <parent link="head_pitch_link" />
    <child link="head_middle_link" />
  </joint>
  <link name="head_middle_link">
    <inertial>
      <origin xyz=".0 .0 .0" rpy="0 0 0" />
      <mass value="0.001" />
      <inertia 
        ixx="0.0000001" 
        ixy="0.0" 
        ixz="0.0" 
        iyy="0.0000001" 
        iyz="0.0" 
        izz="0.0000001" />
    </inertial>
    <visual>
      <origin xyz="0 0 0" rpy="0 0 0" />
      <geometry>
        <box size="0.01 0.01 0.01"/>
      </geometry>
      <material name="">
        <color rgba="1 0 0 1" />
      </material>
    </visual>
  </link>
  
  <joint name="head_left_joint" type="fixed">
    <origin xyz="0.06 0.06 0.07" rpy="0 0 0" />
    <parent link="head_pitch_link" />
    <child link="head_left_link" />
  </joint>
  <link name="head_left_link">
    <inertial>
      <origin xyz=".0 .0 .0" rpy="0 0 0" />
      <mass value="0.001" />
      <inertia 
        ixx="0.0000001" 
        ixy="0.0" 
        ixz="0.0" 
        iyy="0.0000001" 
        iyz="0.0" 
        izz="0.0000001" />
    </inertial>
    <visual>
      <origin xyz="0 0 0" rpy="0 0 0" />
      <geometry>
        <box size="0.01 0.01 0.01"/>
      </geometry>
      <material name="">
        <color rgba="1 0 0 1" />
      </material>
    </visual>
  </link>
  
  <joint name="head_right_joint" type="fixed">
    <origin xyz="0.06 -0.06 0.07" rpy="0 0 0" />
    <parent link="head_pitch_link" />
    <child link="head_right_link" />
  </joint>
  <link name="head_right_link">
    <inertial>
      <origin xyz=".0 .0 .0" rpy="0 0 0" />
      <mass value="0.001" />
      <inertia 
        ixx="0.0000001" 
        ixy="0.0" 
        ixz="0.0" 
        iyy="0.0000001" 
        iyz="0.0" 
        izz="0.0000001" />
    </inertial>
    <visual>
      <origin xyz="0 0 0" rpy="0 0 0" />
      <geometry>
        <box size="0.01 0.01 0.01"/>
      </geometry>
      <material name="">
        <color rgba="1 0 0 1" />
      </material>
    </visual>
  </link>

</robot>