<?xml version="1.0" encoding="utf-8"?>
<!-- This URDF was automatically created by SolidWorks to URDF Exporter! Originally created by Stephen Brawner (brawner@gmail.com) 
     Commit Version: 1.6.0-4-g7f85cfe  Build Version: 1.6.7995.38578
     For more information, please see http://wiki.ros.org/sw_urdf_exporter -->
<robot
  name="UB_D03_03">
  
  <!-- <link name="root_link">
    <inertial>
      <origin xyz="0 0 0" rpy="0 0 0" />
      <mass value="0.001" />
      <inertia ixx="1E-10" ixy="0" ixz="0" iyy="1E-10" iyz="0" izz="1E-10" />
    </inertial>
  </link>
  <joint name="floating_base_joint" type="floating">
    <origin xyz="0.0 0.0 0.0" rpy="0 0 0" />
    <parent link="root_link" />
    <child link="base_link" />
  </joint> -->


  <link
    name="base_link">
    <inertial>
      <origin
        xyz="-0.0041214 5.036E-05 0.034849"
        rpy="0 0 0" />
      <mass
        value="5.765" />
      <inertia
        ixx="0.036047"
        ixy="9.6E-06"
        ixz="0.0018589"
        iyy="0.014476"
        iyz="-7.93E-06"
        izz="0.038467" />
    </inertial>
    <visual>
      <origin
        xyz="0 0 0"
        rpy="0 0 0" />
      <geometry>
        <mesh
          filename="package://UB_D03_description/meshes/UB_D03_03/base_link.STL" />
      </geometry>
      <material
        name="">
        <color
          rgba="1 1 1 1" />
      </material>
    </visual>
    <!-- <collision>
      <origin
        xyz="0 0 0"
        rpy="0 0 0" />
      <geometry>
        <mesh
          filename="package://UB_D03_description/meshes/UB_D03_03/base_link.STL" />
      </geometry>
    </collision> -->
  </link>

  <!-- waist -->
  <link
    name="waist_yaw_link">
    <inertial>
      <origin
        xyz="0.019524 -0.0001341 0.023212"
        rpy="0 0 0" />
      <mass
        value="0.778" />
      <inertia
        ixx="0.00090134"
        ixy="4.58E-06"
        ixz="-0.00019608"
        iyy="0.0013518"
        iyz="2.09E-06"
        izz="0.0014869" />
    </inertial>
    <visual>
      <origin
        xyz="0 0 0"
        rpy="0 0 0" />
      <geometry>
        <mesh
          filename="package://UB_D03_description/meshes/UB_D03_03/waist_yaw_link.STL" />
      </geometry>
      <material
        name="">
        <color
          rgba="1 1 1 1" />
      </material>
    </visual>
    <!-- <collision>
      <origin
        xyz="0 0 0"
        rpy="0 0 0" />
      <geometry>
        <mesh
          filename="package://UB_D03_description/meshes/UB_D03_03/waist_yaw_link.STL" />
      </geometry>
    </collision> -->
  </link>
  <joint
    name="waist_yaw_joint"
    type="revolute">
    <origin
      xyz="0 0 0.0925"
      rpy="0 0 0" />
    <parent
      link="base_link" />
    <child
      link="waist_yaw_link" />
    <axis
      xyz="0 0 1" />
    <limit
      lower="-2.618"
      upper="2.618"
      effort="45"
      velocity="16" />
  </joint>
  <link
    name="waist_roll_link">
    <inertial>
      <origin
        xyz="-0.00014211 8.87E-05 -0.00011009"
        rpy="0 0 0" />
      <mass
        value="0.392" />
      <inertia
        ixx="0.00016746"
        ixy="0"
        ixz="0"
        iyy="8.157E-05"
        iyz="0"
        izz="0.00021059" />
    </inertial>
    <visual>
      <origin
        xyz="0 0 0"
        rpy="0 0 0" />
      <geometry>
        <mesh
          filename="package://UB_D03_description/meshes/UB_D03_03/waist_roll_link.STL" />
      </geometry>
      <material
        name="">
        <color
          rgba="1 1 1 1" />
      </material>
    </visual>
    <!-- <collision>
      <origin
        xyz="0 0 0"
        rpy="0 0 0" />
      <geometry>
        <mesh
          filename="package://UB_D03_description/meshes/UB_D03_03/waist_roll_link.STL" />
      </geometry>
    </collision> -->
  </link>
  <joint
    name="waist_roll_joint"
    type="revolute">
    <origin
      xyz="0 0 0.062"
      rpy="0 0 0" />
    <parent
      link="waist_yaw_link" />
    <child
      link="waist_roll_link" />
    <axis
      xyz="1 0 0" />
    <limit
      lower="-0.524"
      upper="0.524"
      effort="45"
      velocity="16" />
  </joint>
  <link
    name="waist_pitch_link">
    <inertial>
      <origin
        xyz="-0.01194049 -0.00204706 0.21730147"
        rpy="0 0 0" />
      <mass
        value="11.989" />
      <inertia
        ixx="0.20231142"
        ixy="-0.00016139"
        ixz="0.00821077"
        iyy="0.1704776"
        iyz="0.00047625"
        izz="0.11458452" />
    </inertial>
    <visual>
      <origin
        xyz="0 0 0"
        rpy="0 0 0" />
      <geometry>
        <mesh
          filename="package://UB_D03_description/meshes/UB_D03_03/waist_pitch_link.STL" />
      </geometry>
      <material
        name="">
        <color
          rgba="1 1 1 1" />
      </material>
    </visual>
    <!-- <collision>
      <origin
        xyz="0 0 0"
        rpy="0 0 0" />
      <geometry>
        <mesh
          filename="package://UB_D03_description/meshes/UB_D03_03/waist_pitch_link.STL" />
      </geometry>
    </collision> -->
  </link>
  <joint
    name="waist_pitch_joint"
    type="revolute">
    <origin
      xyz="0 0 0"
      rpy="0 0 0" />
    <parent
      link="waist_roll_link" />
    <child
      link="waist_pitch_link" />
    <axis
      xyz="0 1 0" />
    <limit
      lower="-0.524"
      upper="0.524"
      effort="45"
      velocity="16" />
  </joint>

  <link
    name="left_shoulder_pitch_link">
    <inertial>
      <origin
        xyz="0.0060726 0.02897752 0"
        rpy="0 0 0" />
      <mass
        value="0.158" />
      <inertia
        ixx="0.00016865"
        ixy="-2.657E-05"
        ixz="0"
        iyy="0.00021233"
        iyz="0"
        izz="0.00025338" />
    </inertial>
    <visual>
      <origin
        xyz="0 0 0"
        rpy="0 0 0" />
      <geometry>
        <mesh
          filename="package://UB_D03_description/meshes/UB_D03_03/left_shoulder_pitch_link.STL" />
      </geometry>
      <material
        name="">
        <color
          rgba="1 1 1 1" />
      </material>
    </visual>
    <!-- <collision>
      <origin
        xyz="0 0 0"
        rpy="0 0 0" />
      <geometry>
        <mesh
          filename="package://UB_D03_description/meshes/UB_D03_03/left_shoulder_pitch_link.STL" />
      </geometry>
    </collision> -->
  </link>
  <joint
    name="left_shoulder_pitch_joint"
    type="revolute">
    <origin
      xyz="0 0.1575 0.2822"
      rpy="0 0 0" />
    <parent
      link="waist_pitch_link" />
    <child
      link="left_shoulder_pitch_link" />
    <axis
      xyz="0 1 0" />
    <limit
      lower="-2.793"
      upper="2.793"
      effort="30"
      velocity="20" />
  </joint>
  <link
    name="left_shoulder_roll_link">
    <inertial>
      <origin
        xyz="0.00335434 4.779E-05 -0.04643687"
        rpy="0 0 0" />
      <mass
        value="1.746" />
      <inertia
        ixx="0.0049148"
        ixy="1.48E-06"
        ixz="-0.00025247"
        iyy="0.00488557"
        iyz="-1.82E-06"
        izz="0.00136983" />
    </inertial>
    <visual>
      <origin
        xyz="0 0 0"
        rpy="0 0 0" />
      <geometry>
        <mesh
          filename="package://UB_D03_description/meshes/UB_D03_03/left_shoulder_roll_link.STL" />
      </geometry>
      <material
        name="">
        <color
          rgba="1 1 1 1" />
      </material>
    </visual>
    <!-- <collision>
      <origin
        xyz="0 0 0"
        rpy="0 0 0" />
      <geometry>
        <mesh
          filename="package://UB_D03_description/meshes/UB_D03_03/left_shoulder_roll_link.STL" />
      </geometry>
    </collision> -->
  </link>
  <joint
    name="left_shoulder_roll_joint"
    type="revolute">
    <origin
      xyz="0 0.055 0"
      rpy="0 0 0" />
    <parent
      link="left_shoulder_pitch_link" />
    <child
      link="left_shoulder_roll_link" />
    <axis
      xyz="1 0 0" />
    <limit
      lower="-0.087"
      upper="3.229"
      effort="30"
      velocity="20" />
  </joint>
  <link
    name="left_shoulder_yaw_link">
    <inertial>
      <origin
        xyz="-0.00949724 0.00403644 -0.060625"
        rpy="0 0 0" />
      <mass
        value="0.265" />
      <inertia
        ixx="0.00073701"
        ixy="-8.11E-06"
        ixz="-1.755E-05"
        iyy="0.00064793"
        iyz="5.117E-05"
        izz="0.00033412" />
    </inertial>
    <visual>
      <origin
        xyz="0 0 0"
        rpy="0 0 0" />
      <geometry>
        <mesh
          filename="package://UB_D03_description/meshes/UB_D03_03/left_shoulder_yaw_link.STL" />
      </geometry>
      <material
        name="">
        <color
          rgba="1 1 1 1" />
      </material>
    </visual>
    <!-- <collision>
      <origin
        xyz="0 0 0"
        rpy="0 0 0" />
      <geometry>
        <mesh
          filename="package://UB_D03_description/meshes/UB_D03_03/left_shoulder_yaw_link.STL" />
      </geometry>
    </collision> -->
  </link>
  <joint
    name="left_shoulder_yaw_joint"
    type="revolute">
    <origin
      xyz="0 0 -0.1306"
      rpy="0 0 0" />
    <parent
      link="left_shoulder_roll_link" />
    <child
      link="left_shoulder_yaw_link" />
    <axis
      xyz="0 0 1" />
    <limit
      lower="-1.571"
      upper="1.571"
      effort="30"
      velocity="20" />
  </joint>
  <link
    name="left_elbow_link">
    <inertial>
      <origin
        xyz="-5.874E-05 0.00486789 -0.0240026"
        rpy="0 0 0" />
      <mass
        value="1.216" />
      <inertia
        ixx="0.00241616"
        ixy="-1.66E-06"
        ixz="1.08E-06"
        iyy="0.00245492"
        iyz="-0.00011637"
        izz="0.00083774" />
    </inertial>
    <visual>
      <origin
        xyz="0 0 0"
        rpy="0 0 0" />
      <geometry>
        <mesh
          filename="package://UB_D03_description/meshes/UB_D03_03/left_elbow_link.STL" />
      </geometry>
      <material
        name="">
        <color
          rgba="1 1 1 1" />
      </material>
    </visual>
    <!-- <collision>
      <origin
        xyz="0 0 0"
        rpy="0 0 0" />
      <geometry>
        <mesh
          filename="package://UB_D03_description/meshes/UB_D03_03/left_elbow_link.STL" />
      </geometry>
    </collision> -->
  </link>
  <joint
    name="left_elbow_joint"
    type="revolute">
    <origin
      xyz="0 0 -0.1157"
      rpy="0 0 0" />
    <parent
      link="left_shoulder_yaw_link" />
    <child
      link="left_elbow_link" />
    <axis
      xyz="0 1 0" />
    <limit
      lower="-2.5307"
      upper="1.2915"
      effort="30"
      velocity="20" />
  </joint>
  <link
    name="left_wrist_yaw_link">
    <inertial>
      <origin
        xyz="0 0.00240189 -0.01766389"
        rpy="0 0 0" />
      <mass
        value="0.116" />
      <inertia
        ixx="0.0001312"
        ixy="0"
        ixz="-9E-08"
        iyy="8.102E-05"
        iyz="3.04E-06"
        izz="0.00011668" />
    </inertial>
    <visual>
      <origin
        xyz="0 0 0"
        rpy="0 0 0" />
      <geometry>
        <mesh
          filename="package://UB_D03_description/meshes/UB_D03_03/left_wrist_yaw_link.STL" />
      </geometry>
      <material
        name="">
        <color
          rgba="1 1 1 1" />
      </material>
    </visual>
    <!-- <collision>
      <origin
        xyz="0 0 0"
        rpy="0 0 0" />
      <geometry>
        <mesh
          filename="package://UB_D03_description/meshes/UB_D03_03/left_wrist_yaw_link.STL" />
      </geometry>
    </collision> -->
  </link>
  <joint
    name="left_wrist_yaw_joint"
    type="revolute">
    <origin
      xyz="0 0 -0.1048"
      rpy="0 0 0" />
    <parent
      link="left_elbow_link" />
    <child
      link="left_wrist_yaw_link" />
    <axis
      xyz="0 0 1" />
    <limit
      lower="-1.571"
      upper="1.571"
      effort="18"
      velocity="14" />
  </joint>
  <link
    name="left_wrist_pitch_link">
    <inertial>
      <origin
        xyz="-3.73E-06 0.00334909 -0.03135721"
        rpy="0 0 0" />
      <mass
        value="0.651" />
      <inertia
        ixx="0.00092892"
        ixy="1.9E-07"
        ixz="-8.8E-07"
        iyy="0.00092506"
        iyz="-5.909E-05"
        izz="0.00033651" />
    </inertial>
    <visual>
      <origin
        xyz="0 0 0"
        rpy="0 0 0" />
      <geometry>
        <mesh
          filename="package://UB_D03_description/meshes/UB_D03_03/left_wrist_pitch_link.STL" />
      </geometry>
      <material
        name="">
        <color
          rgba="1 1 1 1" />
      </material>
    </visual>
    <!-- <collision>
      <origin
        xyz="0 0 0"
        rpy="0 0 0" />
      <geometry>
        <mesh
          filename="package://UB_D03_description/meshes/UB_D03_03/left_wrist_pitch_link.STL" />
      </geometry>
    </collision> -->
  </link>
  <joint
    name="left_wrist_pitch_joint"
    type="revolute">
    <origin
      xyz="0 0 -0.0345"
      rpy="0 0 0" />
    <parent
      link="left_wrist_yaw_link" />
    <child
      link="left_wrist_pitch_link" />
    <axis
      xyz="0 1 0" />
    <limit
      lower="-1.571"
      upper="1.571"
      effort="18"
      velocity="14" />
  </joint>
  <link
    name="left_hand_yaw_link">
    <inertial>
      <origin
        xyz="2.8E-06 -4.277E-05 -0.05887156"
        rpy="0 0 0" />
      <mass
        value="0.261" />
      <inertia
        ixx="0.00057637"
        ixy="0"
        ixz="-2E-08"
        iyy="0.00047053"
        iyz="5.1E-07"
        izz="0.00013901" />
    </inertial>
    <visual>
      <origin
        xyz="0 0 0"
        rpy="0 0 0" />
      <geometry>
        <mesh
          filename="package://UB_D03_description/meshes/UB_D03_03/left_hand_yaw_link.STL" />
      </geometry>
      <material
        name="">
        <color
          rgba="1 1 1 1" />
      </material>
    </visual>
    <!-- <collision>
      <origin
        xyz="0 0 0"
        rpy="0 0 0" />
      <geometry>
        <mesh
          filename="package://UB_D03_description/meshes/UB_D03_03/left_hand_yaw_link.STL" />
      </geometry>
    </collision> -->
  </link>
  <joint
    name="left_hand_yaw_joint"
    type="revolute">
    <origin
      xyz="0 0 -0.0815"
      rpy="0 0 0" />
    <parent
      link="left_wrist_pitch_link" />
    <child
      link="left_hand_yaw_link" />
    <axis
      xyz="0 0 1" />
    <limit
      lower="-2.356"
      upper="2.356"
      effort="18"
      velocity="14" />
  </joint>

  <!-- Left hand Contact -->
  <joint name="left_hand_contact_joint" type="fixed">
    <origin xyz="0 0 0" rpy="0 0 0" />
    <parent link="left_hand_yaw_link" />
    <child link="left_hand_contact" />
  </joint>
  <link name="left_hand_contact">
    <inertial>
      <origin xyz=".0 .0 .0" rpy="0 0 0" />
      <mass value="0.001" />
      <inertia 
        ixx="0.0000001" 
        ixy="0.0" 
        ixz="0.0" 
        iyy="0.0000001" 
        iyz="0.0" 
        izz="0.0000001" />
    </inertial>
    <visual>
      <origin xyz="0 0 0" rpy="0 0 0" />
      <geometry>
        <box size="0.01 0.01 0.01"/>
      </geometry>
      <material name="">
        <color rgba="1 0 0 1" />
      </material>
    </visual>
  </link>

  <link
    name="right_shoulder_pitch_link">
    <inertial>
      <origin
        xyz="0.00608318 -0.02889547 -7.462E-05"
        rpy="0 0 0" />
      <mass
        value="0.159" />
      <inertia
        ixx="0.00016917"
        ixy="2.654E-05"
        ixz="3E-08"
        iyy="0.00021258"
        iyz="2.6E-07"
        izz="0.00025368" />
    </inertial>
    <visual>
      <origin
        xyz="0 0 0"
        rpy="0 0 0" />
      <geometry>
        <mesh
          filename="package://UB_D03_description/meshes/UB_D03_03/right_shoulder_pitch_link.STL" />
      </geometry>
      <material
        name="">
        <color
          rgba="1 1 1 1" />
      </material>
    </visual>
    <!-- <collision>
      <origin
        xyz="0 0 0"
        rpy="0 0 0" />
      <geometry>
        <mesh
          filename="package://UB_D03_description/meshes/UB_D03_03/right_shoulder_pitch_link.STL" />
      </geometry>
    </collision> -->
  </link>
  <joint
    name="right_shoulder_pitch_joint"
    type="revolute">
    <origin
      xyz="0 -0.1575 0.2822"
      rpy="0 0 0" />
    <parent
      link="waist_pitch_link" />
    <child
      link="right_shoulder_pitch_link" />
    <axis
      xyz="0 1 0" />
    <limit
      lower="-2.793"
      upper="2.793"
      effort="30"
      velocity="20" />
  </joint>
  <link
    name="right_shoulder_roll_link">
    <inertial>
      <origin
        xyz="0.00333695 4.67E-05 -0.04641655"
        rpy="0 0 0" />
      <mass
        value="1.744" />
      <inertia
        ixx="0.00490313"
        ixy="1.53E-06"
        ixz="-0.00025087"
        iyy="0.00487395"
        iyz="-1.67E-06"
        izz="0.00136829" />
    </inertial>
    <visual>
      <origin
        xyz="0 0 0"
        rpy="0 0 0" />
      <geometry>
        <mesh
          filename="package://UB_D03_description/meshes/UB_D03_03/right_shoulder_roll_link.STL" />
      </geometry>
      <material
        name="">
        <color
          rgba="1 1 1 1" />
      </material>
    </visual>
    <!-- <collision>
      <origin
        xyz="0 0 0"
        rpy="0 0 0" />
      <geometry>
        <mesh
          filename="package://UB_D03_description/meshes/UB_D03_03/right_shoulder_roll_link.STL" />
      </geometry>
    </collision> -->
  </link>
  <joint
    name="right_shoulder_roll_joint"
    type="revolute">
    <origin
      xyz="0 -0.055 0"
      rpy="0 0 0" />
    <parent
      link="right_shoulder_pitch_link" />
    <child
      link="right_shoulder_roll_link" />
    <axis
      xyz="1 0 0" />
    <limit
      lower="-3.229"
      upper="0.087"
      effort="30"
      velocity="20" />
  </joint>
  <link
    name="right_shoulder_yaw_link">
    <inertial>
      <origin
        xyz="-0.00951399 -0.00405211 -0.06053064"
        rpy="0 0 0" />
      <mass
        value="0.265" />
      <inertia
        ixx="0.00073708"
        ixy="8.18E-06"
        ixz="-1.756E-05"
        iyy="0.00064809"
        iyz="-5.102E-05"
        izz="0.0003342" />
    </inertial>
    <visual>
      <origin
        xyz="0 0 0"
        rpy="0 0 0" />
      <geometry>
        <mesh
          filename="package://UB_D03_description/meshes/UB_D03_03/right_shoulder_yaw_link.STL" />
      </geometry>
      <material
        name="">
        <color
          rgba="1 1 1 1" />
      </material>
    </visual>
    <!-- <collision>
      <origin
        xyz="0 0 0"
        rpy="0 0 0" />
      <geometry>
        <mesh
          filename="package://UB_D03_description/meshes/UB_D03_03/right_shoulder_yaw_link.STL" />
      </geometry>
    </collision> -->
  </link>
  <joint
    name="right_shoulder_yaw_joint"
    type="revolute">
    <origin
      xyz="0 0 -0.1306"
      rpy="0 0 0" />
    <parent
      link="right_shoulder_roll_link" />
    <child
      link="right_shoulder_yaw_link" />
    <axis
      xyz="0 0 1" />
    <limit
      lower="-1.571"
      upper="1.571"
      effort="30"
      velocity="20" />
  </joint>
  <link
    name="right_elbow_link">
    <inertial>
      <origin
        xyz="5.719E-05 -0.00484446 -0.02392416"
        rpy="0 0 0" />
      <mass
        value="1.214" />
      <inertia
        ixx="0.00241424"
        ixy="-1.7E-06"
        ixz="-9.7E-07"
        iyy="0.00245286"
        iyz="0.00011576"
        izz="0.00083629" />
    </inertial>
    <visual>
      <origin
        xyz="0 0 0"
        rpy="0 0 0" />
      <geometry>
        <mesh
          filename="package://UB_D03_description/meshes/UB_D03_03/right_elbow_link.STL" />
      </geometry>
      <material
        name="">
        <color
          rgba="1 1 1 1" />
      </material>
    </visual>
    <!-- <collision>
      <origin
        xyz="0 0 0"
        rpy="0 0 0" />
      <geometry>
        <mesh
          filename="package://UB_D03_description/meshes/UB_D03_03/right_elbow_link.STL" />
      </geometry>
    </collision> -->
  </link>
  <joint
    name="right_elbow_joint"
    type="revolute">
    <origin
      xyz="0 0 -0.1157"
      rpy="0 0 0" />
    <parent
      link="right_shoulder_yaw_link" />
    <child
      link="right_elbow_link" />
    <axis
      xyz="0 1 0" />
    <limit
      lower="-2.5307"
      upper="1.2915"
      effort="30"
      velocity="20" />
  </joint>
  <link
    name="right_wrist_yaw_link">
    <inertial>
      <origin
        xyz="0 -0.00240189 -0.01756389"
        rpy="0 0 0" />
      <mass
        value="0.116" />
      <inertia
        ixx="0.0001312"
        ixy="0"
        ixz="9E-08"
        iyy="8.102E-05"
        iyz="-3.04E-06"
        izz="0.00011668" />
    </inertial>
    <visual>
      <origin
        xyz="0 0 0"
        rpy="0 0 0" />
      <geometry>
        <mesh
          filename="package://UB_D03_description/meshes/UB_D03_03/right_wrist_yaw_link.STL" />
      </geometry>
      <material
        name="">
        <color
          rgba="1 1 1 1" />
      </material>
    </visual>
    <!-- <collision>
      <origin
        xyz="0 0 0"
        rpy="0 0 0" />
      <geometry>
        <mesh
          filename="package://UB_D03_description/meshes/UB_D03_03/right_wrist_yaw_link.STL" />
      </geometry>
    </collision> -->
  </link>
  <joint
    name="right_wrist_yaw_joint"
    type="revolute">
    <origin
      xyz="0 0 -0.1048"
      rpy="0 0 0" />
    <parent
      link="right_elbow_link" />
    <child
      link="right_wrist_yaw_link" />
    <axis
      xyz="0 0 1" />
    <limit
      lower="-1.571"
      upper="1.571"
      effort="18"
      velocity="14" />
  </joint>
  <link
    name="right_wrist_pitch_link">
    <inertial>
      <origin
        xyz="3.73E-06 -0.00334909 -0.03135721"
        rpy="0 0 0" />
      <mass
        value="0.651" />
      <inertia
        ixx="0.00092892"
        ixy="1.9E-07"
        ixz="8.8E-07"
        iyy="0.00092506"
        iyz="5.909E-05"
        izz="0.00033651" />
    </inertial>
    <visual>
      <origin
        xyz="0 0 0"
        rpy="0 0 0" />
      <geometry>
        <mesh
          filename="package://UB_D03_description/meshes/UB_D03_03/right_wrist_pitch_link.STL" />
      </geometry>
      <material
        name="">
        <color
          rgba="1 1 1 1" />
      </material>
    </visual>
    <!-- <collision>
      <origin
        xyz="0 0 0"
        rpy="0 0 0" />
      <geometry>
        <mesh
          filename="package://UB_D03_description/meshes/UB_D03_03/right_wrist_pitch_link.STL" />
      </geometry>
    </collision> -->
  </link>
  <joint
    name="right_wrist_pitch_joint"
    type="revolute">
    <origin
      xyz="0 0 -0.0345"
      rpy="0 0 0" />
    <parent
      link="right_wrist_yaw_link" />
    <child
      link="right_wrist_pitch_link" />
    <axis
      xyz="0 1 0" />
    <limit
      lower="-1.571"
      upper="1.571"
      effort="18"
      velocity="14" />
  </joint>
  <link
    name="right_hand_yaw_link">
    <inertial>
      <origin
        xyz="-2.8E-06 4.277E-05 -0.05877156"
        rpy="0 0 0" />
      <mass
        value="0.261" />
      <inertia
        ixx="0.00057637"
        ixy="0"
        ixz="2E-08"
        iyy="0.00047053"
        iyz="-5.1E-07"
        izz="0.00013901" />
    </inertial>
    <visual>
      <origin
        xyz="0 0 0"
        rpy="0 0 0" />
      <geometry>
        <mesh
          filename="package://UB_D03_description/meshes/UB_D03_03/right_hand_yaw_link.STL" />
      </geometry>
      <material
        name="">
        <color
          rgba="1 1 1 1" />
      </material>
    </visual>
    <!-- <collision>
      <origin
        xyz="0 0 0"
        rpy="0 0 0" />
      <geometry>
        <mesh
          filename="package://UB_D03_description/meshes/UB_D03_03/right_hand_yaw_link.STL" />
      </geometry>
    </collision> -->
  </link>
  <joint
    name="right_hand_yaw_joint"
    type="revolute">
    <origin
      xyz="0 0 -0.0815"
      rpy="0 0 0" />
    <parent
      link="right_wrist_pitch_link" />
    <child
      link="right_hand_yaw_link" />
    <axis
      xyz="0 0 1" />
    <limit
      lower="-2.356"
      upper="2.356"
      effort="18"
      velocity="14" />
  </joint>

  <!-- Right hand Contact -->
  <joint name="right_hand_contact_joint" type="fixed">
    <origin xyz="0 0 0.0" rpy="0 0 0" />
    <parent link="right_hand_yaw_link" />
    <child link="right_hand_contact" />
  </joint>
  <link name="right_hand_contact">
    <inertial>
      <origin xyz=".0 .0 .0" rpy="0 0 0" />
      <mass value="0.001" />
      <inertia 
        ixx="0.0000001" 
        ixy="0.0" 
        ixz="0.0" 
        iyy="0.0000001" 
        iyz="0.0" 
        izz="0.0000001" />
    </inertial>
    <visual>
      <origin xyz="0 0 0" rpy="0 0 0" />
      <geometry>
        <box size="0.01 0.01 0.01"/>
      </geometry>
      <material name="">
        <color rgba="1 0 0 1" />
      </material>
    </visual>
  </link>
  
  <link
    name="head_yaw_link">
    <inertial>
      <origin
        xyz="1.263E-05 0.00749931 0.03957992"
        rpy="0 0 0" />
      <mass
        value="0.314" />
      <inertia
        ixx="0.00015227"
        ixy="9.6E-07"
        ixz="6.8E-07"
        iyy="0.00014564"
        iyz="7.3E-07"
        izz="0.0001379" />
    </inertial>
    <visual>
      <origin
        xyz="0 0 0"
        rpy="0 0 0" />
      <geometry>
        <mesh
          filename="package://UB_D03_description/meshes/UB_D03_03/neck_yaw_link.STL" />
      </geometry>
      <material
        name="">
        <color
          rgba="1 1 1 1" />
      </material>
    </visual>
    <!-- <collision>
      <origin
        xyz="0 0 0"
        rpy="0 0 0" />
      <geometry>
        <mesh
          filename="package://UB_D03_description/meshes/UB_D03_03/neck_yaw_link.STL" />
      </geometry>
    </collision> -->
  </link>
  <joint
    name="head_yaw_joint"
    type="revolute">
    <origin
      xyz="-0.013 0 0.3837"
      rpy="0 0 0" />
    <parent
      link="waist_pitch_link" />
    <child
      link="head_yaw_link" />
    <axis
      xyz="0 0 1" />
    <limit
      lower="-0.785"
      upper="0.785"
      effort="18"
      velocity="14" />
  </joint>
  <link
    name="head_pitch_link">
    <inertial>
      <origin
        xyz="0.00894282 -0.00017284 0.06951097"
        rpy="0 0 0" />
      <mass
        value="0.969" />
      <inertia
        ixx="0.00251828"
        ixy="1.3E-07"
        ixz="0.00022007"
        iyy="0.00242323"
        iyz="-4E-06"
        izz="0.00348849" />
    </inertial>
    <visual>
      <origin
        xyz="0 0 0"
        rpy="0 0 0" />
      <geometry>
        <mesh
          filename="package://UB_D03_description/meshes/UB_D03_03/neck_pitch_link.STL" />
      </geometry>
      <material
        name="">
        <color
          rgba="1 1 1 1" />
      </material>
    </visual>
    <!-- <collision>
      <origin
        xyz="0 0 0"
        rpy="0 0 0" />
      <geometry>
        <mesh
          filename="package://UB_D03_description/meshes/UB_D03_03/neck_pitch_link.STL" />
      </geometry>
    </collision> -->
  </link>
  <joint
    name="head_pitch_joint"
    type="revolute">
    <origin
      xyz="0 0 0.0415"
      rpy="0 0 0" />
    <parent
      link="head_yaw_link" />
    <child
      link="head_pitch_link" />
    <axis
      xyz="0 1 0" />
    <limit
      lower="-0.524"
      upper="0.96"
      effort="18"
      velocity="14" />
  </joint>
</robot>